Workbook

Sheet 1. 도급내역
B1: 1. 2025년 10월 소각로 도급비용
T2: * 실 스팀량 기준
B3: 일별 | C3: 폐합성수지 소각로 [ton] | T3: 일별 | U3: 폐합성수지 소각로 [ton]
C4: 스팀생산량 / 운휴시간 | Q4: 스팀량 합계(ton) | R4: 총 운영비용(원) | U4: 스팀생산량 / 운휴시간 | AA4: 스팀량 합계(ton) | AB4: 총 운영비용(원)
C5: 1호기 | J5: 2호기 | U5: 1호기 | X5: 2호기
C6: 스팀량(톤) | D6: 운영단가(원/톤) | E6: 운영비용(원) | F6: 운휴시간(Hr) | G6: 운휴시간당 고정비(원/시간) | H6: 운영비용(원) | I6: 1호기 소계(원) | J6: 스팀량(톤/일) | K6: 운영단가(원/톤) | L6: 운영비용(원) | M6: 운휴시간(Hr) | N6: 운휴시간당 고정비(원/시간) | O6: 운영비용(원) | P6: 2호기 소계(원) | U6: 스팀량(톤) | V6: 운영단가(원/톤) | W6: 운영비용(원) | X6: 스팀량(톤/일) | Y6: 운영단가(원/톤) | Z6: 운영비용(원)
B7: 1일 | C7: 0 | D7: 11700 | E7: =C7*D7 -> 0 | F7: 24 | G7: 78000 | H7: =F7*G7 -> 1872000 | I7: =E7+H7 -> 1872000 | J7: 0 | K7: =D7 -> 11700 | L7: =J7*K7 -> 0 | M7: 24 | N7: 96000 | O7: =M7*N7 -> 2304000 | P7: =L7+O7 -> 2304000 | Q7: =C7+J7 -> 0 | R7: =I7+P7 -> 4176000 | T7: 1일 | U7: 0 | V7: 11700 | W7: =U7*V7 -> 0 | X7: 0 | Y7: =V7 -> 11700 | Z7: =X7*Y7 -> 0 | AA7: =U7+X7 -> 0 | AB7: =W7+Z7 -> 0
B8: 2일 | C8: 0 | D8: 11700 | E8: =C8*D8 -> 0 | F8: 24 | G8: 78000 | H8: =F8*G8 -> 1872000 | I8: =E8+H8 -> 1872000 | J8: 0 | K8: =D8 -> 11700 | L8: =J8*K8 -> 0 | M8: 24 | N8: 96000 | O8: =M8*N8 -> 2304000 | P8: =L8+O8 -> 2304000 | Q8: =C8+J8 -> 0 | R8: =I8+P8 -> 4176000 | T8: 2일 | U8: 0 | V8: 11700 | W8: =U8*V8 -> 0 | X8: 0 | Y8: =V8 -> 11700 | Z8: =X8*Y8 -> 0 | AA8: =U8+X8 -> 0 | AB8: =W8+Z8 -> 0
B9: 3일 | C9: 0 | D9: 11700 | E9: =C9*D9 -> 0 | F9: 24 | G9: 78000 | H9: =F9*G9 -> 1872000 | I9: =E9+H9 -> 1872000 | J9: 0 | K9: =D9 -> 11700 | L9: =J9*K9 -> 0 | M9: 24 | N9: 96000 | O9: =M9*N9 -> 2304000 | P9: =L9+O9 -> 2304000 | Q9: =C9+J9 -> 0 | R9: =I9+P9 -> 4176000 | T9: 3일 | U9: 0 | V9: 11700 | W9: =U9*V9 -> 0 | X9: 0 | Y9: =V9 -> 11700 | Z9: =X9*Y9 -> 0 | AA9: =U9+X9 -> 0 | AB9: =W9+Z9 -> 0
B10: 4일 | C10: 0 | D10: 11700 | E10: =C10*D10 -> 0 | F10: 24 | G10: 78000 | H10: =F10*G10 -> 1872000 | I10: =E10+H10 -> 1872000 | J10: 0 | K10: =D10 -> 11700 | L10: =J10*K10 -> 0 | M10: 24 | N10: 96000 | O10: =M10*N10 -> 2304000 | P10: =L10+O10 -> 2304000 | Q10: =C10+J10 -> 0 | R10: =I10+P10 -> 4176000 | T10: 4일 | U10: 0 | V10: 11700 | W10: =U10*V10 -> 0 | X10: 0 | Y10: =V10 -> 11700 | Z10: =X10*Y10 -> 0 | AA10: =U10+X10 -> 0 | AB10: =W10+Z10 -> 0
B11: 5일 | C11: 0 | D11: 11700 | E11: =C11*D11 -> 0 | F11: 24 | G11: 78000 | H11: =F11*G11 -> 1872000 | I11: =E11+H11 -> 1872000 | J11: 0 | K11: =D11 -> 11700 | L11: =J11*K11 -> 0 | M11: 24 | N11: 96000 | O11: =M11*N11 -> 2304000 | P11: =L11+O11 -> 2304000 | Q11: =C11+J11 -> 0 | R11: =I11+P11 -> 4176000 | T11: 5일 | U11: 0 | V11: 11700 | W11: =U11*V11 -> 0 | X11: 0 | Y11: =V11 -> 11700 | Z11: =X11*Y11 -> 0 | AA11: =U11+X11 -> 0 | AB11: =W11+Z11 -> 0
B12: 6일 | C12: 0 | D12: 11700 | E12: =C12*D12 -> 0 | F12: 24 | G12: 78000 | H12: =F12*G12 -> 1872000 | I12: =E12+H12 -> 1872000 | J12: 0 | K12: =D12 -> 11700 | L12: =J12*K12 -> 0 | M12: 24 | N12: 96000 | O12: =M12*N12 -> 2304000 | P12: =L12+O12 -> 2304000 | Q12: =C12+J12 -> 0 | R12: =I12+P12 -> 4176000 | T12: 6일 | U12: 0 | V12: 11700 | W12: =U12*V12 -> 0 | X12: 0 | Y12: =V12 -> 11700 | Z12: =X12*Y12 -> 0 | AA12: =U12+X12 -> 0 | AB12: =W12+Z12 -> 0
B13: 7일 | C13: 0 | D13: 11700 | E13: =C13*D13 -> 0 | F13: 24 | G13: 78000 | H13: =F13*G13 -> 1872000 | I13: =E13+H13 -> 1872000 | J13: 0 | K13: =D13 -> 11700 | L13: =J13*K13 -> 0 | M13: 24 | N13: 96000 | O13: =M13*N13 -> 2304000 | P13: =L13+O13 -> 2304000 | Q13: =C13+J13 -> 0 | R13: =I13+P13 -> 4176000 | T13: 7일 | U13: 0 | V13: 11700 | W13: =U13*V13 -> 0 | X13: 0 | Y13: =V13 -> 11700 | Z13: =X13*Y13 -> 0 | AA13: =U13+X13 -> 0 | AB13: =W13+Z13 -> 0
B14: 8일 | C14: 0 | D14: 11700 | E14: =C14*D14 -> 0 | F14: 24 | G14: 78000 | H14: =F14*G14 -> 1872000 | I14: =E14+H14 -> 1872000 | J14: 0 | K14: =D14 -> 11700 | L14: =J14*K14 -> 0 | M14: 24 | N14: 96000 | O14: =M14*N14 -> 2304000 | P14: =L14+O14 -> 2304000 | Q14: =C14+J14 -> 0 | R14: =I14+P14 -> 4176000 | T14: 8일 | U14: 0 | V14: 11700 | W14: =U14*V14 -> 0 | X14: 0 | Y14: =V14 -> 11700 | Z14: =X14*Y14 -> 0 | AA14: =U14+X14 -> 0 | AB14: =W14+Z14 -> 0
B15: 9일 | C15: 0 | D15: 11700 | E15: =C15*D15 -> 0 | F15: 24 | G15: 78000 | H15: =F15*G15 -> 1872000 | I15: =E15+H15 -> 1872000 | J15: 0 | K15: =D15 -> 11700 | L15: =J15*K15 -> 0 | M15: 24 | N15: 96000 | O15: =M15*N15 -> 2304000 | P15: =L15+O15 -> 2304000 | Q15: =C15+J15 -> 0 | R15: =I15+P15 -> 4176000 | T15: 9일 | U15: 0 | V15: 11700 | W15: =U15*V15 -> 0 | X15: 0 | Y15: =V15 -> 11700 | Z15: =X15*Y15 -> 0 | AA15: =U15+X15 -> 0 | AB15: =W15+Z15 -> 0
B16: 10일 | C16: 0 | D16: 11700 | E16: =C16*D16 -> 0 | F16: 24 | G16: 78000 | H16: =F16*G16 -> 1872000 | I16: =E16+H16 -> 1872000 | J16: 0 | K16: =D16 -> 11700 | L16: =J16*K16 -> 0 | M16: 24 | N16: 96000 | O16: =M16*N16 -> 2304000 | P16: =L16+O16 -> 2304000 | Q16: =C16+J16 -> 0 | R16: =I16+P16 -> 4176000 | T16: 10일 | U16: 0 | V16: 11700 | W16: =U16*V16 -> 0 | X16: 0 | Y16: =V16 -> 11700 | Z16: =X16*Y16 -> 0 | AA16: =U16+X16 -> 0 | AB16: =W16+Z16 -> 0
B17: 11일 | C17: 0 | D17: 11700 | E17: =C17*D17 -> 0 | F17: 24 | G17: 78000 | H17: =F17*G17 -> 1872000 | I17: =E17+H17 -> 1872000 | J17: 0 | K17: =D17 -> 11700 | L17: =J17*K17 -> 0 | M17: 24 | N17: 96000 | O17: =M17*N17 -> 2304000 | P17: =L17+O17 -> 2304000 | Q17: =C17+J17 -> 0 | R17: =I17+P17 -> 4176000 | T17: 11일 | U17: 0 | V17: 11700 | W17: =U17*V17 -> 0 | X17: 0 | Y17: =V17 -> 11700 | Z17: =X17*Y17 -> 0 | AA17: =U17+X17 -> 0 | AB17: =W17+Z17 -> 0
B18: 12일 | C18: 0 | D18: 11700 | E18: =C18*D18 -> 0 | F18: 24 | G18: 78000 | H18: =F18*G18 -> 1872000 | I18: =E18+H18 -> 1872000 | J18: 0 | K18: =D18 -> 11700 | L18: =J18*K18 -> 0 | M18: 24 | N18: 96000 | O18: =M18*N18 -> 2304000 | P18: =L18+O18 -> 2304000 | Q18: =C18+J18 -> 0 | R18: =I18+P18 -> 4176000 | T18: 12일 | U18: 0 | V18: 11700 | W18: =U18*V18 -> 0 | X18: 0 | Y18: =V18 -> 11700 | Z18: =X18*Y18 -> 0 | AA18: =U18+X18 -> 0 | AB18: =W18+Z18 -> 0
... B37: 31일 | C37: 0 | D37: 11700 | E37: =C37*D37 -> 0 | F37: 24 | G37: 78000 | H37: =F37*G37 -> 1872000 | I37: =E37+H37 -> 1872000 | J37: 336 | K37: =D37 -> 11700 | L37: =J37*K37 -> 3931200 | M37: 0 | N37: 96000 | O37: =M37*N37 -> 0 | P37: =L37+O37 -> 3931200 | Q37: =C37+J37 -> 336 | R37: =I37+P37 -> 5803200 | T37: 31일 | U37: 0 | V37: 11700 | W37: =U37*V37 -> 0 | X37: 351 | Y37: =V37 -> 11700 | Z37: =X37*Y37 -> 4106700 | AA37: =U37+X37 -> 351 | AB37: =W37+Z37 -> 4106700
B38: 합 계 | C38: =SUM(C7:C37) -> 0 | E38: =SUM(E7:E37) -> 0 | F38: =SUM(F7:F37) -> 744 | H38: =SUM(H7:H37) -> 58032000 | I38: =E38+H38 -> 58032000 | J38: =SUM(J7:J37) -> 4764 | L38: =SUM(L7:L37) -> 55738800 | M38: =SUM(M7:M37) -> 305 | O38: =SUM(O7:O37) -> 29280000 | P38: =SUM(P7:P37) -> 85018800 | Q38: =SUM(Q7:Q37) -> 4764 | R38: =SUM(R7:R37) -> 143050800 | T38: 합 계 | U38: =SUM(U7:U37) -> 0 | W38: =SUM(W7:W37) -> 0 | X38: =SUM(X7:X37) -> 4871 | Z38: =SUM(Z7:Z37) -> 56990700 | AA38: =SUM(AA7:AA37) -> 4871 | AB38: =SUM(AB7:AB37) -> 56990700
B39: 평 균 | C39: =AVERAGE(C7:C37) -> 0 | E39: =AVERAGE(E7:E37) -> 0 | F39: =AVERAGE(F7:F37) -> 24 | H39: =AVERAGE(H7:H37) -> 1872000 | I39: =E39+H39 -> 1872000 | J39: =AVERAGE(J7:J37) -> 153.67742 | L39: =AVERAGE(L7:L37) -> 1798025.8 | M39: =AVERAGE(M7:M37) -> 9.8387097 | O39: =AVERAGE(O7:O37) -> 944516.13 | P39: =AVERAGE(P7:P37) -> 2742541.9 | Q39: =AVERAGE(Q7:Q37) -> 153.67742 | R39: =AVERAGE(R7:R37) -> 4614541.9 | T39: 평 균 | U39: =AVERAGE(U7:U37) -> 0 | W39: =AVERAGE(W7:W37) -> 0 | X39: =AVERAGE(X7:X37) -> 157.12903 | Z39: =AVERAGE(Z7:Z37) -> 1838409.7 | AA39: =AVERAGE(AA7:AA37) -> 157.12903 | AB39: =AVERAGE(AB7:AB37) -> 1838409.7
L41: [단위 : 원] | Z41: [단위 : 톤, 원]
H42: 구 분 | I42: 스팀량(톤/월) | J42: 인건비 | K42: 운영비 | L42: 총 금액 | W42: 구 분 | X42: 결산기준 | Y42: 실 사용량 기준 | Z42: 증 감
H43: 폐합성소각로 | I43: =Q38 -> 4764 | J43: 96380000 | K43: =L43-J43 -> 46670800 | L43: =R38 -> 143050800 | W43: 스팀량 | X43: =I43 -> 4764 | Y43: =AA38 -> 4871 | Z43: =X43-Y43 -> -107
W44: 스팀비용 | X44: =E38+L38 -> 55738800 | Y44: =AB38 -> 56990700 | Z44: =X44-Y44 -> -1251900
Y45: 실 운영비 : | Z45: =L43-Z44 -> 144302700

Sheet 2. 2025년 사업계획대비
A1: 2. 소각로 위탁운영비용 사업계획대비 실적 (단위:천원)
A3: 1) 폐합성소각로
A4: 구 분 | C4: 1월 | D4: 2월 | E4: 3월 | F4: 4월 | G4: 5월 | H4: 6월 | I4: 7월 | J4: 8월 | K4: 9월 | L4: 10월 | M4: 11월 | N4: 12월 | O4: 합계
A5: 폐합성소각로 (인건비) | B5: 2025계획 | C5: 96400 | D5: 96400 | E5: 96400 | F5: 96400 | G5: 96400 | H5: 96400 | I5: 96400 | J5: 96400 | K5: 96400 | L5: 96400 | M5: 96400 | N5: 96400 | O5: =SUM(C5:N5) -> 1156800
B6: 2025실적 | C6: 94700 | D6: 96380 | E6: 96380 | F6: 96380 | G6: 96380 | H6: 96380 | I6: 96380 | J6: 96380 | K6: 96380 | L6: 96380 | O6: =SUM(C6:N6) -> 962120
A7: 폐합성소각로 (운영비) | B7: =B5 -> 2025계획 | C7: 37204.93 | D7: 55174.11 | E7: 60308.43 | F7: 63156.51 | G7: 57943.95 | H7: 68788.71 | I7: 60714.75 | J7: 68200.23 | K7: 56162 | L7: 66371.79 | M7: 56162 | N7: 71727.39 | O7: =SUM(C7:N7) -> 721914.8
B8: =B6 -> 2025실적 | C8: 50691 | D8: 67391.3 | E8: 79025.5 | F8: 53594.26 | G8: 61663 | H8: 58580.2 | I8: 57922.3 | J8: 63637.31 | K8: 61204 | L8: ='1. 도급내역'!K43/1000 -> 46670.8 | O8: =SUM(C8:N8) -> 600379.67
A9: 폐합성소각로 (합계) | B9: =B5 -> 2025계획 | C9: =C5+C7 -> 133604.93 | D9: =D5+D7 -> 151574.11 | E9: =E5+E7 -> 156708.43 | F9: =F5+F7 -> 159556.51 | G9: =G5+G7 -> 154343.95 | H9: =H5+H7 -> 165188.71 | I9: =I5+I7 -> 157114.75 | J9: =J5+J7 -> 164600.23 | ... N9: =N5+N7 -> 168127.39 | O9: =SUM(C9:N9) -> 1878714.8
B10: =B6 -> 2025실적 | C10: =C6+C8 -> 145391 | D10: =D6+D8 -> 163771.3 | E10: =E6+E8 -> 175405.5 | F10: =F6+F8 -> 149974.26 | G10: =G6+G8 -> 158043 | H10: =H6+H8 -> 154960.2 | I10: =I6+I8 -> 154302.3 | J10: =J6+J8 -> 160017.31 | ... L10: =L6+L8 -> 143050.8 | N10: =N6+N8 -> 0 | O10: =SUM(C10:N10) -> 1562499.7
A11: 합계 | B11: 달성율(%) | C11: =C10/C9 -> 1.0882158 | D11: =D10/D9 -> 1.0804701 | E11: =E10/E9 -> 1.1193112 | F11: =F10/F9 -> 0.93994447 | G11: =G10/G9 -> 1.0239663 | H11: =H10/H9 -> 0.93807985 | I11: =I10/I9 -> 0.98209939 | J11: =J10/J9 -> 0.97215727 | ... O11: =O10/O9 -> 0.8316854
A12: 증감 | C12: =C10-C9 -> 11786.07 | D12: =D10-D9 -> 12197.19 | E12: =E10-E9 -> 18697.07 | F12: =F10-F9 -> -9582.25 | G12: =G10-G9 -> 3699.05 | H12: =H10-H9 -> -10228.51 | I12: =I10-I9 -> -2812.45 | J12: =J10-J9 -> -4582.92 | ... O12: =O10-O9 -> -316215.13
A14: 구 분 | B14: `25년 10월 | E14: '25년 누계 | H14: `25년 9월 | I14: 전월 대비 | K14: 비 고
B15: 계 획 | C15: 실 적 | D15: 증 감 | E15: 계 획 | F15: 실 적 | G15: 증 감 | H15: 실 적 | I15: 증 감 | J15: 증감률(%)
A16: 위탁운영비 (백만원) | B16: =L9/1000 -> 162.77179 | C16: =L10/1000 -> 143.0508 | D16: =C16-B16 -> -19.72099 | E16: =SUM(C9:N9)/1000 -> 1878.7148 | F16: =SUM(C10:N10)/1000 -> 1562.4997 | G16: =F16-E16 -> -316.21513 | H16: =K10/1000 -> 157.584 | I16: =C16-H16 -> -14.5332 | J16: =I16/H16 -> -0.092225099
A18: 비 고 | B18: 1월 | C18: #1 폐합성수지소각로
C19: #2 폐합성수지소각로 | E19: 1/1~6 제지 조단 운휴, | G19: 1/21~31 자폐 확보 및 설 명절 운휴
B20: 2월 | C20: #1 폐합성수지소각로
C21: #2 폐합성수지소각로 | E21: 2/7~11 제지 조단 운휴, | G21: 2/23~24 절탄기 누수 보수 운휴
B22: 3월 | C22: #1 폐합성수지소각로 | E22: 3/13~17 가동
C23: #2 폐합성수지소각로 | E23: 에너지회수효율 정기검사 30일 연속가동, 3/31~4/5 제지 조단기간 운휴
B24: 4월 | C24: #1 폐합성수지소각로
C25: #2 폐합성수지소각로 | E25: 4/1~4 제지 조단기간 운휴, 4/17~18, 4/19~22 워터자켓 누수로 인한 CO초과로 운휴, 4/28~30 제지 조단기간 운휴
B26: 5월 | C26: #1 폐합성수지소각로
C27: #2 폐합성수지소각로 | E27: 5/1~6 제지 조단기간 운휴, 5/20~21 유인송풍기 베어링 교체 운휴, 5/27~31 통합인허가 정기검사 대비 설비 운휴
B28: 6월 | C28: #1 폐합성수지소각로
C29: #2 폐합성수지소각로 | E29: 6/1~3, 6/25~30 제지2 운휴로 인한 스팀사용량 감소로 설비 운휴
B30: 7월 | C30: #1 폐합성수지소각로
C31: #2 폐합성수지소각로 | E31: 7/5 CO초과 운휴, 7/14 수관 누수 운휴, 7/22 유인송풍기 진동 점검 운휴
B32: 8월 | C32: #1 폐합성수지소각로
C33: #2 폐합성수지소각로 | E33: 8/2~11 제지2 운휴로 인한 스팀사용량 감소로 설비 운휴
B34: 9월 | C34: #1 폐합성수지소각로
C35: #2 폐합성수지소각로 | E35: 9/6~14 제지2 운휴로 인한 스팀사용량 감소로 설비 운휴 (유인송풍기 베어링 교체-케이앤이 정비사업팀)
B36: 10월 | C36: #1 폐합성수지소각로
C37: #2 폐합성수지소각로 | E37: 10/1~13 추석 연휴기간 설비 운휴
B38: 11월 | C38: #1 폐합성수지소각로
C39: #2 폐합성수지소각로
B40: 12월 | C40: #1 폐합성수지소각로
C41: #2 폐합성수지소각로

Sheet 3. 2025년(전년)대비 및 절감내역
A1: 3. 소각로 위탁운영비용 전년도 실적 및 비교 (단위:천원)
A3: 구 분 | C3: 1월 | D3: 2월 | E3: 3월 | F3: 4월 | G3: 5월 | H3: 6월 | I3: 7월 | J3: 8월 | K3: 9월 | L3: 10월 | M3: 11월 | N3: 12월 | O3: 합계
A4: 폐합성소각로 (합계) | B4: 2024실적 | C4: 163458.5 | D4: 139889.8 | E4: 132995.5 | F4: 141391.5 | G4: 144176 | H4: 130786 | I4: 130333.6 | J4: 148377.5 | K4: 150361.5 | L4: 143293 | M4: 156543.32 | N4: 142524 | O4: =SUM(C4:N4) -> 1724130.2
B5: 2025실적 | C5: ='2. 2025년 사업계획대비'!C10 -> 145391 | D5: ='2. 2025년 사업계획대비'!D10 -> 163771.3 | E5: ='2. 2025년 사업계획대비'!E10 -> 175405.5 | F5: ='2. 2025년 사업계획대비'!F10 -> 149974.26 | G5: ='2. 2025년 사업계획대비'!G10 -> 158043 | H5: ='2. 2025년 사업계획대비'!H10 -> 154960.2 | I5: ='2. 2025년 사업계획대비'!I10 -> 154302.3 | J5: ='2. 2025년 사업계획대비'!J10 -> 160017.31 | ... N5: ='2. 2025년 사업계획대비'!N10 -> 0 | O5: =SUM(C5:N5) -> 1562499.7
B6: 증감 | C6: =C5-C4 -> -18067.5 | D6: =D5-D4 -> 23881.5 | E6: =E5-E4 -> 42410 | F6: =F5-F4 -> 8582.76 | G6: =G5-G4 -> 13867 | H6: =H5-H4 -> 24174.2 | I6: =I5-I4 -> 23968.7 | J6: =J5-J4 -> 11639.81 | ... O6: =O5-O4 -> -161630.55
A8: 4. 소각로 운영실적 비교 (단위 : 톤)
D9: 저압운전기간 실 사용량 실적 기준 ('25.2~)
A10: 구 분 | C10: 1월 | D10: 2월 | E10: 3월 | F10: 4월 | G10: 5월 | H10: 6월 | I10: 7월 | J10: 8월 | K10: 9월 | L10: 10월 | M10: 11월 | N10: 12월 | O10: 합계
A11: 폐합성소각로 스팀생산량 | B11: =B4 -> 2024실적 | C11: 10384 | D11: 7184 | E11: 7429 | F11: 8752 | G11: 7198 | H11: 8549 | I11: 7222 | J11: 8485 | K11: 8247 | L11: 7210 | M11: 9656 | N11: 7082 | O11: =SUM(C11:N11) -> 97398
B12: =B5 -> 2025실적 | C12: 6656 | D12: 9627 | E12: 12712 | F12: 7678 | G12: 7016 | H12: 6746 | I12: 6946 | J12: 6783 | K12: 7154 | L12: ='1. 도급내역'!Y43 -> 4871 | O12: =SUM(C12:N12) -> 76189
B13: 증감 | C13: =C12-C11 -> -3728 | D13: =D12-D11 -> 2443 | E13: =E12-E11 -> 5283 | F13: =F12-F11 -> -1074 | G13: =G12-G11 -> -182 | H13: =H12-H11 -> -1803 | I13: =I12-I11 -> -276 | J13: =J12-J11 -> -1702 | ... O13: =O12-O11 -> -21209

Sheet 4. 2025 계획대비 가동실적
A1: 5. 소각로 가동계획대비 실적
A3: 2025년 | B3: 스팀생산량 | E3: 운영단가(위탁) | H3: 위탁운영비용(천원) | K3: 스팀생산량 | N3: 운영단가(위탁) | Q3: 위탁운영비용(천원) | T3: 폐합성 1호기 | W3: 폐합성 2호기 | Z3: 스팀생산량 | AC3: 운영단가(위탁) | AF3: 위탁운영비용(천원)
B4: 계획 | C4: 실적 | D4: 증감 | E4: 계획 | F4: 실적 | G4: 증감 | H4: 계획 | I4: 실적 | J4: 증감 | K4: 계획 | L4: 실적 | M4: 증감 | N4: 계획 | O4: 실적 | P4: 증감 | Q4: 계획 | R4: 실적 | S4: 증감 | T4: 가동계획(hr) | U4: 가동실적(hr) | V4: 달성율(%) | W4: 가동계획(hr) | X4: 가동실적(hr) | Y4: 달성율(%) | Z4: 계획 | AA4: 실적 | AB4: 증감 | AC4: 계획 | AD4: 실적 | AE4: 증감 | AF4: 계획 | AG4: 실적 | AH4: 증감
A5: 1월 | B5: 7648 | E5: 13000 | F5: 11300 | G5: =F5-E5 -> -1700 | H5: =B5*E5/1000 -> 99424 | I5: =C5*F5/1000 -> 0 | J5: =I5-H5 -> -99424 | K5: 13034 | M5: =L5-K5 -> -13034 | N5: 13000 | O5: 11300 | P5: =O5-N5 -> -1700 | Q5: =K5*N5/1000 -> 169442 | R5: =L5*O5/1000 -> 0 | S5: =R5-Q5 -> -169442 | T5: 600 | U5: 141 | V5: =IFERROR(U5/T5," ") -> 0.235 | W5: 176.2 | X5: 391 | Y5: =X5/W5 -> 2.2190692 | Z5: 7354.9 | AA5: {=TRANSPOSE('3. 2025년(전년)대비 및 절감내역'!C12:N12)} -> 6656 | AB5: =AA5-Z5 -> -698.9 | AC5: =AF5/Z5*1000 -> 18165.431 | AD5: =IFERROR(AG5*1000/AA5," ") -> 21843.6 | AE5: =IFERROR(AD5-AC5," ") -> 3678.1686 | AF5: 133604.93 | AG5: {=TRANSPOSE('2. 2025년 사업계획대비'!C10:N10)} -> 145391 | AH5: =AG5-AF5 -> 11786.07
A6: 2월 | B6: 8309 | E6: 13000 | F6: 11300 | G6: =F6-E6 -> -1700 | H6: =B6*E6/1000 -> 108017 | I6: =C6*F6/1000 -> 0 | J6: =I6-H6 -> -108017 | K6: 9511 | M6: =L6-K6 -> -9511 | N6: 13000 | O6: 11300 | P6: =O6-N6 -> -1700 | Q6: =K6*N6/1000 -> 123643 | R6: =L6*O6/1000 -> 0 | S6: =R6-Q6 -> -123643 | T6: 120 | U6: 222 | V6: =IFERROR(U6/T6," ") -> 1.85 | W6: 553.4 | X6: 503.6 | Y6: =X6/W6 -> 0.91001084 | Z6: 8984.3 | AA6: 9627 | AB6: =AA6-Z6 -> 642.7 | AC6: =AF6/Z6*1000 -> 16870.998 | AD6: =IFERROR(AG6*1000/AA6," ") -> 17011.665 | AE6: =IFERROR(AD6-AC6," ") -> 140.66681 | AF6: 151574.11 | AG6: 163771.3 | AH6: =AG6-AF6 -> 12197.19
A7: 3월 | B7: 7955 | E7: 13000 | F7: 11300 | G7: =F7-E7 -> -1700 | H7: =B7*E7/1000 -> 103415 | I7: =C7*F7/1000 -> 0 | J7: =I7-H7 -> -103415 | K7: 12492 | M7: =L7-K7 -> -12492 | N7: 13000 | O7: 11300 | P7: =O7-N7 -> -1700 | Q7: =K7*N7/1000 -> 162396 | R7: =L7*O7/1000 -> 0 | S7: =R7-Q7 -> -162396 | T7: 120 | U7: 117 | V7: =IFERROR(U7/T7," ") -> 0.975 | W7: 606.2 | X7: 686.3 | Y7: =X7/W7 -> 1.1321346 | Z7: 9749.9 | AA7: 12712 | AB7: =AA7-Z7 -> 2962.1 | AC7: =AF7/Z7*1000 -> 16072.824 | AD7: =IFERROR(AG7*1000/AA7," ") -> 13798.419 | AE7: =IFERROR(AD7-AC7," ") -> -2274.4055 | AF7: 156708.43 | AG7: 175405.5 | AH7: =AG7-AF7 -> 18697.07
A8: 4월 | B8: 9116 | E8: 13000 | F8: 11300 | G8: =F8-E8 -> -1700 | H8: =B8*E8/1000 -> 118508 | I8: =C8*F8/1000 -> 0 | J8: =I8-H8 -> -118508 | K8: 10210 | M8: =L8-K8 -> -10210 | N8: 13000 | O8: 11300 | P8: =O8-N8 -> -1700 | Q8: =K8*N8/1000 -> 132730 | R8: =L8*O8/1000 -> 0 | S8: =R8-Q8 -> -132730 | T8: 0 | U8: 0 | V8: =IFERROR(U8/T8," ") | W8: 601.4 | X8: 478 | Y8: =X8/W8 -> 0.79481211 | Z8: 8720.3 | AA8: 7678 | AB8: =AA8-Z8 -> -1042.3 | AC8: =AF8/Z8*1000 -> 18297.135 | AD8: =IFERROR(AG8*1000/AA8," ") -> 19532.985 | AE8: =IFERROR(AD8-AC8," ") -> 1235.8497 | AF8: 159556.51 | AG8: 149974.26 | AH8: =AG8-AF8 -> -9582.25
A9: 5월 | B9: 7580 | E9: 13000 | F9: 11300 | G9: =F9-E9 -> -1700 | H9: =B9*E9/1000 -> 98540 | I9: =C9*F9/1000 -> 0 | J9: =I9-H9 -> -98540 | K9: 12547 | M9: =L9-K9 -> -12547 | N9: 13000 | O9: 11300 | P9: =O9-N9 -> -1700 | Q9: =K9*N9/1000 -> 163111 | R9: =L9*O9/1000 -> 0 | S9: =R9-Q9 -> -163111 | T9: 240 | U9: 0 | V9: =IFERROR(U9/T9," ") -> 0 | W9: 539 | X9: 455.3 | Y9: =X9/W9 -> 0.84471243 | Z9: 9735.5 | AA9: 7016 | AB9: =AA9-Z9 -> -2719.5 | AC9: =AF9/Z9*1000 -> 15853.726 | AD9: =IFERROR(AG9*1000/AA9," ") -> 22526.083 | AE9: =IFERROR(AD9-AC9," ") -> 6672.3572 | AF9: 154343.95 | AG9: 158043 | AH9: =AG9-AF9 -> 3699.05
A10: 6월 | B10: 7986 | E10: 13000 | F10: 11300 | G10: =F10-E10 -> -1700 | H10: =B10*E10/1000 -> 103818 | I10: =C10*F10/1000 -> 0 | J10: =I10-H10 -> -103818 | K10: 10239 | M10: =L10-K10 -> -10239 | N10: 13000 | O10: 11300 | P10: =O10-N10 -> -1700 | Q10: =K10*N10/1000 -> 133107 | R10: =L10*O10/1000 -> 0 | S10: =R10-Q10 -> -133107 | T10: 240 | U10: 0 | V10: =IFERROR(U10/T10," ") -> 0 | W10: 589.4 | X10: 513 | Y10: =X10/W10 -> 0.87037665 | Z10: 10466.3 | AA10: 6746 | AB10: =AA10-Z10 -> -3720.3 | AC10: =AF10/Z10*1000 -> 15782.914 | AD10: =IFERROR(AG10*1000/AA10," ") -> 22970.679 | AE10: =IFERROR(AD10-AC10," ") -> 7187.7652 | AF10: 165188.71 | AG10: 154960.2 | AH10: =AG10-AF10 -> -10228.51
A11: 7월 | B11: 7085 | E11: 13000 | F11: 11300 | G11: =F11-E11 -> -1700 | H11: =B11*E11/1000 -> 92105 | I11: =C11*F11/1000 -> 0 | J11: =I11-H11 -> -92105 | K11: 10131 | M11: =L11-K11 -> -10131 | N11: 13000 | O11: 11300 | P11: =O11-N11 -> -1700 | Q11: =K11*N11/1000 -> 131703 | R11: =L11*O11/1000 -> 0 | S11: =R11-Q11 -> -131703 | T11: 120 | U11: 0 | V11: =IFERROR(U11/T11," ") -> 0 | W11: 611 | X11: 481.4 | Y11: =X11/W11 -> 0.78788871 | Z11: 9819.5 | AA11: 6946 | AB11: =AA11-Z11 -> -2873.5 | AC11: =AF11/Z11*1000 -> 16000.28 | AD11: =IFERROR(AG11*1000/AA11," ") -> 22214.555 | AE11: =IFERROR(AD11-AC11," ") -> 6214.2751 | AF11: 157114.75 | AG11: 154302.3 | AH11: =AG11-AF11 -> -2812.45
A12: 8월 | B12: 7219 | E12: 13000 | F12: 11300 | G12: =F12-E12 -> -1700 | H12: =B12*E12/1000 -> 93847 | I12: =C12*F12/1000 -> 0 | J12: =I12-H12 -> -93847 | K12: 11242 | M12: =L12-K12 -> -11242 | N12: 13000 | O12: 11300 | P12: =O12-N12 -> -1700 | Q12: =K12*N12/1000 -> 146146 | R12: =L12*O12/1000 -> 0 | S12: =R12-Q12 -> -146146 | T12: 0 | U12: 0 | V12: =IFERROR(U12/T12," ") | W12: 618.2 | X12: 499 | Y12: =X12/W12 -> 0.80718214 | Z12: 8963.9 | AA12: 6783 | AB12: =AA12-Z12 -> -2180.9 | AC12: =AF12/Z12*1000 -> 18362.569 | AD12: =IFERROR(AG12*1000/AA12," ") -> 23590.935 | AE12: =IFERROR(AD12-AC12," ") -> 5228.3659 | AF12: 164600.23 | AG12: 160017.31 | AH12: =AG12-AF12 -> -4582.92
A13: 9월 | B13: 7156 | E13: 13000 | F13: 11300 | G13: =F13-E13 -> -1700 | H13: =B13*E13/1000 -> 93028 | I13: =C13*F13/1000 -> 0 | J13: =I13-H13 -> -93028 | K13: 10164 | M13: =L13-K13 -> -10164 | N13: 13000 | O13: 11300 | P13: =O13-N13 -> -1700 | Q13: =K13*N13/1000 -> 132132 | R13: =L13*O13/1000 -> 0 | S13: =R13-Q13 -> -132132 | T13: 120 | U13: 0 | V13: =IFERROR(U13/T13," ") -> 0 | W13: 600 | X13: 529.3 | Y13: =X13/W13 -> 0.88216667 | Z13: 9660 | AA13: 7154 | AB13: =AA13-Z13 -> -2506 | AC13: =AF13/Z13*1000 -> 15793.168 | AD13: =IFERROR(AG13*1000/AA13," ") -> 22027.397 | AE13: =IFERROR(AD13-AC13," ") -> 6234.2296 | AF13: 152562 | AG13: 157584 | AH13: =AG13-AF13 -> 5022
A14: 10월 | B14: 7708 | E14: 13000 | F14: 11300 | G14: =F14-E14 -> -1700 | H14: =B14*E14/1000 -> 100204 | I14: =C14*F14/1000 -> 0 | J14: =I14-H14 -> -100204 | K14: 10023 | M14: =L14-K14 -> -10023 | N14: 13000 | O14: 11300 | P14: =O14-N14 -> -1700 | Q14: =K14*N14/1000 -> 130299 | R14: =L14*O14/1000 -> 0 | S14: =R14-Q14 -> -130299 | T14: 0 | U14: 0 | V14: =IFERROR(U14/T14," ") | W14: 596.6 | X14: 342.5 | Y14: =X14/W14 -> 0.57408649 | Z14: 8650.7 | AA14: 4871 | AB14: =AA14-Z14 -> -3779.7 | AC14: =AF14/Z14*1000 -> 18816.025 | AD14: =IFERROR(AG14*1000/AA14," ") -> 29367.851 | AE14: =IFERROR(AD14-AC14," ") -> 10551.825 | AF14: 162771.79 | AG14: 143050.8 | AH14: =AG14-AF14 -> -19720.99
A15: 11월 | B15: 7542 | E15: 13000 | F15: 11300 | G15: =F15-E15 -> -1700 | H15: =B15*E15/1000 -> 98046 | I15: =C15*F15/1000 -> 0 | J15: =I15-H15 -> -98046 | K15: 11291 | M15: =L15-K15 -> -11291 | N15: 13000 | O15: 11300 | P15: =O15-N15 -> -1700 | Q15: =K15*N15/1000 -> 146783 | R15: =L15*O15/1000 -> 0 | S15: =R15-Q15 -> -146783 | T15: 120 | V15: =IFERROR(U15/T15," ") -> 0 | W15: 600 | Y15: =X15/W15 -> 0 | Z15: 9660 | AA15: 0 | AB15: =AA15-Z15 -> -9660 | AC15: =AF15/Z15*1000 -> 15793.168 | AD15: =IFERROR(AG15*1000/AA15," ") | AE15: =IFERROR(AD15-AC15," ") | AF15: 152562 | AG15: 0 | AH15: =AG15-AF15 -> -152562
A16: 12월 | B16: 9000 | E16: 13000 | F16: 11300 | G16: =F16-E16 -> -1700 | H16: =B16*E16/1000 -> 117000 | I16: =C16*F16/1000 -> 0 | J16: =I16-H16 -> -117000 | K16: 10293 | M16: =L16-K16 -> -10293 | N16: 13000 | O16: 11300 | P16: =O16-N16 -> -1700 | Q16: =K16*N16/1000 -> 133809 | R16: =L16*O16/1000 -> 0 | S16: =R16-Q16 -> -133809 | T16: 120 | V16: =IFERROR(U16/T16," ") -> 0 | W16: 620.6 | Y16: =X16/W16 -> 0 | Z16: 9958.7 | AA16: 0 | AB16: =AA16-Z16 -> -9958.7 | AC16: =AF16/Z16*1000 -> 16882.464 | AD16: =IFERROR(AG16*1000/AA16," ") | AE16: =IFERROR(AD16-AC16," ") | AF16: 168127.39 | AG16: 0 | AH16: =AG16-AF16 -> -168127.39
A17: 합계 | B17: =SUM(B5:B16) -> 94304 | C17: =SUM(C5:C16) -> 0 | D17: =SUM(D5:D16) -> 0 | E17: =SUM(E5:E16) -> 156000 | F17: =SUM(F5:F16) -> 135600 | G17: =SUM(G5:G16) -> -20400 | H17: =SUM(H5:H16) -> 1225952 | I17: =SUM(I5:I16) -> 0 | ... U17: =SUM(U5:U16) -> 480 | V17: =U17/T17 -> 0.26666667 | W17: =SUM(W5:W16) -> 6712 | X17: =SUM(X5:X16) -> 4879.4 | Y17: =X17/W17 -> 0.72696663 | Z17: =SUM(Z5:Z16) -> 111724 | AA17: =SUM(AA5:AA16) -> 76189 | AB17: =SUM(AB5:AB16) -> -35535 | AC17: =SUM(AC5:AC16) -> 202690.7 | AD17: =IFERROR(AG17*1000/AA17," ") -> 20508.206 | AE17: =IFERROR(AD17-AC17," ") -> -182182.5 | AF17: =SUM(AF5:AF16) -> 1878714.8 | AG17: =SUM(AG5:AG16) -> 1562499.7 | AH17: =SUM(AH5:AH16) -> -316215.13
A18: 평균 | B18: =AVERAGE(B5:B16) -> 7858.6667 | C18: =AVERAGE(C5:C16) -> #DIV/0! | D18: =AVERAGE(D5:D16) -> #DIV/0! | E18: =AVERAGE(E5:E16) -> 13000 | F18: =AVERAGE(F5:F16) -> 11300 | G18: =AVERAGE(G5:G16) -> -1700 | H18: =AVERAGE(H5:H16) -> 102162.67 | I18: =AVERAGE(I5:I16) -> 0 | ... X18: =AVERAGE(X5:X16) -> 487.94 | Y18: =AVERAGE(Y5:Y17) -> 0.81149281 | Z18: =AVERAGE(Z5:Z16) -> 9310.3333 | AA18: =AVERAGE(AA5:AA16) -> 6349.0833 | AB18: =AVERAGE(AB5:AB16) -> -2961.25 | AC18: =AVERAGE(AC5:AC16) -> 16890.892 | AD18: =IFERROR(AG18*1000/AA18," ") -> 20508.206 | AE18: =IFERROR(AD18-AC18," ") -> 3617.3137 | AF18: =AVERAGE(AF5:AF16) -> 156559.57 | AG18: =AVERAGE(AG5:AG16) -> 130208.31 | AH18: =AVERAGE(AH5:AH16) -> -26351.261
D19: 사용량영향 | G19: 단가영향

Sheet 5. 폐합성소각로 총 운영비용
A1: 6. #1, #2 폐합성소각로 운영내역 및 비용 관리
A3: 2025 | B3: 폐기물 실소각량 | E3: 소각로 가동시간 | G3: 소각로 운휴시간 (고정비 지급) | I3: 스팀생산량 | L3: 스팀생산원단위 | O3: 위탁운영비용
B4: 1호기 | C4: 2호기 | D4: 합계 | E4: 1호기 | F4: 2호기 | G4: 1호기 | H4: 2호기 | I4: 1호기 | J4: 2호기 | K4: 합계 | L4: 1호기 | M4: 2호기 | N4: 합계 | O4: 위탁계약단가 | P4: 1호기(천원) | S4: 2호기(천원) | V4: 차감비 | W4: 비용합계
P5: 고정비 | Q5: 스팀구매비 | R5: 합 계 | S5: 고정비 | T5: 스팀구매비 | U5: 합 계 | Y5: 구 분 | Z5: 1호기 | AA5: 2호기
A6: 1월 | B6: 268.16 | C6: 1564.89 | D6: =B6+C6 -> 1833.05 | E6: 141 | F6: 391 | G6: 603 | H6: 353 | I6: 1218 | J6: 5438 | K6: =SUM(I6:J6) -> 6656 | L6: =I6/E6 -> 8.6382979 | M6: =J6/F6 -> 13.907928 | N6: =L6+M6 -> 22.546226 | O6: 11500 | P6: =G6*$Z$6/1000 -> 39195 | Q6: 14007 | R6: =SUM(P6:Q6) -> 53202 | S6: =H6*$AA$6/1000 -> 29652 | T6: 62537 | U6: =SUM(S6:T6) -> 92189 | W6: =R6+U6 -> 145391 | Y6: 고정비 단가 | Z6: 65000 | AA6: 84000
A7: 2월 | B7: 418.16 | C7: 1953.77 | D7: =B7+C7 -> 2371.93 | E7: ='4. 2025 계획대비 가동실적'!U6 -> 222 | F7: 503.6 | G7: 450 | H7: 101 | I7: 2529 | J7: 7098 | K7: =SUM(I7:J7) -> 9627 | L7: =IFERROR(I7/E7,0) -> 11.391892 | M7: =IFERROR(J7/F7,0) -> 14.094519 | N7: =IFERROR(L7+M7," ") -> 25.486411 | O7: 11700 | P7: 42939 | Q7: 25936.8 | R7: =SUM(P7:Q7) -> 68875.8 | S7: 13932 | T7: 80963.5 | U7: =SUM(S7:T7) -> 94895.5 | W7: =R7+U7 -> 163771.3 | Y7: 변경 후 | Z7: 78000 | AA7: 96000
A8: 3월 | B8: 224.1 | C8: 2519.96 | D8: =B8+C8 -> 2744.06 | E8: 117 | F8: 686.3 | G8: 627 | H8: 24 | I8: 1049 | J8: 11663 | K8: =SUM(I8:J8) -> 12712 | L8: =IFERROR(I8/E8,0) -> 8.965812 | M8: =IFERROR(J8/F8,0) -> 16.994026 | N8: =IFERROR(L8+M8," ") -> 25.959838 | O8: 11700 | P8: =G8*$Z$7/1000 -> 48906 | Q8: 11489.4 | R8: =SUM(P8:Q8) -> 60395.4 | S8: =H8*$AA$7/1000 -> 2304 | T8: 112706.1 | U8: =SUM(S8:T8) -> 115010.1 | W8: =R8+U8 -> 175405.5
A9: 4월 | B9: 0 | C9: 1772.62 | D9: =B9+C9 -> 1772.62 | E9: 0 | F9: 478 | G9: 720 | H9: 152 | I9: ='1. 도급내역'!U38 -> 0 | J9: 7678 | K9: =SUM(I9:J9) -> 7678 | L9: =IFERROR(I9/E9,0) -> 0 | M9: =IFERROR(J9/F9,0) -> 16.062762 | N9: =IFERROR(L9+M9," ") -> 16.062762 | O9: 11700 | P9: =G9*$Z$7/1000 -> 56160 | Q9: ='1. 도급내역'!E38/1000 -> 0 | R9: =SUM(P9:Q9) -> 56160 | S9: =H9*$AA$7/1000 -> 14592 | T9: 79255.8 | U9: =SUM(S9:T9) -> 93847.8 | V9: -33.54 | W9: =R9+U9+V9 -> 149974.26 | Y9: * 2/20이후 9bar운전, 운영비 결산시 1호기 10톤/시간, 2호기-14톤/시간 일괄 적용 (기준 초과분에 대해서만 적용)
A10: 5월 | B10: 0 | C10: 1693.68 | D10: =B10+C10 -> 1693.68 | E10: 0 | F10: 455.3 | G10: 744 | H10: 263 | I10: 0 | J10: 7016 | K10: =SUM(I10:J10) -> 7016 | L10: =IFERROR(I10/E10,0) -> 0 | M10: =IFERROR(J10/F10,0) -> 15.40962 | N10: =IFERROR(L10+M10," ") -> 15.40962 | O10: 11700 | P10: =G10*$Z$7/1000 -> 58032 | Q10: =I10*O10/1000 -> 0 | R10: =SUM(P10:Q10) -> 58032 | S10: =H10*$AA$7/1000 -> 25248 | T10: 74763 | U10: =SUM(S10:T10) -> 100011 | W10: =R10+U10+V10 -> 158043
A11: 6월 | B11: 0 | C11: 1903.87 | D11: =B11+C11 -> 1903.87 | E11: 0 | F11: 513 | G11: 720 | H11: 207 | I11: 0 | J11: 6746 | K11: =SUM(I11:J11) -> 6746 | L11: =IFERROR(I11/E11,0) -> 0 | M11: =IFERROR(J11/F11,0) -> 13.150097 | N11: =IFERROR(L11+M11," ") -> 13.150097 | O11: 11700 | P11: =G11*$Z$7/1000 -> 56160 | Q11: =I11*O11/1000 -> 0 | R11: =SUM(P11:Q11) -> 56160 | S11: =H11*$AA$7/1000 -> 19872 | T11: 78928.2 | U11: =SUM(S11:T11) -> 98800.2 | W11: =R11+U11+V11 -> 154960.2
A12: 7월 | B12: 0 | C12: 1893.26 | D12: =B12+C12 -> 1893.26 | E12: 0 | F12: 481.4 | G12: 744 | H12: 201 | I12: 0 | J12: 6946 | K12: =SUM(I12:J12) -> 6946 | L12: =IFERROR(I12/E12,0) -> 0 | M12: =IFERROR(J12/F12,0) -> 14.428749 | N12: =IFERROR(L12+M12," ") -> 14.428749 | O12: 11700 | P12: =G12*$Z$7/1000 -> 58032 | Q12: =I12*O12/1000 -> 0 | R12: =SUM(P12:Q12) -> 58032 | S12: =H12*$AA$7/1000 -> 19296 | T12: 76974.3 | U12: =SUM(S12:T12) -> 96270.3 | W12: =R12+U12+V12 -> 154302.3
A13: 8월 | B13: 0 | C13: 1841.18 | D13: =B13+C13 -> 1841.18 | E13: 0 | F13: 499 | G13: 744 | H13: 245 | I13: 0 | J13: 6783 | K13: =SUM(I13:J13) -> 6783 | L13: =IFERROR(I13/E13,0) -> 0 | M13: =IFERROR(J13/F13,0) -> 13.593186 | N13: =IFERROR(L13+M13," ") -> 13.593186 | O13: 11700 | P13: =G13*$Z$7/1000 -> 58032 | Q13: =I13*O13/1000 -> 0 | R13: =SUM(P13:Q13) -> 58032 | S13: =H13*$AA$7/1000 -> 23520 | T13: 78659.1 | U13: =SUM(S13:T13) -> 102179.1 | V13: -193.79 | W13: =R13+U13+V13 -> 160017.31
A14: 9월 | B14: 0 | C14: 2077.86 | D14: =B14+C14 -> 2077.86 | E14: 0 | F14: 529.3 | G14: =24*30 -> 720 | H14: 190.7 | I14: 0 | J14: 7154 | K14: =SUM(I14:J14) -> 7154 | L14: =IFERROR(I14/E14,0) -> 0 | M14: =IFERROR(J14/F14,0) -> 13.515964 | N14: =IFERROR(L14+M14," ") -> 13.515964 | O14: 11700 | P14: =G14*$Z$7/1000 -> 56160 | Q14: =I14*O14/1000 -> 0 | R14: =SUM(P14:Q14) -> 56160 | S14: =H14*$AA$7/1000 -> 18307.2 | T14: 83116.8 | U14: =SUM(S14:T14) -> 101424 | W14: =R14+U14 -> 157584
A15: 10월 | B15: 0 | C15: 1281.52 | D15: =B15+C15 -> 1281.52 | E15: 0 | F15: 342.5 | G15: 744 | H15: ='1. 도급내역'!M38 -> 305 | J15: ='4. 2025 계획대비 가동실적'!AA14 -> 4871 | K15: =SUM(I15:J15) -> 4871 | L15: =IFERROR(I15/E15,0) -> 0 | M15: =IFERROR(J15/F15,0) -> 14.221898 | N15: =IFERROR(L15+M15," ") -> 14.221898 | O15: 11700 | P15: =G15*$Z$7/1000 -> 58032 | Q15: =I15*O15/1000 -> 0 | R15: =SUM(P15:Q15) -> 58032 | S15: =H15*$AA$7/1000 -> 29280 | T15: ='1. 도급내역'!L38/1000 -> 55738.8 | U15: =SUM(S15:T15) -> 85018.8 | W15: =R15+U15 -> 143050.8
A16: 11월 | D16: =B16+C16 -> 0 | K16: =SUM(I16:J16) -> 0 | L16: =IFERROR(I16/E16,0) -> 0 | M16: =IFERROR(J16/F16,0) -> 0 | N16: =IFERROR(L16+M16," ") -> 0 | O16: 11700 | P16: =G16*$Z$7/1000 -> 0 | Q16: =I16*O16/1000 -> 0 | R16: =SUM(P16:Q16) -> 0 | S16: =H16*$AA$7/1000 -> 0 | T16: =J16*O16/1000 -> 0 | U16: =SUM(S16:T16) -> 0 | W16: =R16+U16 -> 0
A17: 12월 | D17: =B17+C17 -> 0 | K17: =SUM(I17:J17) -> 0 | L17: =IFERROR(I17/E17,0) -> 0 | M17: =IFERROR(J17/F17,0) -> 0 | N17: =IFERROR(L17+M17," ") -> 0 | O17: 11700 | P17: =G17*$Z$7/1000 -> 0 | Q17: =I17*O17/1000 -> 0 | R17: =SUM(P17:Q17) -> 0 | S17: =H17*$AA$7/1000 -> 0 | T17: =J17*O17/1000 -> 0 | U17: =SUM(S17:T17) -> 0 | W17: =R17+U17 -> 0
A18: 합 계 | B18: =SUM(B6:B17) -> 910.42 | C18: =SUM(C6:C17) -> 18502.61 | D18: =SUM(D6:D17) -> 19413.03 | E18: =SUM(E6:E17) -> 480 | F18: =SUM(F6:F17) -> 4879.4 | G18: =SUM(G6:G17) -> 6816 | H18: =SUM(H6:H17) -> 2041.7 | I18: =SUM(I6:I17) -> 4796 | ... W18: =SUM(W6:W17) -> 1562499.7
A19: 월평균 | B19: =AVERAGE(B6:B17) -> 91.042 | C19: =AVERAGE(C6:C17) -> 1850.261 | D19: =AVERAGE(D6:D17) -> 1617.7525 | E19: =AVERAGE(E6:E17) -> 48 | F19: =AVERAGE(F6:F17) -> 487.94 | G19: =AVERAGE(G6:G17) -> 681.6 | H19: =AVERAGE(H6:H17) -> 204.17 | I19: =AVERAGE(I6:I17) -> 532.88889 | ... W19: =AVERAGE(W6:W17) -> 130208.31
A20: 원단위 | B20: =B18/E18 -> 1.8967083 | C20: =C18/F18 -> 3.7919847 | I20: =I18/E18 -> 9.9916667 | J20: =J18/F18 -> 14.631512 | K20: =I20+J20 -> 24.623179 | L20: =L19 -> 2.4163335 | M20: =M19 -> 12.114896 | N20: =L20+M20 -> 14.531229 | O20: =W18*1000/K18 -> 20508.206 | P20: =P18*1000/$B$18 -> 583959.05 | Q20: =Q18*1000/$B$18 -> 56493.926 | R20: =R18*1000/$B$18 -> 640452.98 | S20: =S18*1000/$C$18 -> 10593.273 | T20: =T18*1000/$C$18 -> 42353.084 | U20: =U18*1000/$C$18 -> 52946.357 | W20: =W18*1000/D18 -> 80487.161
A21: 단위 | B21: 톤/hr | C21: 톤/hr | I21: 톤/hr | J21: 톤/hr | K21: 톤/hr | L21: 톤/hr | M21: 톤/hr | N21: 톤/hr | O21: 원/톤.스팀 | P21: =P18*1000/$I$18 -> 110852.38 | Q21: =Q18*1000/$I$18 -> 10724.187 | R21: =R18*1000/I18 -> 121576.56 | S21: =S18*1000/$J$18 -> 2745.412 | T21: =T18*1000/$J$18 -> 10976.463 | U21: =U18*1000/K18 -> 12858.1 | W21: 원/처리량
A24: 2025 | B24: 자체 운영비용
B25: 외부 폐합성수지 수익금(톤, 천원) | D25: 폐기물 처리량(톤) | J25: 폐기물처리비용(천원) | N25: 전력비용(Kw, 천원) | S25: 가성소다 (Kg, 천원) | V25: 기타 운영비용(천원) | Z25: 비용합계 | AA25: 원단위
B26: 입고량 | C26: 수익비용 | D26: 바닥재(재활용) | E26: 바닥재(매립) | F26: 바닥재 소계 | G26: 비산재(고형화) | H26: 비산재(매립) | I26: 비산재 소계 | J26: 바닥재 | K26: 비산재 | L26: 기타(내화물 등) | M26: 비용소계 | N26: 1호기사용량 | O26: 2호기사용량 | P26: 사용량합계 | Q26: 전력단가 | R26: 비용소계 | S26: 구입량 | T26: 단가 | U26: 구입비용 | V26: 용수사용비 | W26: 폐기물처분부담금 | X26: 기타 | Y26: 비용소계 | AA26: 처리량당 비용 | AB26: 스팀톤당 비용
A27: 1월 | B27: 642.04 | C27: 29122.99 | D27: 168.97 | E27: 0 | F27: =SUM(D27:E27) -> 168.97 | G27: 0 | H27: 35.63 | I27: =SUM(G27:H27) -> 35.63 | J27: 8617.47 | K27: 4311.23 | L27: 0 | M27: =SUM(J27:L27) -> 12928.7 | N27: 54080 | O27: 184216 | P27: =SUM(N27:O27) -> 238296 | Q27: 194.06 | R27: =P27*Q27/1000 -> 46243.722 | S27: 7990 | T27: 335 | U27: =S27*T27/1000 -> 2676.65 | V27: =(40946*49.81)/1000 -> 2039.5203 | W27: =E27*10000*1.192/1000 -> 0 | X27: 0 | Y27: =SUM(V27:X27) -> 2039.5203 | Z27: =SUM(-C27,M27,R27,U27,Y27) -> 34765.602 | AA27: =Z27*1000/D6 -> 18965.987 | AB27: =Z27*1000/K6 -> 5223.1974
A28: 2월 | B28: 803.4 | C28: 40611.01 | D28: 287.16 | E28: 0 | F28: =SUM(D28:E28) -> 287.16 | G28: 0 | H28: 44.76 | I28: =SUM(G28:H28) -> 44.76 | J28: 14645.16 | K28: 5415.96 | L28: 0 | M28: =SUM(J28:L28) -> 20061.12 | N28: 61360 | O28: 170296 | P28: =SUM(N28:O28) -> 231656 | Q28: 195.36 | R28: =P28*Q28/1000 -> 45256.316 | S28: 0 | T28: 335 | U28: =S28*T28/1000 -> 0 | V28: =(33481*50.21)/1000 -> 1681.081 | W28: =E28*10000*1.132/1000 -> 0 | X28: 0 | Y28: =SUM(V28:X28) -> 1681.081 | Z28: =SUM(-C28,M28,R28,U28,Y28) -> 26387.507 | AA28: =IFERROR(Z28*1000/D7,0) -> 11124.91 | AB28: =IFERROR(Z28*1000/K7," ") -> 2740.9896
A29: 3월 | B29: 1446.02 | C29: 69756.89 | D29: 262.87 | E29: 0 | F29: =SUM(D29:E29) -> 262.87 | G29: 32.81 | H29: 0 | I29: =SUM(G29:H29) -> 32.81 | J29: 13406.37 | K29: 6603.6 | L29: 0 | M29: =SUM(J29:L29) -> 20009.97 | N29: 65490 | O29: 220032 | P29: =SUM(N29:O29) -> 285522 | Q29: 167.95 | R29: =P29*Q29/1000 -> 47953.42 | S29: 0 | T29: 335 | U29: =S29*T29/1000 -> 0 | V29: =(39358*44.03)/1000 -> 1732.9327 | W29: =E29*10000*1.168/1000 -> 0 | X29: 0 | Y29: =SUM(V29:X29) -> 1732.9327 | Z29: =SUM(-C29,M29,R29,U29,Y29) -> -60.56736 | AA29: =IFERROR(Z29*1000/D8,0) -> -22.07217 | AB29: =IFERROR(Z29*1000/K8," ") -> -4.7645815
A30: 4월 | B30: 787.58 | C30: 36299.56 | D30: 336.84 | E30: 0 | F30: =SUM(D30:E30) -> 336.84 | G30: 23.49 | H30: 20.53 | I30: =SUM(G30:H30) -> 44.02 | J30: 17178.84 | K30: 5302.93 | L30: 0 | M30: =SUM(J30:L30) -> 22481.77 | N30: 39520 | O30: 192072 | P30: =SUM(N30:O30) -> 231592 | Q30: 165.9 | R30: =P30*Q30/1000 -> 38421.113 | S30: 0 | T30: 335 | U30: =S30*T30/1000 -> 0 | V30: =(37618*44.56)/1000 -> 1676.2581 | W30: =E30*10000*1.132/1000 -> 0 | X30: 0 | Y30: =SUM(V30:X30) -> 1676.2581 | Z30: =SUM(-C30,M30,R30,U30,Y30) -> 26279.581 | AA30: =IFERROR(Z30*1000/D9,0) -> 14825.276 | AB30: =IFERROR(Z30*1000/K9," ") -> 3422.7118
A31: 5월 | B31: 474.75 | C31: 22420.75 | D31: 264.45 | E31: 0 | F31: =SUM(D31:E31) -> 264.45 | G31: 44.49 | H31: 0 | I31: =SUM(G31:H31) -> 44.49 | J31: 13486.95 | K31: 5338.8 | L31: 0 | M31: =SUM(J31:L31) -> 18825.75 | N31: 29432 | O31: 183080 | P31: =SUM(N31:O31) -> 212512 | Q31: 175.68 | R31: =P31*Q31/1000 -> 37334.108 | S31: 0 | T31: 335 | U31: =S31*T31/1000 -> 0 | V31: =(33997*44.6)/1000 -> 1516.2662 | W31: =E31*10000*1.132/1000 -> 0 | X31: 0 | Y31: =SUM(V31:X31) -> 1516.2662 | Z31: =SUM(-C31,M31,R31,U31,Y31) -> 35255.374 | AA31: =IFERROR(Z31*1000/D10," ") -> 20815.841 | AB31: =IFERROR(Z31*1000/K10," ") -> 5024.9963
A32: 6월 | B32: 436.59 | C32: 24266.56 | D32: 204.07 | E32: 0 | F32: =SUM(D32:E32) -> 204.07 | G32: 20.35 | H32: 0 | I32: =SUM(G32:H32) -> 20.35 | J32: 10407.57 | K32: 2442 | L32: 0 | M32: =SUM(J32:L32) -> 12849.57 | N32: 38688 | O32: 178280 | P32: =SUM(N32:O32) -> 216968 | Q32: 192.67 | R32: =P32*Q32/1000 -> 41803.225 | S32: 0 | T32: 335 | U32: =S32*T32/1000 -> 0 | V32: =(38878*49.34)/1000 -> 1918.2405 | W32: =E32*10000*1.168/1000 -> 0 | X32: 0 | Y32: =SUM(V32:X32) -> 1918.2405 | Z32: =SUM(-C32,M32,R32,U32,Y32) -> 32304.475 | AA32: =IFERROR(Z32*1000/D11," ") -> 16967.795 | AB32: =IFERROR(Z32*1000/K11," ") -> 4788.6859
A33: 7월 | B33: 92.3 | C33: 5132.72 | D33: 118.13 | E33: 0 | F33: =SUM(D33:E33) -> 118.13 | G33: 40.52 | H33: 18.18 | I33: =SUM(G33:H33) -> 58.7 | J33: 6024.63 | K33: 7062.18 | L33: 0 | M33: =SUM(J33:L33) -> 13086.81 | N33: 48880 | O33: 163644 | P33: =SUM(N33:O33) -> 212524 | Q33: 196.56 | R33: =P33*Q33/1000 -> 41773.717 | S33: 0 | T33: 335 | U33: =S33*T33/1000 -> 0 | V33: =(36485*50.18)/1000 -> 1830.8173 | W33: =E33*10000*1.132/1000 -> 0 | X33: 0 | Y33: =SUM(V33:X33) -> 1830.8173 | Z33: =SUM(-C33,M33,R33,U33,Y33) -> 51558.625 | AA33: =IFERROR(Z33*1000/D12," ") -> 27232.723 | AB33: =IFERROR(Z33*1000/K12," ") -> 7422.7793
A34: 8월 | B34: 176.44 | C34: 8365.78 | D34: 204.98 | E34: 0 | F34: =SUM(D34:E34) -> 204.98 | G34: 21.98 | H34: 0 | I34: =SUM(G34:H34) -> 21.98 | J34: 10453.98 | K34: 2637.6 | L34: 0 | M34: =SUM(J34:L34) -> 13091.58 | N34: 45760 | O34: 163376 | P34: =SUM(N34:O34) -> 209136 | Q34: 191.4 | R34: =P34*Q34/1000 -> 40028.63 | S34: 0 | T34: 335 | U34: =S34*T34/1000 -> 0 | V34: =(39042*49.14)/1000 -> 1918.5239 | W34: =E34*10000*1.132/1000 -> 0 | X34: 0 | Y34: =SUM(V34:X34) -> 1918.5239 | Z34: =SUM(-C34,M34,R34,U34,Y34) -> 46672.954 | AA34: =IFERROR(Z34*1000/D13," ") -> 25349.479 | AB34: =IFERROR(Z34*1000/K13," ") -> 6880.8719
A35: 9월 | B35: 186.48 | C35: 12123.64 | D35: 253.79 | E35: 0 | F35: =SUM(D35:E35) -> 253.79 | G35: 0 | H35: 38.86 | I35: =SUM(G35:H35) -> 38.86 | J35: 12943.29 | K35: 4663.2 | L35: 0 | M35: =SUM(J35:L35) -> 17606.49 | N35: 38480 | O35: 153016 | P35: =SUM(N35:O35) -> 191496 | Q35: 169.42 | R35: =P35*Q35/1000 -> 32443.252 | S35: 0 | T35: 335 | U35: =S35*T35/1000 -> 0 | V35: =(25917*44.38)/1000 -> 1150.1965 | W35: =E35*10000*1.168/1000 -> 0 | X35: 0 | Y35: =SUM(V35:X35) -> 1150.1965 | Z35: =SUM(-C35,M35,R35,U35,Y35) -> 39076.299 | AA35: =IFERROR(Z35*1000/D14," ") -> 18806.031 | AB35: =IFERROR(Z35*1000/K14," ") -> 5462.1609
A36: 10월 | B36: 63.02 | C36: 4720.21 | D36: 145.75 | E36: 0 | F36: =SUM(D36:E36) -> 145.75 | G36: 0 | H36: 54.83 | I36: =SUM(G36:H36) -> 54.83 | J36: 7433.25 | K36: 6579.6 | L36: 0 | M36: =SUM(J36:L36) -> 14012.85 | N36: 37440 | O36: 132080 | P36: =SUM(N36:O36) -> 169520 | Q36: 168.27 | R36: =P36*Q36/1000 -> 28525.13 | S36: 0 | T36: 335 | U36: =S36*T36/1000 -> 0 | V36: =(18393*44.06)/1000 -> 810.39558 | W36: =E36*10000*1.132/1000 -> 0 | X36: 0 | Y36: =SUM(V36:X36) -> 810.39558 | Z36: =SUM(-C36,M36,R36,U36,Y36) -> 38628.166 | AA36: =IFERROR(Z36*1000/D15," ") -> 30142.461 | AB36: =IFERROR(Z36*1000/K15," ") -> 7930.2332
A37: 11월 | F37: =SUM(D37:E37) -> 0 | I37: =SUM(G37:H37) -> 0 | M37: =SUM(J37:L37) -> 0 | P37: =SUM(N37:O37) -> 0 | R37: =P37*Q37/1000 -> 0 | T37: 335 | U37: =S37*T37/1000 -> 0 | W37: =E37*10000*1.132/1000 -> 0 | X37: 0 | Y37: =SUM(V37:X37) -> 0 | Z37: =SUM(-C37,M37,R37,U37,Y37) -> 0 | AA37: =IFERROR(Z37*1000/D16," ") | AB37: =IFERROR(Z37*1000/K16," ")
A38: 12월 | F38: =SUM(D38:E38) -> 0 | I38: =SUM(G38:H38) -> 0 | M38: =SUM(J38:L38) -> 0 | P38: =SUM(N38:O38) -> 0 | R38: =P38*Q38/1000 -> 0 | T38: 335 | U38: =S38*T38/1000 -> 0 | W38: =E38*10000*1.132/1000 -> 0 | Y38: =SUM(V38:X38) -> 0 | Z38: =SUM(-C38,M38,R38,U38,Y38) -> 0 | AA38: =IFERROR(Z38*1000/D17," ") | AB38: =IFERROR(Z38*1000/K17," ")
A39: 합 계 | B39: =SUM(B27:B38) -> 5108.62 | C39: =SUM(C27:C38) -> 252820.11 | D39: =SUM(D27:D38) -> 2247.01 | E39: =SUM(E27:E38) -> 0 | F39: =SUM(F27:F38) -> 2247.01 | G39: =SUM(G27:G38) -> 183.64 | H39: =SUM(H27:H38) -> 212.79 | I39: =SUM(I27:I38) -> 396.43 | ... R39: =SUM(R27:R38) -> 399782.63 | U39: =SUM(U27:U38) -> 2676.65 | V39: =SUM(V27:V38) -> 16274.232 | W39: =SUM(W27:W38) -> 0 | X39: =SUM(X27:X38) -> 0 | Y39: =SUM(Y27:Y38) -> 16274.232 | Z39: =SUM(Z27:Z38) -> 330868.02 | AA39: =Z39*1000/D18 -> 17043.605 | AB39: =Z39*1000/K18 -> 4342.7268
A40: 월평균 | B40: =AVERAGE(B27:B38) -> 510.862 | C40: =AVERAGE(C27:C38) -> 25282.011 | D40: =AVERAGE(D27:D38) -> 224.701 | E40: =AVERAGE(E27:E38) -> 0 | F40: =AVERAGE(F27:F38) -> 187.25083 | G40: =AVERAGE(G27:G38) -> 18.364 | H40: =AVERAGE(H27:H38) -> 21.279 | I40: =AVERAGE(I27:I38) -> 33.035833 | ... R40: =AVERAGE(R27:R38) -> 33315.219 | U40: =AVERAGE(U27:U38) -> 223.05417 | V40: =AVERAGE(V27:V38) -> 1627.4232 | W40: =AVERAGE(W27:W38) -> 0 | X40: =AVERAGE(X27:X38) -> 0 | Y40: =AVERAGE(Y27:Y38) -> 1356.186 | Z40: =AVERAGE(Z27:Z38) -> 27572.335
A41: 원단위 | C41: =C39*1000/$K$18 -> 3318.3282 | F41: =F39/D18 -> 0.11574752 | I41: =I39/D18 -> 0.02042082 | M41: =M39*1000/$K$18 -> 2165.0712 | R41: =R39*1000/$K$18 -> 5247.2487 | U41: =U39*1000/$K$18 -> 35.131712 | Y41: =Y39*1000/$K$18 -> 213.60343 | Z41: =Z39*1000/$K$18 -> 4342.7268 | AA41: =AA39 -> 17043.605 | AB41: =AB39 -> 4342.7268
A42: 단위 | C42: 원/스팀 | F42: 톤.Ash/톤.소각 | I42: 톤.Ash/톤.소각 | M42: 원/스팀 | R42: 원/스팀 | U42: 원/스팀 | Y42: 원/스팀 | Z42: 원/스팀 | AA42: 원/처리량 | AB42: 원/스팀
V43: =AVERAGE(AA27:AA38) -> 18420.843
...

Sheet 6. 25년 사고이력
B2: '25년 폐합성소각로 설비 사고 이력
B4: No. | C4: 일 자 | D4: 사 유 | E4: 조치내역 | F4: 운휴시간(Hr) | G4: 손실금액(백만원) | H4: 비 고
B5: 1 | C5: 45704 | D5: 연료투입용 크레인 슬립링 이탈로 케이블 파손 운휴 | E5: 케이블 및 고정볼트 교체 (전기팀) | F5: 10.8 | G5: 7.3 | H5: -
B6: 2 | C6: 3/16~17 | D6: 폐기물 과다 투입으로 CO 및 Nox초과로 운휴 | F6: 33.5 | G6: 8.9 | H6: -
B7: 3 | C7: 45764 | D7: CO초과로 운휴 | E7: 1차 보일러 수관 누수처 보수 | F7: 33 | G7: 0 | H7: 제지3호기 정비로 LNG미가동
B8: 4 | C8: 4/19~21 | D8: CO초과로 운휴 | E8: 워터자켓 보온재 임시조치 | F8: 59.5 | G8: 25 | H8: -
B9: 5 | C9: 45843 | D9: CO초과로 운휴 | E9: TMS시간 준수 후 재가동 | F9: 11 | G9: 1.4 | H9: -
B10: 6 | C10: 7/14~15 | D10: 수관 누수 운휴 | E10: 수관 막음 조치 후 재가동 | F10: 31 | G10: 0 | H10: LNG미가동
B11: 7 | C11: 45860 | D11: 유인송풍기 진동 증가 운휴 | E11: 송풍기 필드밸런싱 후 재가동 | F11: 13 | H11: -
B12: 8 | C12: 45947 | D12: 폐기물 투입 호퍼 앵커 노출로 인한 연료 엉킴 | E12: 투입호퍼 막힘 해소 및 앵커 제거 | F12: 15.8 | G12: 9.1
B13: 9 | C13: 10/19~22 | D13: 램피더 동작불능 및 내화물 탈락 운휴 | E13: 램피더 프레임 및 내화물 보수 | F13: 63 | G13: 35.8 | H13: -
B14: 10 | C14: 45959 | D14: 유인송풍기 진동 증가 운휴 | E14: 임펠러 및 덕트 소제 | F14: 15 | G14: 0 | H14: 제지3호기 정비로 LNG미가동
B16: 발생횟수 | C16: =COUNTA(C5:C10) -> 6 | D16: 합 계 (Hr) | F16: =SUM(F5:F14) -> 285.6 | G16: =SUM(G5:G14) -> 87.5
D17: 합 계 (Day) | F17: =F16/24 -> 11.9
B21: 2. '25년 폐합성소각로 정기 정비 이력
B23: No. | C23: 일 자 | D23: 사 유 | E23: 조치내역 | F23: 운휴시간(Hr) | G23: 비 고
B34: 정비횟수 | C34: =COUNTA(C24:C33) -> 0 | D34: 합 계 (Hr) | F34: =SUM(F24:F33) -> 0
D35: 합 계 (Day) | F35: =F34/24 -> 0
G36: 총 운휴시간 | H36: =F16+F34 -> 285.6
G37: 총 운휴일수 | H37: =H36/24 -> 11.9
E38: .
