Workbook

Sheet 1. 운영실적
A1: 1. 유동상 소각로 위탁 운영비용 사업계획대비 실적 (단위: 백만원)
A3: 구 분 | B3: 1월 | E3: 2월 | H3: 3월 | K3: 4월 | N3: 5월 | Q3: 6월 | T3: 7월 | W3: 8월 | Z3: 9월 | AC3: 10월 | AF3: 11월 | AI3: 12월 | AL3: 합 계
B4: 계획 | C4: 실적 | D4: 증감 | E4: 계획 | F4: 실적 | G4: 증감 | H4: 계획 | I4: 실적 | J4: 증감 | K4: 계획 | L4: 실적 | M4: 증감 | N4: 계획 | O4: 실적 | P4: 증감 | Q4: 계획 | R4: 실적 | S4: 증감 | T4: 계획 | U4: 실적 | V4: 증감 | W4: 계획 | X4: 실적 | Y4: 증감 | Z4: 계획 | AA4: 실적 | AB4: 증감 | AC4: 계획 | AD4: 실적 | AE4: 증감 | AF4: 계획 | AG4: 실적 | AH4: 증감 | AI4: 계획 | AJ4: 실적 | AK4: 증감 | AL4: 계획 | AM4: 실적 | AN4: 증감
A5: 운영비 | B5: 345 | C5: 290.9316 | D5: =C5-B5 -> -54.0684 | E5: 333.7856 | F5: 287.18552 | G5: =F5-E5 -> -46.600084 | H5: 293.2448 | I5: 305.13218 | J5: =I5-H5 -> 11.887384 | K5: 354.056 | L5: 288.28613 | M5: =L5-K5 -> -65.769866 | N5: 293.2448 | O5: 324.71287 | P5: =O5-N5 -> 31.468074 | Q5: 283.1096 | R5: 289.44732 | S5: =R5-Q5 -> 6.337716 | T5: 364.1912 | U5: 314.93804 | V5: =U5-T5 -> -49.253164 | W5: 364.1912 | X5: 298.23335 | Y5: =X5-W5 -> -65.957854 | Z5: 354.056 | AA5: 339.31497 | AB5: =AA5-Z5 -> -14.741032 | AC5: 274.1432 | AD5: ='3. 세부 운영내역'!AK17/10^6 -> 326.35474 | AE5: =AD5-AC5 -> 52.211536 | AF5: 354.056 | AH5: =AG5-AF5 -> -354.056 | AI5: 364.1912 | AK5: =AJ5-AI5 -> -364.1912 | AL5: =SUM(B5,E5,H5,K5,N5,Q5,T5,W5,Z5,AC5,AF5,AI5) -> 3977.2696 | AM5: =SUM(C5,F5,I5,L5,O5,R5,U5,X5,AA5,AD5,AG5,AJ5) -> 3064.5367 | AN5: =AM5-AL5 -> -912.73289
A6: 전력비 | B6: 121.26569 | C6: 108.49332 | D6: =C6-B6 -> -12.772367 | E6: 124.41984 | F6: 102.0377 | G6: =F6-E6 -> -22.382137 | H6: 92.278154 | I6: 94.075849 | J6: =I6-H6 -> 1.7976944 | K6: 120.17817 | L6: 90.347481 | M6: =L6-K6 -> -29.830688 | N6: 95.566077 | O6: 101.111 | P6: =O6-N6 -> 5.5449185 | Q6: 103.46577 | R6: 104.25798 | S6: =R6-Q6 -> 0.79220238 | T6: 145.53626 | U6: 115.87644 | V6: =U6-T6 -> -29.659815 | W6: 142.57577 | X6: 106.51199 | Y6: =X6-W6 -> -36.063774 | Z6: 123.55266 | AA6: 101.85734 | AB6: =AA6-Z6 -> -21.695319 | AC6: 87.491179 | AD6: ='3. 세부 운영내역'!AK65/10^6 -> 102.10439 | AE6: =AD6-AC6 -> 14.613206 | AF6: 141.94793 | AH6: =AG6-AF6 -> -141.94793 | AI6: 146.90364 | AK6: =AJ6-AI6 -> -146.90364 | AL6: =SUM(B6,E6,H6,K6,N6,Q6,T6,W6,Z6,AC6,AF6,AI6) -> 1445.1811 | AM6: =SUM(C6,F6,I6,L6,O6,R6,U6,X6,AA6,AD6,AG6,AJ6) -> 1026.6735 | AN6: =AM6-AL6 -> -418.50765
A7: 폐기물처리비 | B7: 45.798372 | C7: 36.41135 | D7: =C7-B7 -> -9.3870216 | E7: 45.798372 | F7: 33.95949 | G7: =F7-E7 -> -11.838882 | H7: 39.255747 | I7: 42.16597 | J7: =I7-H7 -> 2.9102229 | K7: 49.069684 | L7: 30.23643 | M7: =L7-K7 -> -18.833254 | N7: 39.255747 | O7: 44.26812 | P7: =O7-N7 -> 5.0123729 | Q7: 37.620091 | R7: 36.38793 | S7: =R7-Q7 -> -1.232161 | T7: 50.70534 | U7: 41.69372 | V7: =U7-T7 -> -9.01162 | W7: 50.70534 | X7: 36.64323 | Y7: =X7-W7 -> -14.06211 | Z7: 49.069684 | AA7: 47.50944 | AB7: =AA7-Z7 -> -1.5602439 | AC7: 34.348779 | AD7: =SUM('3. 세부 운영내역'!AK49:AK62)/10^6 -> 50.44521 | AE7: =AD7-AC7 -> 16.096431 | AF7: 49.069684 | AH7: =AG7-AF7 -> -49.069684 | AI7: 50.70534 | AK7: =AJ7-AI7 -> -50.70534 | AL7: =SUM(B7,E7,H7,K7,N7,Q7,T7,W7,Z7,AC7,AF7,AI7) -> 541.40218 | AM7: =SUM(C7,F7,I7,L7,O7,R7,U7,X7,AA7,AD7,AG7,AJ7) -> 399.72089 | AN7: =AM7-AL7 -> -141.68129
A8: SRF수입금 | B8: -50.039405 | C8: -56.45611 | D8: =C8-B8 -> -6.4167053 | E8: -50.039405 | F8: -53.56009 | G8: =F8-E8 -> -3.5206853 | H8: -42.890918 | I8: -62.87792 | J8: =I8-H8 -> -19.987002 | K8: -53.613648 | L8: -56.57397 | M8: =L8-K8 -> -2.9603221 | N8: -42.890918 | O8: -68.72314 | P8: =O8-N8 -> -25.832222 | Q8: -41.103797 | R8: -62.10351 | S8: =R8-Q8 -> -20.999713 | T8: -55.40077 | U8: -64.37344 | V8: =U8-T8 -> -8.9726705 | W8: -55.40077 | X8: -65.4274 | Y8: =X8-W8 -> -10.02663 | Z8: -53.613648 | AA8: -84.56299 | AB8: =AA8-Z8 -> -30.949342 | AC8: -37.529554 | AD8: ='3. 세부 운영내역'!AK46/10^6 -> -72.26553 | AE8: =AD8-AC8 -> -34.735976 | AF8: -53.613648 | AH8: =AG8-AF8 -> 53.613648 | AI8: -55.40077 | AK8: =AJ8-AI8 -> 55.40077 | AL8: =SUM(B8,E8,H8,K8,N8,Q8,T8,W8,Z8,AC8,AF8,AI8) -> -591.53725 | AM8: =SUM(C8,F8,I8,L8,O8,R8,U8,X8,AA8,AD8,AG8,AJ8) -> -646.9241 | AN8: =AM8-AL8 -> -55.386851
A9: 총 금액 | B9: =SUM(B5:B8) -> 462.02465 | C9: =SUM(C5:C8) -> 379.38016 | D9: =SUM(D5:D8) -> -82.644494 | E9: =SUM(E5:E8) -> 453.9644 | F9: =SUM(F5:F8) -> 369.62262 | G9: =SUM(G5:G8) -> -84.341788 | H9: =SUM(H5:H8) -> 381.88778 | I9: =SUM(I5:I8) -> 378.49608 | ... X9: =SUM(X5:X8) -> 375.96117 | Y9: =X9-W9 -> -126.11037 | Z9: =SUM(Z5:Z8) -> 473.06469 | AA9: =SUM(AA5:AA8) -> 404.11875 | AB9: =AA9-Z9 -> -68.945937 | AC9: =SUM(AC5:AC8) -> 358.4536 | AD9: =SUM(AD5:AD8) -> 406.6388 | AE9: =AD9-AC9 -> 48.185197 | AF9: =SUM(AF5:AF8) -> 491.45997 | AG9: =SUM(AG5:AG8) -> 0 | AH9: =AG9-AF9 -> -491.45997 | AI9: =SUM(AI5:AI8) -> 506.39941 | AJ9: =SUM(AJ5:AJ8) -> 0 | AK9: =AJ9-AI9 -> -506.39941 | AL9: =SUM(AL5:AL8) -> 5372.3157 | AM9: =SUM(AM5:AM8) -> 3844.007 | AN9: =AM9-AL9 -> -1528.3087
A12: 구 분 | B12: `25년 10월 | E12: '25년 누계 | H12: `25년 9월 | I12: 전월 대비 | K12: 비 고
B13: 계 획 | C13: 실 적 | D13: 증 감 | E13: 계 획 | F13: 실 적 | G13: 증 감 | H13: 실 적 | I13: 증 감 | J13: 증감률(%)
A14: 위탁운영비(백만) | B14: =AC9 -> 358.4536 | C14: =AD9 -> 406.6388 | D14: =C14-B14 -> 48.185197 | E14: =AL9 -> 5372.3157 | F14: =AM9 -> 3844.007 | G14: =F14-E14 -> -1528.3087 | H14: =AA9 -> 404.11875 | I14: =C14-H14 -> 2.5200462 | J14: =I14/H14 -> 0.006235905
A16: 2. 유동상 소각로 위탁 운영비용 전년도 실적 및 비교 (단위:천원)
A18: 구 분 | C18: 1월 | D18: 2월 | E18: 3월 | F18: 4월 | G18: 5월 | H18: 6월 | I18: 7월 | J18: 8월 | K18: 9월 | L18: 10월 | M18: 11월 | N18: 12월 | O18: 합계
A19: 유동상 소각로 (합계) | B19: 2024실적 | C19: 392.6876 | D19: 383.06851 | E19: 369.99182 | F19: 320.64202 | G19: 402.87264 | H19: 256.90538 | I19: 407.01462 | J19: 381.04337 | K19: 374.89038 | L19: 323.17679 | M19: 378.64492 | N19: 314.01669 | O19: =SUM(C19:N19) -> 4304.9547
B20: 2025실적 | C20: =C9 -> 379.38016 | D20: =F9 -> 369.62262 | E20: =I9 -> 378.49608 | F20: =L9 -> 352.29607 | G20: =O9 -> 401.36885 | H20: =R9 -> 367.98971 | I20: =U9 -> 408.13476 | J20: =X9 -> 375.96117 | K20: =AA9 -> 404.11875 | L20: =AD9 -> 406.6388 | M20: =AG9 -> 0 | N20: =AJ9 -> 0 | O20: =SUM(C20:N20) -> 3844.007
B21: 증감 | C21: =C20-C19 -> -13.30744 | D21: =D20-D19 -> -13.445895 | E21: =E20-E19 -> 8.5042644 | F21: =F20-F19 -> 31.654058 | G21: =G20-G19 -> -1.5037903 | H21: =H20-H19 -> 111.08434 | I21: =I20-I19 -> 1.1201375 | J21: =J20-J19 -> -5.0822038 | ... O21: =O20-O19 -> -460.94775
A23: 유동상 소각로 정비 | B23: 1월 | C23: 1/13 제지 3호기 운휴시 동시운휴, 인버터 점검, 1/24~31 설 운휴기간 슬러지 감소로 운휴
B24: 2월 | C24: 2/7~11 제지 조단시 슬러지 재고 감소로 운휴
B25: 3월 | C25: 3/27~4/6 제지 조단기간 정비 시행 (내화물 보수, B/F클리닝)
B26: 4월 | C26: 4/1~4/4 제지 조단기간 운휴, 4/5~6 내화물 큐어링으로 인한 추가 운휴, 4/28~30 제지 조단기간 운휴
B27: 5월 | C27: 5/1~4 제지 조단기간 운휴
B28: 6월 | C28: 6/11~16 제지2 운휴로 인한 스팀사용량 감소로 설비 운휴
B29: 7월 | C29: 7/4~9 제지2 운휴로 인한 스팀사용량 감소로 설비 운휴
B30: 8월 | C30: 8/16~21정기정비 운휴 (고정비 지급 처리)
B31: 9월 | C31: 9/2 제지3호기 정비시 운휴
B32: 10월 | C32: 10/6~8 추석 연휴기간 스팀사용량 감소로 설비 운휴
B33: 11월
B34: 12월

Sheet 2. 운영실적
B1: 1. 2025년 10월 소각로 도급비용
B3: 일별 | C3: 유동상 소각로
C4: 스팀 구매량 / 운휴시간 | J4: 총 운영비용(원)
C5: 스팀 생산량 | E5: 스팀단가 (원/톤) | F5: 운영비용(원) | G5: 운휴시간(Hr) | H5: 운휴시간당 고정비(원/시간) | I5: 운영비용(원)
C6: (T/D) | D6: (T/hr)
B7: 1일 | D7: =C7/24 -> 0 | F7: =C7*E7 -> 0 | G7: 0 | I7: =G7*H7 -> 0 | J7: =F7+I7 -> 0
B8: 2일 | D8: =C8/24 -> 0 | F8: =C8*E8 -> 0 | G8: 0 | I8: =G8*H8 -> 0 | J8: =F8+I8 -> 0
B9: 3일 | D9: =C9/24 -> 0 | F9: =C9*E9 -> 0 | G9: 0 | I9: =G9*H9 -> 0 | J9: =F9+I9 -> 0
B10: 4일 | D10: =C10/24 -> 0 | F10: =C10*E10 -> 0 | G10: 0 | I10: =G10*H10 -> 0 | J10: =F10+I10 -> 0
B11: 5일 | D11: =C11/24 -> 0 | F11: =C11*E11 -> 0 | G11: 0 | I11: =G11*H11 -> 0 | J11: =F11+I11 -> 0
B12: 6일 | D12: =C12/24 -> 0 | F12: =C12*E12 -> 0 | G12: 0 | I12: =G12*H12 -> 0 | J12: =F12+I12 -> 0
B13: 7일 | D13: =C13/24 -> 0 | F13: =C13*E13 -> 0 | G13: 0 | I13: =G13*H13 -> 0 | J13: =F13+I13 -> 0
B14: 8일 | D14: =C14/24 -> 0 | F14: =C14*E14 -> 0 | G14: 0 | I14: =G14*H14 -> 0 | J14: =F14+I14 -> 0
B15: 9일 | D15: =C15/24 -> 0 | F15: =C15*E15 -> 0 | G15: 0 | I15: =G15*H15 -> 0 | J15: =F15+I15 -> 0
B16: 10일 | D16: =C16/24 -> 0 | F16: =C16*E16 -> 0 | G16: 0 | I16: =G16*H16 -> 0 | J16: =F16+I16 -> 0
B17: 11일 | D17: =C17/24 -> 0 | F17: =C17*E17 -> 0 | G17: 0 | I17: =G17*H17 -> 0 | J17: =F17+I17 -> 0
B18: 12일 | D18: =C18/24 -> 0 | F18: =C18*E18 -> 0 | G18: 0 | I18: =G18*H18 -> 0 | J18: =F18+I18 -> 0
... B34: 28일 | D34: =C34/24 -> 0 | F34: =C34*E34 -> 0 | G34: 0 | I34: =G34*H34 -> 0 | J34: =F34+I34 -> 0
B35: 29일 | D35: =C35/24 -> 0 | F35: =C35*E35 -> 0 | G35: 0 | J35: =F35+I35 -> 0
B36: 30일 | D36: =C36/24 -> 0 | F36: =C36*E36 -> 0 | G36: 0 | I36: =G36*H36 -> 0 | J36: =F36+I36 -> 0
B37: 31일 | D37: =C37/24 -> 0 | F37: =C37*E37 -> 0 | G37: 0 | I37: =G37*H37 -> 0 | J37: =F37+I37 -> 0
B38: 합 계 | C38: =SUM(C7:C37) -> 0 | F38: =SUM(F7:F37) -> 0 | G38: =SUM(G7:G36) -> 0 | I38: =SUM(I7:I37) -> 0 | J38: =SUM(J7:J37) -> 0
B39: 평 균 | C39: =AVERAGE(C7:C36) -> #DIV/0! | D39: =C39/24 -> #DIV/0! | F39: =AVERAGE(F7:F36) -> 0 | G39: =AVERAGE(G7:G36) -> 0 | I39: =AVERAGE(I7:I36) -> 0 | J39: =AVERAGE(J7:J36) -> 0
H41: [단위 : 원]
D42: 설비명 | E42: 인건비 | F42: 운영비 | G42: 설비개선비용 | H42: 총 지급비용
D43: 유동상소각로 | E43: 122450000 | F43: =H43-E43 -> -72450000 | G43: 50000000 | H43: =J38+G43 -> 50000000

Sheet 3. 세부 운영내역
B1: 유동상 소각로 운영현황 및 비용 (2025. 10월)
A3: 구 분 | C3: 1 | D3: 2 | E3: 3 | F3: 4 | G3: 5 | H3: 6 | I3: 7 | J3: 8 | K3: 9 | L3: 10 | M3: 11 | N3: 12 | O3: 13 | P3: 14 | Q3: 15 | R3: 16 | S3: 17 | T3: 18 | U3: 19 | V3: 20 | W3: 21 | X3: 22 | Y3: 23 | Z3: 24 | AA3: 25 | AB3: 26 | AC3: 27 | AD3: 28 | AE3: 29 | AF3: 30 | AG3: 31 | AH3: 합계 | AI3: 평균 | AJ3: 단가 | AK3: 비용
A4: 가동시간 | B4: HR | C4: 24 | D4: 24 | E4: 24 | F4: 24 | G4: 24 | H4: 0 | I4: 0 | J4: 12.5 | K4: 24 | L4: 24 | M4: 24 | N4: 24 | O4: 24 | P4: 24 | Q4: 24 | R4: 24 | S4: 24 | T4: 24 | U4: 24 | V4: 24 | W4: 24 | X4: 24 | Y4: 24 | Z4: 24 | AA4: 24 | AB4: 24 | AC4: 24 | AD4: 24 | AE4: 24 | AF4: 24 | AG4: 24 | AH4: =SUM(C4:AG4) -> 684.5 | AI4: =AVERAGE(C4:AG4) -> 22.080645
A5: 운휴시간 | C5: =24-C4 -> 0 | D5: =24-D4 -> 0 | E5: =24-E4 -> 0 | F5: =24-F4 -> 0 | G5: =24-G4 -> 0 | H5: =24-H4 -> 24 | I5: =24-I4 -> 24 | J5: =24-J4 -> 11.5 | ... AG5: =24-AG4 -> 0 | AH5: =SUM(C5:AG5) -> 59.5 | AI5: =AVERAGE(C5:AG5) -> 1.9193548
A6: 스팀 | B6: 스팀 생산량 (톤) | C6: 504.3 | D6: 462.7 | E6: 492 | F6: 488.4 | G6: 480.8 | H6: 23.6 | I6: 0 | J6: 260.7 | K6: 470.6 | L6: 480.8 | M6: 468 | N6: 489 | O6: 483.4 | P6: 495.8 | Q6: 502.7 | R6: 495.7 | S6: 496.9 | T6: 514.1 | U6: 515.3 | V6: 553.4 | W6: 542.1 | X6: 533.8 | Y6: 530.7 | Z6: 513.3 | AA6: 489.5 | AB6: 489.5 | AC6: 512.5 | AD6: 496.9 | AE6: 452.2 | AF6: 490.6 | AG6: 494.3 | AH6: =SUM(C6:AG6) -> 14223.6 | AI6: =AVERAGE(C6:AG6) -> 458.82581 | AK6: =AJ6*AH6 -> 0
B7: 스팀 송기량 (톤) | C7: 293 | D7: 161 | E7: 234 | F7: 245 | G7: 231 | H7: 0 | I7: 0 | J7: 158 | K7: 288 | L7: 285 | M7: 273 | N7: 318 | O7: 368 | P7: 310 | Q7: 409 | R7: 329 | S7: 417 | T7: 409 | U7: 419 | V7: 464 | W7: 430 | X7: 434 | Y7: 440 | Z7: 397 | AA7: 296 | AB7: 208 | AC7: 210 | AD7: 300 | AE7: 210 | AF7: 315 | AG7: 287 | AH7: =SUM(C7:AG7) -> 9138 | AI7: =AVERAGE(C7:AG7) -> 294.77419 | AK7: =AJ7*AH7 -> 0
A8: 소각량 | B8: 슬러지 (톤) | C8: 190 | D8: 165.1 | E8: 174.5 | F8: 165.7 | G8: 161.3 | H8: 0 | I8: 0 | J8: 81 | K8: 148.8 | L8: 129.8 | M8: 122.5 | N8: 176.6 | O8: 160.2 | P8: 152 | Q8: 186.9 | R8: 174.1 | S8: 192.4 | T8: 172.4 | U8: 147.1 | V8: 166.9 | W8: 160.8 | X8: 182 | Y8: 177.4 | Z8: 194.9 | AA8: 164.2 | AB8: 187 | AC8: 164.2 | AD8: 169.6 | AE8: 146.2 | AF8: 142.8 | AG8: 178.5 | AH8: =SUM(C8:AG8) -> 4734.9 | AI8: =AVERAGE(C8:AG8) -> 152.73871 | AK8: =AJ8*AH8 -> 0
B9: SRF (톤) | C9: 63.052 | D9: 70.504 | E9: 72.324 | F9: 61.984 | G9: 73.192 | H9: 0 | I9: 0 | J9: 34.594 | K9: 70.264 | L9: 76.522 | M9: 67.01 | N9: 55.744 | O9: 59.934 | P9: 72.726 | Q9: 60.634 | R9: 72.246 | S9: 68.59 | T9: 72.596 | U9: 74.65 | V9: 84.842 | W9: 81.386 | X9: 82.864 | Y9: 75.652 | Z9: 71.086 | AA9: 67.864 | AB9: 77.024 | AC9: 82.57 | AD9: 72.304 | AE9: 70.624 | AF9: 79.358 | AG9: 64.872 | AH9: =SUM(C9:AG9) -> 2037.012 | AI9: =AVERAGE(C9:AG9) -> 65.710065 | AK9: =AJ9*AH9 -> 0
B10: 소각량 | C10: =C8+C9 -> 253.052 | D10: =D8+D9 -> 235.604 | E10: =E8+E9 -> 246.824 | F10: =F8+F9 -> 227.684 | G10: =G8+G9 -> 234.492 | H10: =H8+H9 -> 0 | I10: =I8+I9 -> 0 | J10: =J8+J9 -> 115.594 | ... AG10: =AG8+AG9 -> 243.372 | AH10: =SUM(C10:AG10) -> 6771.912 | AI10: =AVERAGE(C10:AG10) -> 218.44877
A11: KNE지급비용 | B11: 스팀단가 (원/톤) | C11: 18760 | D11: 18760 | E11: 18760 | F11: 18760 | G11: 18760 | H11: 18760 | I11: 18760 | J11: 18760 | K11: 18760 | L11: 18760 | M11: 18760 | N11: 18760 | O11: 18760 | P11: 18760 | Q11: 18760 | R11: 18760 | S11: 18760 | T11: 18760 | U11: 18760 | V11: 18760 | W11: 18760 | X11: 18760 | Y11: 18760 | Z11: 18760 | AA11: 18760 | AB11: 18760 | AC11: 18760 | AD11: 18760 | AE11: 18760 | AF11: 18760 | AG11: 18760
B12: 스팀 구매비 (원/일) | C12: =C6*C11 -> 9460668 | D12: =D6*D11 -> 8680252 | E12: =E6*E11 -> 9229920 | F12: =F6*F11 -> 9162384 | G12: =G6*G11 -> 9019808 | H12: =H6*H11 -> 442736 | I12: =I6*I11 -> 0 | J12: =J6*J11 -> 4890732 | ... AG12: =AG6*AG11 -> 9273068 | AH12: =SUM(C12:AG12) -> 266834736 | AI12: =AVERAGE(C12:AG12) -> 8607572.1 | AK12: =AH12 -> 266834736
B13: 운휴시간 단가(원/시간) | C13: 160000 | D13: 160000 | E13: 160000 | F13: 160000 | G13: 160000 | H13: 160000 | I13: 160000 | J13: 160000 | K13: 160000 | L13: 160000 | M13: 160000 | N13: 160000 | O13: 160000 | P13: 160000 | Q13: 160000 | R13: 160000 | S13: 160000 | T13: 160000 | U13: 160000 | V13: 160000 | W13: 160000 | X13: 160000 | Y13: 160000 | Z13: 160000 | AA13: 160000 | AB13: 160000 | AC13: 160000 | AD13: 160000 | AE13: 160000 | AF13: 160000 | AG13: 160000
B14: 고정비(원/일) | C14: =C13*C5 -> 0 | D14: =D13*D5 -> 0 | E14: =E13*E5 -> 0 | F14: =F13*F5 -> 0 | G14: =G13*G5 -> 0 | H14: =H13*H5 -> 3840000 | I14: =I13*I5 -> 3840000 | J14: =J13*J5 -> 1840000 | ... AE14: =AE13*AE5 -> 0 | AG14: =AG13*AG5 -> 0 | AH14: =SUM(C14:AG14) -> 9520000 | AI14: =AVERAGE(C14:AG14) -> 317333.33 | AK14: =AH14 -> 9520000
B15: 설비개선비용 | AK15: 50000000
B16: 추가비용
B17: 운영비 합계 (원/월) | AK17: =SUM(AK12:AK15) -> 326354736
A18: 탄산암모늄 (KG) | B18: 반입 | C18: 6200 | D18: 7350 | E18: 0 | F18: 0 | G18: 8040 | H18: 0 | I18: 0 | J18: 0 | K18: 0 | L18: 7980 | M18: 0 | N18: 0 | O18: 10420 | P18: 0 | Q18: 5390 | R18: 0 | S18: 6890 | T18: 0 | U18: 0 | V18: 7890 | W18: 0 | X18: 6250 | Y18: 0 | Z18: 10000 | AA18: 0 | AB18: 0 | AC18: 8120 | AD18: 0 | AE18: 7260 | AF18: 0 | AG18: 5770 | AH18: =SUM(C18:AG18) -> 97560 | AI18: =IFERROR(AVERAGE(C18:AG18),"") -> 3147.0968 | AJ18: 380 | AK18: =AH18*AJ18 -> 37072800
B19: 사용 | C19: 3427 | D19: 3129 | E19: 3773 | F19: 3506 | G19: 3085 | H19: 0 | I19: 0 | J19: 1682 | K19: 3048 | L19: 2250 | M19: 3182 | N19: 3064 | O19: 3372 | P19: 3455 | Q19: 3229 | R19: 3727 | S19: 2984 | T19: 3773 | U19: 3439 | V19: 3178 | W19: 3227 | X19: 2674 | Y19: 3455 | Z19: 3209 | AA19: 3182 | AB19: 2636 | AC19: 2935 | AD19: 3545 | AE19: 2690 | AF19: 3045 | AG19: 2876 | AH19: =SUM(C19:AG19) -> 90777 | AI19: =IFERROR(AVERAGE(C19:AG19),"") -> 2928.2903 | AJ19: =AJ18 -> 380 | AK19: =AH19*AJ19 -> 34495260
B20: 재고 | C20: =9441+C18-C19 -> 12214 | D20: =C20+D18-D19 -> 16435 | E20: =D20+E18-E19 -> 12662 | F20: =E20+F18-F19 -> 9156 | G20: =F20+G18-G19 -> 14111 | H20: =G20+H18-H19 -> 14111 | I20: =H20+I18-I19 -> 14111 | J20: =I20+J18-J19 -> 12429 | K20: =J20+K18-K19 -> 9381 | ... AG20: =AF20+AG18-AG19 -> 16224 | AI20: =IFERROR(AVERAGE(C20:AG20),"") -> 12678.935 | AK20: =AJ20*AH20 -> 0
A21: 청관제 (KG) | B21: 반입 | C21: 660 | D21: 0 | E21: 0 | F21: 0 | G21: 0 | H21: 0 | I21: 0 | J21: 0 | K21: 0 | L21: 610 | M21: 0 | N21: 0 | O21: 0 | P21: 0 | Q21: 0 | R21: 0 | S21: 600 | T21: 0 | U21: 0 | V21: 0 | W21: 0 | X21: 410 | Y21: 0 | Z21: 0 | AA21: 0 | AB21: 0 | AC21: 0 | AD21: 0 | AE21: 0 | AF21: 0 | AG21: 600 | AH21: =SUM(C21:AG21) -> 2880 | AI21: =IFERROR(AVERAGE(C21:AG21),"") -> 92.903226 | AJ21: 1300 | AK21: =AH21*AJ21 -> 3744000
B22: 사용 | C22: 100 | D22: 70 | E22: 80 | F22: 70 | G22: 70 | H22: 80 | I22: 100 | J22: 60 | K22: 80 | L22: 90 | M22: 80 | N22: 70 | O22: 70 | P22: 70 | Q22: 80 | R22: 70 | S22: 90 | T22: 80 | U22: 70 | V22: 80 | W22: 80 | X22: 90 | Y22: 70 | Z22: 70 | AA22: 70 | AB22: 70 | AC22: 50 | AD22: 80 | AE22: 60 | AF22: 60 | AG22: 60 | AH22: =SUM(C22:AG22) -> 2320 | AI22: =IFERROR(AVERAGE(C22:AG22),"") -> 74.83871 | AJ22: 1300 | AK22: =AH22*AJ22 -> 3016000
B23: 재고 | C23: =380+C21-C22 -> 940 | D23: =C23+D21-D22 -> 870 | E23: =D23+E21-E22 -> 790 | F23: =E23+F21-F22 -> 720 | G23: =F23+G21-G22 -> 650 | H23: =G23+H21-H22 -> 570 | I23: =H23+I21-I22 -> 470 | J23: =I23+J21-J22 -> 410 | K23: =J23+K21-K22 -> 330 | ... AG23: =AF23+AG21-AG22 -> 940 | AI23: =IFERROR(AVERAGE(C23:AG23),"") -> 672.58065 | AK23: =AJ23*AH23 -> 0
A24: 활성탄 (KG) | B24: 반입 | C24: 0 | D24: 0 | E24: 0 | F24: 0 | G24: 0 | H24: 0 | I24: 0 | J24: 0 | K24: 0 | L24: 0 | M24: 0 | N24: 0 | O24: 0 | P24: 0 | Q24: 0 | R24: 0 | S24: 0 | T24: 0 | U24: 0 | V24: 0 | W24: 0 | X24: 0 | Y24: 2000 | Z24: 0 | AA24: 0 | AB24: 0 | AC24: 0 | AD24: 0 | AE24: 0 | AF24: 0 | AG24: 0 | AH24: =SUM(C24:AG24) -> 2000 | AI24: =IFERROR(AVERAGE(C24:AG24),"") -> 64.516129 | AJ24: 1650 | AK24: =AJ24*AH24 -> 3300000
B25: 사용 | C25: 120 | D25: 120 | E25: 120 | F25: 120 | G25: 120 | H25: 0 | I25: 0 | J25: 60 | K25: 80 | L25: 80 | M25: 80 | N25: 80 | O25: 80 | P25: 80 | Q25: 80 | R25: 80 | S25: 80 | T25: 80 | U25: 80 | V25: 120 | W25: 120 | X25: 120 | Y25: 120 | Z25: 120 | AA25: 120 | AB25: 120 | AC25: 120 | AD25: 120 | AE25: 120 | AF25: 120 | AG25: 120 | AH25: =SUM(C25:AG25) -> 2980 | AI25: =IFERROR(AVERAGE(C25:AG25),"") -> 96.129032 | AJ25: 1650 | AK25: =AJ25*AH25 -> 4917000
B26: 재고 | C26: =1970+C24-C25 -> 1850 | D26: =C26+D24-D25 -> 1730 | E26: =D26+E24-E25 -> 1610 | F26: =E26+F24-F25 -> 1490 | G26: =F26+G24-G25 -> 1370 | H26: =G26+H24-H25 -> 1370 | I26: =H26+I24-I25 -> 1370 | J26: =I26+J24-J25 -> 1310 | K26: =J26+K24-K25 -> 1230 | ... AG26: =AF26+AG24-AG25 -> 990 | AI26: =IFERROR(AVERAGE(C26:AG26),"") -> 1130 | AK26: =AJ26*AH26 -> 0
A27: 가성소다 (KG) | B27: 반입 | C27: 0 | D27: 0 | E27: 0 | F27: 0 | G27: 0 | H27: 0 | I27: 0 | J27: 0 | K27: 0 | L27: 0 | M27: 0 | N27: 0 | O27: 0 | P27: 0 | Q27: 0 | R27: 0 | S27: 0 | T27: 0 | U27: 0 | V27: 0 | W27: 0 | X27: 0 | Y27: 0 | Z27: 0 | AA27: 0 | AB27: 0 | AC27: 0 | AD27: 0 | AE27: 0 | AG27: 0 | AH27: =SUM(C27:AG27) -> 0 | AI27: =IFERROR(AVERAGE(C27:AG27),"") -> 0 | AJ27: 460 | AK27: =AJ27*AH27 -> 0
B28: 사용 | C28: 0 | D28: 0 | E28: 0 | F28: 0 | G28: 0 | H28: 0 | I28: 0 | J28: 0 | K28: 0 | L28: 0 | M28: 0 | N28: 0 | O28: 0 | P28: 0 | Q28: 0 | R28: 0 | S28: 0 | T28: 0 | U28: 0 | V28: 0 | W28: 0 | X28: 0 | Y28: 0 | Z28: 0 | AA28: 0 | AB28: 0 | AC28: 0 | AD28: 0 | AE28: 0 | AG28: 0 | AH28: =SUM(C28:AG28) -> 0 | AI28: =IFERROR(AVERAGE(C28:AG28),"") -> 0 | AJ28: 460 | AK28: =AJ28*AH28 -> 0
B29: 재고 | C29: =0+C27-C28 -> 0 | D29: =C29+D27-D28 -> 0 | E29: =D29+E27-E28 -> 0 | F29: =E29+F27-F28 -> 0 | G29: =F29+G27-G28 -> 0 | H29: =G29+H27-H28 -> 0 | I29: =H29+I27-I28 -> 0 | J29: =I29+J27-J28 -> 0 | K29: =J29+K27-K28 -> 0 | ... AE29: =AD29+AE27-AE28 -> 0 | AG29: =AE29+AG27-AG28 -> 0 | AI29: =IFERROR(AVERAGE(C29:AG29),"") -> 0 | AK29: =AJ29*AH29 -> 0
A30: 소석회 (KG) | B30: 반입 | C30: 0 | D30: 0 | E30: 0 | F30: 0 | G30: 0 | H30: 0 | I30: 0 | J30: 0 | K30: 0 | L30: 0 | M30: 0 | N30: 0 | O30: 0 | P30: 0 | Q30: 0 | R30: 0 | S30: 0 | T30: 0 | U30: 0 | V30: 0 | W30: 0 | X30: 0 | Y30: 0 | Z30: 0 | AA30: 0 | AB30: 0 | AC30: 0 | AD30: 0 | AE30: 0 | AF30: 0 | AG30: 0 | AH30: =SUM(C30:AG30) -> 0 | AI30: =IFERROR(AVERAGE(C30:AG30),"") -> 0 | AJ30: 580 | AK30: =AJ30*AH30 -> 0
B31: 사용 | C31: 20 | D31: 20 | E31: 20 | F31: 20 | G31: 20 | H31: 0 | I31: 0 | J31: 0 | K31: 20 | L31: 20 | M31: 20 | N31: 20 | O31: 20 | P31: 20 | Q31: 20 | R31: 20 | S31: 20 | T31: 20 | U31: 20 | V31: 20 | W31: 20 | X31: 20 | Y31: 20 | Z31: 20 | AA31: 20 | AB31: 20 | AC31: 20 | AD31: 20 | AE31: 20 | AF31: 20 | AG31: 20 | AH31: =SUM(C31:AG31) -> 560 | AI31: =IFERROR(AVERAGE(C31:AG31),"") -> 18.064516 | AJ31: =AJ30 -> 580 | AK31: =AJ31*AH31 -> 324800
B32: 재고 | C32: =1480+C30-C31 -> 1460 | D32: =C32+D30-D31 -> 1440 | E32: =D32+E30-E31 -> 1420 | F32: =E32+F30-F31 -> 1400 | G32: =F32+G30-G31 -> 1380 | H32: =G32+H30-H31 -> 1380 | I32: =H32+I30-I31 -> 1380 | J32: =I32+J30-J31 -> 1380 | K32: =J32+K30-K31 -> 1360 | ... AG32: =AF32+AG30-AG31 -> 920 | AI32: =IFERROR(AVERAGE(C32:AG32),"") -> 1208.3871 | AK32: =AJ32*AH32 -> 0
A33: 소금(KG) | B33: 반입 | C33: 1440 | D33: 0 | E33: 0 | F33: 0 | G33: 0 | H33: 0 | I33: 1440 | J33: 0 | K33: 0 | L33: 0 | M33: 0 | N33: 0 | O33: 0 | P33: 1440 | Q33: 0 | R33: 0 | S33: 0 | T33: 0 | U33: 0 | V33: 0 | W33: 1440 | X33: 0 | Y33: 0 | Z33: 0 | AA33: 0 | AB33: 0 | AC33: 0 | AD33: 0 | AE33: 1440 | AF33: 0 | AG33: 0 | AH33: =SUM(C33:AG33) -> 7200 | AI33: =IFERROR(AVERAGE(C33:AG33),"") -> 232.25806 | AJ33: 140 | AK33: =AJ33*AH33 -> 1008000
B34: 사용 | C34: 200 | D34: 200 | E34: 200 | F34: 200 | G34: 200 | H34: 20 | I34: 200 | J34: 200 | K34: 200 | L34: 200 | M34: 200 | N34: 200 | O34: 200 | P34: 200 | Q34: 200 | R34: 200 | S34: 200 | T34: 200 | U34: 200 | V34: 200 | W34: 200 | X34: 200 | Y34: 200 | Z34: 200 | AA34: 200 | AB34: 200 | AC34: 200 | AD34: 200 | AE34: 200 | AF34: 200 | AG34: 200 | AH34: =SUM(C34:AG34) -> 6020 | AI34: =IFERROR(AVERAGE(C34:AG34),"") -> 194.19355 | AJ34: =AJ33 -> 140 | AK34: =AJ34*AH34 -> 842800
B35: 재고 | C35: =470+C33-C34 -> 1710 | D35: =C35+D33-D34 -> 1510 | E35: =D35+E33-E34 -> 1310 | F35: =E35+F33-F34 -> 1110 | G35: =F35+G33-G34 -> 910 | H35: =G35+H33-H34 -> 890 | I35: =H35+I33-I34 -> 2130 | J35: =I35+J33-J34 -> 1930 | K35: =J35+K33-K34 -> 1730 | ... AG35: =AF35+AG33-AG34 -> 1650 | AH35: 0 | AI35: =IFERROR(AVERAGE(C35:AG35),"") -> 1508.7097 | AK35: =AJ35*AH35 -> 0
A36: 경유(L) | B36: 반입 | C36: 0 | D36: 0 | E36: 3000 | F36: 0 | G36: 0 | H36: 0 | I36: 0 | J36: 0 | K36: 0 | L36: 0 | M36: 0 | N36: 0 | O36: 0 | P36: 0 | Q36: 0 | R36: 0 | S36: 0 | T36: 0 | U36: 0 | V36: 0 | W36: 0 | X36: 0 | Y36: 0 | Z36: 0 | AA36: 0 | AB36: 0 | AC36: 0 | AD36: 0 | AE36: 0 | AF36: 0 | AG36: 0 | AH36: =SUM(C36:AG36) -> 3000 | AI36: =IFERROR(AVERAGE(C36:AG36),"") -> 96.774194 | AJ36: 1390 | AK36: =AH36*AJ36 -> 4170000
B37: 사용 | C37: 0 | D37: 0 | E37: 0 | F37: 0 | G37: 0 | H37: 0 | I37: 0 | J37: 4220 | K37: 0 | L37: 0 | M37: 0 | N37: 0 | O37: 0 | P37: 0 | Q37: 0 | R37: 0 | S37: 0 | T37: 0 | U37: 0 | V37: 0 | W37: 0 | X37: 0 | Y37: 0 | Z37: 0 | AA37: 0 | AB37: 0 | AC37: 0 | AD37: 0 | AE37: 0 | AF37: 0 | AG37: 0 | AH37: =SUM(C37:AG37) -> 4220 | AI37: =IFERROR(AVERAGE(C37:AG37),"") -> 136.12903 | AJ37: =AJ36 -> 1390 | AK37: =AJ37*AH37 -> 5865800
B38: 재고 | C38: =4090+C36-C37 -> 4090 | D38: =C38+D36-D37 -> 4090 | E38: =D38+E36-E37 -> 7090 | F38: =E38+F36-F37 -> 7090 | G38: =F38+G36-G37 -> 7090 | H38: =G38+H36-H37 -> 7090 | I38: =H38+I36-I37 -> 7090 | J38: =I38+J36-J37 -> 2870 | K38: =J38+K36-K37 -> 2870 | ... AG38: =AF38+AG36-AG37 -> 2870 | AI38: =IFERROR(AVERAGE(C38:AG38),"") -> 3629.3548 | AK38: =AJ38*AH38 -> 0
A39: 규사(KG) | B39: 반입 | C39: 0 | D39: 0 | E39: 0 | F39: 0 | G39: 0 | H39: 0 | I39: 0 | J39: 0 | K39: 0 | L39: 0 | M39: 0 | N39: 0 | O39: 0 | P39: 0 | Q39: 0 | R39: 0 | S39: 0 | T39: 0 | U39: 0 | V39: 0 | W39: 0 | X39: 0 | Y39: 0 | Z39: 0 | AA39: 0 | AB39: 0 | AC39: 0 | AD39: 0 | AE39: 0 | AH39: =SUM(C39:AG39) -> 0 | AI39: =IFERROR(AVERAGE(C39:AG39),"") -> 0 | AJ39: 145 | AK39: =AJ39*AH39 -> 0
B40: 사용 | C40: 사용량 측정불가 | AI40: =IFERROR(AVERAGE(C40:AG40),"") | AK40: =AJ40*AH40 -> 0
A41: 활성탄 (KG) | B41: 반입 | AH41: =SUM(C41:AG41) -> 0 | AJ41: 5900 | AK41: =AH41*AJ41 -> 0
...

Sheet 3-1. 월별 운영내역
A2: 1. 운영현황 | V2: * 소각톤당 약품사용량(Kg/ton)
A3: 2025년도 | B3: 유동상 소각로 | J3: 도급비 원단위 | R3: 운영비 원단위 | V3: 구 분 | W3: 탄산암모늄 | X3: 활성탄 | Y3: 소석회
B4: 슬러지 소각량(톤) | C4: SRF소각량(톤) | D4: 전체 소각량(톤) | E4: SRF반입량(톤) | F4: 스팀 생산량(톤) | G4: 스팀 송기량(톤) | H4: 가동시간(Hr) | I4: 운휴시간 (고정비 지급) | J4: 가동시간 운영비 스팀생산 운영비 | K4: 운휴시간 고정비 | L4: 설비개선비용 | M4: 차감비 | N4: 추가 지급분 | O4: 도급비용(천원) | P4: 소각 원단위 (천원/톤) | Q4: 스팀 원단위 (천원/톤) | R4: 운영비용(천원) | S4: 소각 원단위 (천원/톤) | T4: 스팀 원단위 (천원/톤) | V4: 1월 | W4: =G23/D5 -> 14.487806 | X4: =O23/D5 -> 0.35882699 | Y4: =K40/D5 -> 0.079739332
A5: 1월 | B5: 4365.2 | C5: 1654.414 | D5: =B5+C5 -> 6019.614 | E5: 1641.19 | F5: 11589.6 | G5: 7010 | H5: 569.5 | I5: 174.5 | J5: =F5*18500/1000 -> 214407.6 | K5: =I5*152000/1000 -> 26524 | L5: =50000000/1000 -> 50000 | M5: 0 | N5: 0 | O5: =J5+K5+L5-M5+N5 -> 290931.6 | P5: =O5/D5 -> 48.330607 | Q5: =O5/F5 -> 25.102816 | R5: 380493.18 | S5: =R5/D5 -> 63.208901 | T5: =R5/F5 -> 32.830571 | U5: =F5/H5 -> 20.350483 | V5: 2월 | W5: =G24/D6 -> 14.101076 | X5: =O24/D6 -> 0.35111675 | Y5: =K41/D6 -> 0.078025944
A6: 2월 | B6: 4650.1 | C6: 1501.7 | D6: =B6+C6 -> 6151.8 | E6: 1574.43 | F6: 11559.5 | G6: 8436 | H6: 563.5 | I6: 99.5 | J6: =F6*18760/1000 -> 216856.22 | K6: =I6*160000/1000 -> 15920 | L6: =50000000/1000 -> 50000 | M6: 0 | N6: 4409.296 | O6: =J6+K6+L6-M6+N6 -> 287185.52 | P6: =O6/D6 -> 46.683169 | Q6: =O6/F6 -> 24.844112 | R6: 370377.36 | S6: =R6/D6 -> 60.20634 | T6: =R6/F6 -> 32.04095 | U6: =F6/H6 -> 20.513753 | V6: 3월 | W6: =G25/D7 -> 12.506048 | X6: =O25/D7 -> 0.36368005 | Y6: =K42/D7 -> 0.0743891
A7: 3월 | B7: 5532.6 | C7: 1726.528 | D7: 7259.128 | E7: 1845.54 | F7: 12593.4 | G7: 7646 | H7: 623 | I7: 118 | J7: =F7*18760/1000 -> 236252.18 | K7: =I7*160000/1000 -> 18880 | L7: =50000000/1000 -> 50000 | M7: 0 | N7: 0 | O7: =J7+K7+L7-M7+N7 -> 305132.18 | P7: =O7/D7 -> 42.034275 | Q7: =O7/F7 -> 24.229532 | R7: 379191.79 | S7: =R7/D7 -> 52.236548 | T7: =R7/F7 -> 30.110358 | U7: =F7/H7 -> 20.214125 | V7: 4월 | W7: =G26/D8 -> 15.897955 | X7: =O26/D8 -> 0.37400884 | Y7: =K43/D8 -> 0.061260068
A8: 4월 | B8: 4539.2 | C8: 1663.862 | D8: =B8+C8 -> 6203.062 | E8: 1657.87 | F8: 11568.4 | G8: 9397 | H8: 541.7 | I8: 151.3 | J8: =F8*18760/1000 -> 217023.18 | K8: =I8*160000/1000 -> 24208 | L8: =50000000/1000 -> 50000 | M8: =2945050/1000 -> 2945.05 | N8: 0 | O8: =J8+K8+L8-M8+N8 -> 288286.13 | P8: =O8/D8 -> 46.474811 | Q8: =O8/F8 -> 24.920139 | R8: 351810.01 | S8: =R8/D8 -> 56.715541 | T8: =R8/F8 -> 30.411294 | U8: =F8/H8 -> 21.355732 | V8: 5월 | W8: =G27/D9 -> 12.779805 | X8: =O27/D9 -> 0.29843936 | Y8: =K44/D9 -> 0.07747945
A9: 5월 | B9: 4940.1 | C9: 2029.49 | D9: =B9+C9 -> 6969.59 | E9: 2006.26 | F9: 13682.4 | G9: 9006 | H9: 663.5 | I9: 80.5 | J9: =F9*18760/1000 -> 256681.82 | K9: =I9*160000/1000 -> 12880 | L9: =50000000/1000 -> 50000 | M9: 0 | N9: 5151.05 | O9: =J9+K9+L9-M9+N9 -> 324712.87 | P9: =O9/D9 -> 46.589953 | Q9: =O9/F9 -> 23.732158 | R9: 401007.36 | S9: =R9/D9 -> 57.536721 | T9: =R9/F9 -> 29.308261 | U9: =F9/H9 -> 20.621552 | V9: 6월 | W9: =G28/D10 -> 14.57516 | X9: =O28/D10 -> 0.363948 | Y9: =K45/D10 -> 0.10343785
A10: 6월 | B10: 3515.6 | C10: 1704.926 | D10: =B10+C10 -> 5220.526 | E10: 1804.43 | F10: 11544.1 | G10: 7500 | H10: 577 | I10: 143 | J10: =F10*18760/1000 -> 216567.32 | K10: =I10*160000/1000 -> 22880 | L10: =50000000/1000 -> 50000 | M10: 0 | N10: 0 | O10: =J10+K10+L10-M10+N10 -> 289447.32 | P10: =O10/D10 -> 55.44409 | Q10: =O10/F10 -> 25.073182 | R10: 365434.8 | S10: =R10/D10 -> 69.999613 | T10: =R10/F10 -> 31.655547 | U10: =F10/H10 -> 20.007106 | V10: 7월 | W10: =G29/D11 -> 15.498483 | X10: =O29/D11 -> 0.34434826 | Y10: =K46/D11 -> 0.09487146
A11: 7월 | B11: 3836.1 | C11: 1855.812 | D11: =B11+C11 -> 5691.912 | E11: 1872.44 | F11: 13116.1 | G11: 7993 | H11: 622.7 | I11: 118 | J11: =F11*18760/1000 -> 246058.04 | K11: =I11*160000/1000 -> 18880 | L11: 50000 | M11: 0 | N11: 0 | O11: =J11+K11+L11-M11+N11 -> 314938.04 | P11: =O11/D11 -> 55.330799 | Q11: =O11/F11 -> 24.011561 | R11: 408897.62 | S11: =R11/D11 -> 71.838359 | T11: =R11/F11 -> 31.175244 | U11: =F11/H11 -> 21.063273 | V11: 8월 | W11: =G30/D12 -> 13.380811 | X11: =O30/D12 -> 0.36536947 | Y11: =K47/D12 -> 0.087959317
A12: 8월 | B12: 4272 | C12: 1639.824 | D12: =B12+C12 -> 5911.824 | E12: 2383.871 | F12: 11997.6 | G12: 7816 | H12: 598.5 | I12: 145.5 | J12: =F12*18760/1000 -> 225074.98 | K12: =I12*160000/1000 -> 23280 | L12: 50000 | M12: 121.63 | N12: 0 | O12: =J12+K12+L12-M12+N12 -> 298233.35 | P12: =O12/D12 -> 50.446926 | Q12: =O12/F12 -> 24.85775 | R12: 376708.56 | S12: =R12/D12 -> 63.721207 | T12: =R12/F12 -> 31.39866 | U12: =F12/H12 -> 20.046115 | V12: 9월 | W12: =G31/D13 -> 13.545116 | X12: =O31/D13 -> 0.44398623 | Y12: =K48/D13 -> 0.091678572
A13: 9월 | B13: 5475.4 | C13: 2159.972 | D13: =B13+C13 -> 7635.372 | E13: 2207.4 | F13: 15311.032 | G13: 10152 | H13: 707 | I13: 13 | J13: =F13*18760/1000 -> 287234.97 | K13: =I13*160000/1000 -> 2080 | L13: 50000 | M13: 0 | O13: =J13+K13+L13 -> 339314.97 | P13: =O13/D13 -> 44.439874 | Q13: =IFERROR(O13/F13," ") -> 22.161469 | R13: 404808.91 | S13: =IFERROR(R13/(D13)," ") -> 53.017576 | T13: =IFERROR(R13/F13," ") -> 26.439034 | U13: =F13/H13 -> 21.65634 | V13: 10월 | W13: =G32/D14 -> 13.404929 | X13: =O32/D14 -> 0.44005297 | Y13: =K49/D14 -> 0.082694518
A14: 10월 | B14: ='3. 세부 운영내역'!AH8 -> 4734.9 | C14: ='3. 세부 운영내역'!AH9 -> 2037.012 | D14: =B14+C14 -> 6771.912 | E14: ='3. 세부 운영내역'!AH46 -> 2101.19 | F14: ='3. 세부 운영내역'!AH6 -> 14223.6 | G14: ='3. 세부 운영내역'!AH7 -> 9138 | H14: ='3. 세부 운영내역'!AH4 -> 684.5 | I14: ='3. 세부 운영내역'!AH5 -> 59.5 | J14: =F14*18760/1000 -> 266834.74 | K14: =I14*160000/1000 -> 9520 | L14: 50000 | M14: 0 | N14: 0 | O14: =J14+K14+L14-M14 -> 326354.74 | P14: =O14/D14 -> 48.192407 | Q14: =IFERROR(O14/F14," ") -> 22.944595 | R14: ='3. 세부 운영내역'!AK96/1000 -> 407296.78 | S14: =IFERROR(R14/(D14)," ") -> 60.145019 | T14: =IFERROR(R14/F14," ") -> 28.63528 | V14: 11월 | W14: =G33/D15 -> #DIV/0! | X14: =O33/D15 -> #DIV/0! | Y14: =K50/D15 -> #DIV/0!
A15: 11월 | J15: =F15*18760/1000 -> 0 | K15: =I15*160000/1000 -> 0 | N15: 0 | O15: =J15+K15+L15-M15 -> 0 | P15: =IFERROR(O15/D15," ") | Q15: =IFERROR(O15/F15," ") | S15: =IFERROR(R15/(D15)," ") | T15: =IFERROR(R15/F15," ") | V15: 12월 | W15: =G34/D16 -> #DIV/0! | X15: =O34/D16 -> #DIV/0! | Y15: =K51/D16 -> #DIV/0!
A16: 12월 | J16: =F16*18760/1000 -> 0 | K16: =I16*160000/1000 -> 0 | O16: =J16+K16+L16-M16+N16 -> 0 | P16: =IFERROR(O16/D16," ") | Q16: =IFERROR(O16/F16," ") | S16: =IFERROR(R16/(D16)," ") | T16: =IFERROR(R16/F16," ")
A17: Total | B17: =SUM(B5:B16) -> 45861.2 | C17: =SUM(C5:C16) -> 17973.54 | D17: =SUM(B17:C17) -> 63834.74 | E17: =SUM(E5:E16) -> 19094.621 | F17: =SUM(F5:F16) -> 127185.73 | G17: =SUM(G5:G16) -> 84094 | H17: =SUM(H5:H16) -> 6150.9 | I17: =SUM(I5:I16) -> 1102.8 | J17: =SUM(J5:J16) -> 2382991 | K17: =SUM(K5:K16) -> 175052 | L17: =SUM(L5:L16) -> 500000 | ... O17: =SUM(O5:O16) -> 3064536.7 | P17: =IFERROR(O17/(D17)," ") -> 48.00735 | Q17: =IFERROR(O17/F17," ") -> 24.094972 | R17: =SUM(R5:R16) -> 3846026.4 | S17: =IFERROR(R17/(D17)," ") -> 60.249738 | T17: =IFERROR(R17/F17," ") -> 30.239448 | U17: =F17/H17 -> 20.677581
A18: Average | B18: =AVERAGE(B5:B16) -> 4586.12 | C18: =AVERAGE(C5:C16) -> 1797.354 | D18: =AVERAGE(D5:D16) -> 6383.474 | E18: =AVERAGE(E5:E16) -> 1909.4621 | F18: =AVERAGE(F5:F16) -> 12718.573 | G18: =AVERAGE(G5:G16) -> 8409.4 | H18: =AVERAGE(H5:H16) -> 615.09 | I18: =AVERAGE(I5:I16) -> 110.28 | ... T18: =AVERAGE(T5:T16) -> 30.40052
A20: 2. 약품 사용량 (실사용량 및 비용)
A21: =A3 -> 2025년도 | B21: 경 유 | F21: 탄산암모늄 | J21: 청관제 | N21: 활성탄 | S21: 약품명 | T21: 단가(Kg/원)
B22: 구입량 | C22: 사용량 | D22: 구입비용 | E22: 사용비용 | F22: 구입량 | G22: 사용량 | H22: 구입비용 | I22: 사용비용 | J22: 구입량 | K22: 사용량 | L22: 구입비용 | M22: 사용비용 | N22: 구입량 | O22: 사용량 | P22: 구입비용 | Q22: 사용비용 | S22: 경유 | T22: =1209/1.1 -> 1099.0909
A23: 1월 | B23: 9000 | C23: 6812 | D23: 12861927 | E23: 9735049.6 | F23: 78220 | G23: 87211 | H23: =VLOOKUP($F$21,$S$21:$T$29,2,0)*F23 -> 29723600 | I23: =VLOOKUP($F$21,$S$21:$T$29,2,0)*G23 -> 33140180 | J23: 1770 | K23: 2130 | L23: =VLOOKUP($J$21,$S$21:$T$29,2,0)*J23 -> 2301000 | M23: =VLOOKUP($J$21,$S$21:$T$29,2,0)*K23 -> 2769000 | N23: 2000 | O23: 2160 | P23: =VLOOKUP($N$21,$S$21:$T$29,2,0)*N23 -> 3300000 | Q23: =VLOOKUP($N$21,$S$21:$T$29,2,0)*O23 -> 3564000 | S23: 탄산암모늄 | T23: 380
A24: 2월 | B24: 6000 | C24: 6018 | D24: 8683636 | E24: 8709686.9 | F24: 94760 | G24: 86747 | H24: =VLOOKUP($F$21,$S$21:$T$29,2,0)*F24 -> 36008800 | I24: =VLOOKUP($F$21,$S$21:$T$29,2,0)*G24 -> 32963860 | J24: 2400 | K24: 1900 | L24: =VLOOKUP($J$21,$S$21:$T$29,2,0)*J24 -> 3120000 | M24: =VLOOKUP($J$21,$S$21:$T$29,2,0)*K24 -> 2470000 | N24: 2000 | O24: 2160 | P24: =VLOOKUP($N$21,$S$21:$T$29,2,0)*N24 -> 3300000 | Q24: =VLOOKUP($N$21,$S$21:$T$29,2,0)*O24 -> 3564000 | S24: 청관제 | T24: 1300
A25: 3월 | B25: 3000 | C25: 2130 | D25: 4246364 | E25: 3014918.4 | F25: 89390 | G25: 90783 | H25: =VLOOKUP($F$21,$S$21:$T$29,2,0)*F25 -> 33968200 | I25: =VLOOKUP($F$21,$S$21:$T$29,2,0)*G25 -> 34497540 | J25: 1820 | K25: 1890 | L25: =VLOOKUP($J$21,$S$21:$T$29,2,0)*J25 -> 2366000 | M25: =VLOOKUP($J$21,$S$21:$T$29,2,0)*K25 -> 2457000 | N25: 4000 | O25: 2640 | P25: =VLOOKUP($N$21,$S$21:$T$29,2,0)*N25 -> 6600000 | Q25: =VLOOKUP($N$21,$S$21:$T$29,2,0)*O25 -> 4356000 | S25: 활성탄 | T25: 1650
A26: 4월 | B26: 6000 | C26: 8510 | D26: 8329091 | E26: 11813427 | F26: 96700 | G26: 98616 | H26: =VLOOKUP($F$21,$S$21:$T$29,2,0)*F26 -> 36746000 | I26: =VLOOKUP($F$21,$S$21:$T$29,2,0)*G26 -> 37474080 | J26: 1600 | K26: 1840 | L26: =VLOOKUP($J$21,$S$21:$T$29,2,0)*J26 -> 2080000 | M26: =VLOOKUP($J$21,$S$21:$T$29,2,0)*K26 -> 2392000 | N26: 2000 | O26: 2320 | P26: =VLOOKUP($N$21,$S$21:$T$29,2,0)*N26 -> 3300000 | Q26: =VLOOKUP($N$21,$S$21:$T$29,2,0)*O26 -> 3828000 | S26: 소금 | T26: 140
A27: 5월 | B27: 6000 | C27: 4710 | D27: 8170910 | E27: 6414164.4 | F27: 92470 | G27: 89070 | H27: =VLOOKUP($F$21,$S$21:$T$29,2,0)*F27 -> 35138600 | I27: =VLOOKUP($F$21,$S$21:$T$29,2,0)*G27 -> 33846600 | J27: 2200 | K27: 1990 | L27: =VLOOKUP($J$21,$S$21:$T$29,2,0)*J27 -> 2860000 | M27: =VLOOKUP($J$21,$S$21:$T$29,2,0)*K27 -> 2587000 | N27: 2000 | O27: 2080 | P27: =VLOOKUP($N$21,$S$21:$T$29,2,0)*N27 -> 3300000 | Q27: =VLOOKUP($N$21,$S$21:$T$29,2,0)*O27 -> 3432000 | S27: 가성소다 | T27: 460
A28: 6월 | B28: 6000 | C28: 3860 | D28: 8116364 | E28: 5221527.5 | F28: 68410 | G28: 76090 | H28: =VLOOKUP($F$21,$S$21:$T$29,2,0)*F28 -> 25995800 | I28: =VLOOKUP($F$21,$S$21:$T$29,2,0)*G28 -> 28914200 | J28: 1970 | K28: 1970 | L28: =VLOOKUP($J$21,$S$21:$T$29,2,0)*J28 -> 2561000 | M28: =VLOOKUP($J$21,$S$21:$T$29,2,0)*K28 -> 2561000 | N28: 1940 | O28: 1900 | P28: =VLOOKUP($N$21,$S$21:$T$29,2,0)*N28 -> 3201000 | Q28: =VLOOKUP($N$21,$S$21:$T$29,2,0)*O28 -> 3135000 | S28: 소석회 | T28: 580
A29: 7월 | B29: 3000 | C29: 4270 | D29: 4161818 | E29: 5923654.3 | F29: 89630 | G29: 88216 | H29: =VLOOKUP($F$21,$S$21:$T$29,2,0)*F29 -> 34059400 | I29: =VLOOKUP($F$21,$S$21:$T$29,2,0)*G29 -> 33522080 | J29: 1900 | K29: 1980 | L29: =VLOOKUP($J$21,$S$21:$T$29,2,0)*J29 -> 2470000 | M29: =VLOOKUP($J$21,$S$21:$T$29,2,0)*K29 -> 2574000 | N29: 2000 | O29: 1960 | P29: =VLOOKUP($N$21,$S$21:$T$29,2,0)*N29 -> 3300000 | Q29: =VLOOKUP($N$21,$S$21:$T$29,2,0)*O29 -> 3234000 | S29: 규사 | T29: 145
A30: 8월 | B30: 6000 | C30: 6060 | D30: 8356363 | E30: 8439926.6 | F30: 73900 | G30: 79105 | H30: =VLOOKUP($F$21,$S$21:$T$29,2,0)*F30 -> 28082000 | I30: =VLOOKUP($F$21,$S$21:$T$29,2,0)*G30 -> 30059900 | J30: 2110 | K30: 1790 | L30: =VLOOKUP($J$21,$S$21:$T$29,2,0)*J30 -> 2743000 | M30: =VLOOKUP($J$21,$S$21:$T$29,2,0)*K30 -> 2327000 | N30: 2000 | O30: 2160 | P30: =VLOOKUP($N$21,$S$21:$T$29,2,0)*N30 -> 3300000 | Q30: =VLOOKUP($N$21,$S$21:$T$29,2,0)*O30 -> 3564000
A31: 9월 | B31: 3000 | C31: 2620 | D31: 4167273 | E31: 3639418.4 | F31: 105320 | G31: 103422 | H31: =VLOOKUP($F$21,$S$21:$T$29,2,0)*F31 -> 40021600 | I31: =VLOOKUP($F$21,$S$21:$T$29,2,0)*G31 -> 39300360 | J31: 1700 | K31: 2220 | L31: =VLOOKUP($J$21,$S$21:$T$29,2,0)*J31 -> 2210000 | M31: =VLOOKUP($J$21,$S$21:$T$29,2,0)*K31 -> 2886000 | N31: 4000 | O31: 3390 | P31: =VLOOKUP($N$21,$S$21:$T$29,2,0)*N31 -> 6600000 | Q31: =VLOOKUP($N$21,$S$21:$T$29,2,0)*O31 -> 5593500
A32: 10월 | B32: ='3. 세부 운영내역'!AH36 -> 3000 | C32: ='3. 세부 운영내역'!AH37 -> 4220 | D32: ='3. 세부 운영내역'!AK36 -> 4170000 | E32: ='3. 세부 운영내역'!AK37 -> 5865800 | F32: ='3. 세부 운영내역'!AH18 -> 97560 | G32: ='3. 세부 운영내역'!AH19 -> 90777 | H32: =VLOOKUP($F$21,$S$21:$T$29,2,0)*F32 -> 37072800 | I32: =VLOOKUP($F$21,$S$21:$T$29,2,0)*G32 -> 34495260 | J32: ='3. 세부 운영내역'!AH21 -> 2880 | K32: ='3. 세부 운영내역'!AH22 -> 2320 | L32: =VLOOKUP($J$21,$S$21:$T$29,2,0)*J32 -> 3744000 | M32: =VLOOKUP($J$21,$S$21:$T$29,2,0)*K32 -> 3016000 | N32: ='3. 세부 운영내역'!AH24 -> 2000 | O32: ='3. 세부 운영내역'!AH25 -> 2980 | P32: =VLOOKUP($N$21,$S$21:$T$29,2,0)*N32 -> 3300000 | Q32: =VLOOKUP($N$21,$S$21:$T$29,2,0)*O32 -> 4917000
A33: 11월 | H33: =VLOOKUP($F$21,$S$21:$T$29,2,0)*F33 -> 0 | I33: =VLOOKUP($F$21,$S$21:$U$29,3,0)*G33 -> 0 | L33: =VLOOKUP($J$21,$S$21:$T$29,2,0)*J33 -> 0 | M33: =VLOOKUP($J$21,$S$21:$T$29,2,0)*K33 -> 0 | P33: =VLOOKUP($N$21,$S$21:$T$29,2,0)*N33 -> 0 | Q33: =VLOOKUP($N$21,$S$21:$T$29,2,0)*O33 -> 0
A34: 12월 | H34: =VLOOKUP($F$21,$S$21:$T$29,2,0)*F34 -> 0 | I34: =VLOOKUP($F$21,$S$21:$U$29,3,0)*G34 -> 0 | L34: =VLOOKUP($J$21,$S$21:$T$29,2,0)*J34 -> 0 | M34: =VLOOKUP($J$21,$S$21:$T$29,2,0)*K34 -> 0 | P34: =VLOOKUP($N$21,$S$21:$T$29,2,0)*N34 -> 0 | Q34: =VLOOKUP($N$21,$S$21:$T$29,2,0)*O34 -> 0
A35: 합계 | B35: =SUM(B23:B34) -> 51000 | C35: =SUM(C23:C34) -> 49210 | D35: =SUM(D23:D34) -> 71263746 | E35: =SUM(E23:E34) -> 68777574 | F35: =SUM(F23:F34) -> 886360 | G35: =SUM(G23:G34) -> 890037 | H35: =SUM(H23:H34) -> 336816800 | I35: =SUM(I23:I34) -> 338214060 | ... Q35: =SUM(Q23:Q34) -> 39187500
A36: 평균 | B36: =AVERAGE(B23:B34) -> 5100 | C36: =AVERAGE(C23:C34) -> 4921 | D36: =AVERAGE(D23:D34) -> 7126374.6 | E36: =AVERAGE(E23:E34) -> 6877757.4 | F36: =AVERAGE(F23:F34) -> 88636 | G36: =AVERAGE(G23:G34) -> 89003.7 | H36: =AVERAGE(H23:H34) -> 28068067 | I36: =AVERAGE(I23:I34) -> 28184505 | ... Q36: =AVERAGE(Q23:Q34) -> 3265625
A38: =A3 -> 2025년도 | B38: 소금 | F38: 가성소다 | J38: 소석회 | N38: 규사 | R38: 활성탄 (다이옥신 측정대비) | T38: 비상발전기용 경유 | V38: 열풍기용 등유 | X38: 총 구입량 | Y38: 총사용량 | Z38: 총 구입비용 | AA38: 총 사용비용 | AB38: 약품비 원단위(천원/톤) (실 구매비용 기준)
B39: 구입량 | C39: 사용량 | D39: 구입비용 | E39: 사용비용 | F39: 구입량 | G39: 사용량 | H39: 구입비용 | I39: 사용비용 | J39: 구입량 | K39: 사용량 | L39: 구입비용 | M39: 사용비용 | N39: 구입량 | O39: 사용량 | P39: 구입비용 | Q39: 사용비용 | R39: 구입량 | S39: 구입비용 | T39: 구입량 | U39: 구입비용 | V39: 구입량 | W39: 구입비용 | AB39: 소각량 | AC39: 스팀량
A40: 1월 | B40: 5760 | C40: 5800 | D40: =VLOOKUP($B$38,$S$21:$T$29,2,0)*B40 -> 806400 | E40: =VLOOKUP($B$38,$S$21:$T$29,2,0)*C40 -> 812000 | F40: 0 | G40: 0 | H40: =VLOOKUP($F$38,$S$21:$T$29,2,0)*F40 -> 0 | I40: =VLOOKUP($F$38,$S$21:$T$29,2,0)*G40 -> 0 | J40: 0 | K40: 480 | L40: =VLOOKUP($J$38,$S$21:$T$29,2,0)*J40 -> 0 | M40: =VLOOKUP($J$38,$S$21:$T$29,2,0)*K40 -> 278400 | N40: 0 | O40: 0 | P40: =VLOOKUP($N$38,$S$21:$T$29,2,0)*N40 -> 0 | Q40: =VLOOKUP($N$38,$S$21:$T$29,2,0)*O40 -> 0 | R40: 0 | S40: 0 | T40: 0 | U40: 0 | V40: 0 | W40: 0 | X40: =B23+F23+J23+N23+B40+F40+J40+N40+R40+T40 -> 96750 | Y40: =C23+G23+K23+O23+C40+G40+K40+O40 -> 104593 | Z40: =D23+H23+L23+P23+D40+H40+L40+P40+S40+U40 -> 48992927 | AA40: =E23+I23+M23+Q23+E40+I40+M40+Q40 -> 50298630 | AB40: =IFERROR((Z40/D5)/1000," ") -> 8.1388818 | AC40: =IFERROR((Z40/F5)/1000," ") -> 4.2273182 | AD40: =Z40/1000 -> 48992.927
A41: 2월 | B41: 4320 | C41: 4800 | D41: =VLOOKUP($B$38,$S$21:$T$29,2,0)*B41 -> 604800 | E41: =VLOOKUP($B$38,$S$21:$T$29,2,0)*C41 -> 672000 | F41: 0 | G41: 0 | H41: =VLOOKUP($F$38,$S$21:$T$29,2,0)*F41 -> 0 | I41: =VLOOKUP($F$38,$S$21:$T$29,2,0)*G41 -> 0 | J41: 0 | K41: 480 | L41: =VLOOKUP($J$38,$S$21:$T$29,2,0)*J41 -> 0 | M41: =VLOOKUP($J$38,$S$21:$T$29,2,0)*K41 -> 278400 | N41: 28070 | O41: 0 | P41: =VLOOKUP($N$38,$S$21:$T$29,2,0)*N41 -> 4070150 | Q41: =VLOOKUP($N$38,$S$21:$T$29,2,0)*O41 -> 0 | R41: 0 | S41: 0 | T41: 0 | U41: 0 | V41: 0 | W41: 0 | X41: =B24+F24+J24+N24+B41+F41+J41+N41+R41+T41 -> 137550 | Y41: =C24+G24+K24+O24+C41+G41+K41+O41 -> 102105 | Z41: =D24+H24+L24+P24+D41+H41+L41+P41+S41+U41 -> 55787386 | AA41: =SUM(E24,I24,M24,Q24,E41,I41,M41,Q41) -> 48657947 | AB41: =IFERROR((Z41/D6)/1000," ") -> 9.0684655 | AC41: =IFERROR((Z41/F6)/1000," ") -> 4.8261072 | AD41: =Z41/1000 -> 55787.386
A42: 3월 | B42: 5760 | C42: 5800 | D42: =VLOOKUP($B$38,$S$21:$T$29,2,0)*B42 -> 806400 | E42: =VLOOKUP($B$38,$S$21:$T$29,2,0)*C42 -> 812000 | F42: 0 | G42: 0 | H42: =VLOOKUP($F$38,$S$21:$T$29,2,0)*F42 -> 0 | I42: =VLOOKUP($F$38,$S$21:$T$29,2,0)*G42 -> 0 | J42: 0 | K42: 540 | L42: =VLOOKUP($J$38,$S$21:$T$29,2,0)*J42 -> 0 | M42: =VLOOKUP($J$38,$S$21:$T$29,2,0)*K42 -> 313200 | N42: 0 | O42: 0 | P42: =VLOOKUP($N$38,$S$21:$T$29,2,0)*N42 -> 0 | Q42: =VLOOKUP($N$38,$S$21:$T$29,2,0)*O42 -> 0 | R42: 0 | S42: 0 | T42: 0 | U42: 0 | V42: 0 | W42: 0 | X42: =B25+F25+J25+N25+B42+F42+J42+N42+R42+T42 -> 103970 | Y42: =C25+G25+K25+O25+C42+G42+K42+O42 -> 103783 | Z42: =D25+H25+L25+P25+D42+H42+L42+P42+S42+U42 -> 47986964 | AA42: =SUM(E25,I25,M25,Q25,E42,I42,M42,Q42) -> 45450658 | AB42: =IFERROR((Z42/D7)/1000," ") -> 6.6105687 | AC42: =IFERROR((Z42/F7)/1000," ") -> 3.8104852 | AD42: =Z42/1000 -> 47986.964
A43: 4월 | B43: 4320 | C43: 5000 | D43: =VLOOKUP($B$38,$S$21:$T$29,2,0)*B43 -> 604800 | E43: =VLOOKUP($B$38,$S$21:$T$29,2,0)*C43 -> 700000 | F43: 0 | G43: 0 | H43: =VLOOKUP($F$38,$S$21:$T$29,2,0)*F43 -> 0 | I43: =VLOOKUP($F$38,$S$21:$T$29,2,0)*G43 -> 0 | J43: 0 | K43: 380 | L43: =VLOOKUP($J$38,$S$21:$T$29,2,0)*J43 -> 0 | M43: =VLOOKUP($J$38,$S$21:$T$29,2,0)*K43 -> 220400 | N43: 0 | O43: 0 | P43: =VLOOKUP($N$38,$S$21:$T$29,2,0)*N43 -> 0 | Q43: =VLOOKUP($N$38,$S$21:$T$29,2,0)*O43 -> 0 | R43: 0 | S43: 0 | T43: 0 | U43: 0 | V43: 0 | W43: 0 | X43: =B26+F26+J26+N26+B43+F43+J43+N43+R43+T43 -> 110620 | Y43: =C26+G26+K26+O26+C43+G43+K43+O43 -> 116666 | Z43: =D26+H26+L26+P26+D43+H43+L43+P43+S43+U43 -> 51059891 | AA43: =SUM(E26,I26,M26,Q26,E43,I43,M43,Q43) -> 56427907 | AB43: =IFERROR((Z43/D8)/1000," ") -> 8.231401 | AC43: =IFERROR((Z43/F8)/1000," ") -> 4.4137384 | AD43: =Z43/1000 -> 51059.891
...

Sheet 4. SRF입고내역
N3: [단위 : Kg, 원]
A4: 품 명 | B4: 구 분 | C4: 대일인터내셔널 | D4: 그린플러스 | E4: 대림종합개발 | F4: 케이제이환경 | G4: 태창 | H4: 평일 | I4: 케이엠 | J4: 두제 | K4: 세종스틸 | L4: 리에나 | M4: 합 계 | N4: 누 계
A5: SRF (비성형) | B5: 45931 | C5: 24460 | D5: 22010 | E5: 0 | G5: 25650 | H5: 0 | I5: 0 | J5: 0 | K5: 0 | L5: 0 | M5: =SUM(C5:L5) -> 72120 | N5: =M5 -> 72120
B6: 45932 | C6: 23300 | D6: 0 | E6: 0 | G6: 0 | H6: 20660 | I6: 20410 | J6: 0 | K6: 23280 | L6: 0 | M6: =SUM(C6:L6) -> 87650 | N6: =N5+M6 -> 159770
B7: 45933 | C7: 20060 | D7: 0 | E7: 0 | G7: 24330 | H7: 0 | I7: 22780 | J7: 0 | K7: 0 | L7: 0 | M7: =SUM(C7:L7) -> 67170 | N7: =N6+M7 -> 226940
B8: 45934 | C8: 20810 | D8: 0 | E8: 0 | G8: 0 | H8: 0 | I8: 0 | J8: 38730 | K8: 0 | L8: 0 | M8: =SUM(C8:L8) -> 59540 | N8: =N7+M8 -> 286480
B9: 45935 | C9: 45880 | D9: 0 | E9: 0 | G9: 0 | H9: 0 | I9: 0 | J9: 0 | K9: 0 | L9: 0 | M9: =SUM(C9:L9) -> 45880 | N9: =N8+M9 -> 332360
B10: 45936 | D10: 0 | E10: 0 | G10: 0 | H10: 0 | J10: 0 | K10: 0 | L10: 0 | M10: =SUM(C10:L10) -> 0 | N10: =N9+M10 -> 332360
B11: 45937 | C11: 0 | D11: 0 | E11: 0 | G11: 0 | H11: 0 | I11: 0 | J11: 0 | K11: 0 | L11: 0 | M11: =SUM(C11:L11) -> 0 | N11: =N10+M11 -> 332360
B12: 45938 | C12: 21100 | D12: 0 | E12: 0 | G12: 0 | H12: 0 | I12: 43160 | J12: 0 | K12: 0 | L12: 0 | M12: =SUM(C12:L12) -> 64260 | N12: =N11+M12 -> 396620
B13: 45939 | C13: 23460 | D13: 0 | E13: 16200 | G13: 0 | H13: 0 | I13: 0 | J13: 0 | K13: 0 | L13: 0 | M13: =SUM(C13:L13) -> 39660 | N13: =N12+M13 -> 436280
B14: 45940 | C14: 19880 | D14: 0 | E14: 14790 | G14: 28020 | H14: 0 | I14: 0 | J14: 0 | K14: 0 | L14: 0 | M14: =SUM(C14:L14) -> 62690 | N14: =N13+M14 -> 498970
B15: 45941 | C15: 21940 | D15: 0 | E15: 0 | G15: 0 | H15: 0 | I15: 22150 | J15: 19260 | K15: 23570 | L15: 0 | M15: =SUM(C15:L15) -> 86920 | N15: =N14+M15 -> 585890
B16: 45942 | C16: 47900 | D16: 0 | E16: 0 | G16: 0 | H16: 0 | I16: 0 | J16: 0 | K16: 0 | L16: 23190 | M16: =SUM(C16:L16) -> 71090 | N16: =N15+M16 -> 656980
B17: 45943 | C17: 21750 | D17: 0 | E17: 0 | G17: 24420 | H17: 0 | I17: 0 | J17: 20760 | K17: 0 | L17: 0 | M17: =SUM(C17:L17) -> 66930 | N17: =N16+M17 -> 723910
B18: 45944 | C18: 21140 | D18: 0 | E18: 17900 | G18: 0 | H18: 25020 | I18: 0 | J18: 0 | K18: 0 | L18: 0 | M18: =SUM(C18:L18) -> 64060 | N18: =N17+M18 -> 787970
B19: 45945 | C19: 20310 | D19: 0 | E19: 0 | G19: 23350 | H19: 0 | I19: 21670 | J19: 0 | K19: 0 | L19: 0 | M19: =SUM(C19:L19) -> 65330 | N19: =N18+M19 -> 853300
B20: 45946 | C20: 24180 | D20: 0 | E20: 0 | G20: 0 | H20: 25640 | I20: 22820 | J20: 0 | K20: 0 | L20: 0 | M20: =SUM(C20:L20) -> 72640 | N20: =N19+M20 -> 925940
B21: 45947 | C21: 23900 | D21: 0 | E21: 19550 | G21: 24470 | H21: 0 | I21: 0 | J21: 0 | K21: 0 | L21: 0 | M21: =SUM(C21:L21) -> 67920 | N21: =N20+M21 -> 993860
B22: 45948 | C22: 25340 | D22: 0 | E22: 0 | G22: 0 | H22: 0 | I22: 41070 | J22: 0 | K22: 0 | L22: 0 | M22: =SUM(C22:L22) -> 66410 | N22: =N21+M22 -> 1060270
... B34: 45960 | C34: 21750 | D34: 0 | E34: 0 | G34: 0 | H34: 23070 | I34: 23070 | J34: 0 | K34: 0 | L34: 0 | M34: =SUM(C34:L34) -> 67890 | N34: =N33+M34 -> 2017630
B35: 45961 | C35: 22990 | E35: 14330 | G35: 22450 | K35: 23790 | M35: =SUM(C35:L35) -> 83560 | N35: =N34+M35 -> 2101190
B36: 합 계 | C36: =SUM(C5:C35) -> 739760 | D36: =SUM(D5:D35) -> 109700 | E36: =SUM(E5:E35) -> 95660 | F36: =SUM(F5:F35) -> 0 | G36: =SUM(G5:G35) -> 261760 | H36: =SUM(H5:H35) -> 157650 | I36: =SUM(I5:I35) -> 446290 | J36: =SUM(J5:J35) -> 78750 | ... M36: =SUM(M5:M35) -> 2101190
B37: 처리단가 | C37: 33000 | D37: 35000 | E37: 33000 | F37: 30000 | G37: 35000 | H37: 35000 | I37: 35000 | J37: 43000 | K37: 33000 | L37: 37000 | M37: =M38/M36*1000 -> 34392.668
B38: 처리비용 | C38: =C36*C37/1000 -> 24412080 | D38: =D36*D37/1000 -> 3839500 | E38: =E36*E37/1000 -> 3156780 | F38: =F36*F37/1000 -> 0 | G38: =G36*G37/1000 -> 9161600 | H38: =H36*H37/1000 -> 5517750 | I38: =I36*I37/1000 -> 15620150 | J38: =J36*J37/1000 -> 3386250 | ... L38: =L36*L37/1000 -> 1738630 | M38: =SUM(C38:L38) -> 72265530

Sheet 5. 설비개선 비용현황
B2: 1. '24년 설비개선 T.F.T
B5: 월 | C5: 지급액 | D5: 사용액 | E5: 잔 액 | F5: 사용처 | H5: 구 분 | I5: No. | J5: Item | K5: 계획비용(백만원) | L5: 실 비용(원) | M5: 완료여부
B6: 1 | C6: 50000000 | D6: 2625500 | E6: =C6-D6 -> 47374500 | F6: '23년 I.D Fan Power Cell 및 고압인버터용 GDB 구입비용 차액 정산 | H6: 설비 개선 | I6: 1 | J6: 탄산암모늄 및 희석수 탱크 이설 및 라인 개선 | K6: 140
B7: 2 | C7: 50000000 | D7: 0 | E7: =E6+C7-D7 -> 97374500 | F7: - | I7: 2 | J7: 에너지회수효율 계측기 추가 설치 및 검교정 | K7: 100
B8: 3 | C8: 50000000 | D8: 0 | E8: =E7+C8-D8 -> 147374500 | F8: - | I8: 3 | J8: 컴프레셔 토출 덕트 라인 개선 | K8: 14
B9: 4 | C9: 50000000 | D9: =15000000+4625000+1300000 -> 20925000 | E9: =E8+C9-D9 -> 176449500 | F9: 백필터 펄싱 배관 (15백만원) + 펄싱밸브 구매 (4.6백만원) +HMI점검 (1.3백만원) | I9: 4 | J9: 습식세정탑 보충수 공급 배관 개선 (여과집진기 공사비용에 포함) | K9: 3 | L9: 0 | M9: 완료
B10: 5 | C10: 50000000 | D10: 950000 | E10: =E9+C10-D10 -> 225499500 | F10: 유인송풍기 PID점검(지아이) | H10: 유지 보수 | I10: 1 | J10: 2차 연소실 내화물 보수 | K10: 260
B11: 6 | C11: 50000000 | E11: =E10+C11-D11 -> 275499500 | I11: 2 | J11: 압입송풍기 모터 및 임펠러 교체 | K11: 40
B12: 7 | E12: =E11+C12-D12 -> 275499500 | I12: 3 | J12: 산기관 교체 | K12: 30
B13: 8 | E13: =E12+C13-D13 -> 275499500 | I13: 4 | J13: 여과집진기 역세 노즐 교체 (펄스V/V구매비 4.6백만원 추가) | K13: 13 | L13: =15000000+4625000 -> 19625000 | M13: 완료
B14: 9 | E14: =E13+C14-D14 -> 275499500 | H14: 추진건수 | I14: =COUNTA(I6:I13) -> 8 | J14: 완료건수 | K14: =SUM(K6:K13) -> 600 | L14: =SUM(L6:L13) -> 19625000 | M14: =COUNTA(M6:M13) -> 2
B15: 10 | E15: =E14+C15-D15 -> 275499500
B16: 11 | E16: =E15+C16-D16 -> 275499500
B17: 12 | E17: =E16+C17-D17 -> 275499500
B18: 총 액 | C18: =SUM(C6:C17) -> 300000000 | D18: =SUM(D6:D17) -> 24500500 | E18: =C18-D18 -> 275499500

Sheet 5. 25년 설비개선리스트
B2: 1. '25년 설비개선 T.F.T
B5: 월 | C5: 지급액 | D5: 사용액 | E5: 잔 액 | F5: 업체명 | G5: 사용처 | I5: 구 분 | J5: No. | K5: Item | L5: 계획비용(백만원) | M5: 실 비용(원) | N5: 완료여부
B6: 1 | C6: 50000000 | D6: 0 | E6: =C6-D6 -> 50000000 | I6: 설비 개선 | J6: 1 | K6: 컴프레셔 수냉식 쿨러 설치 | L6: 12 | M6: =D17+D19 -> 10250000 | N6: 완료
B7: 2 | C7: 50000000 | D7: 41520000 | E7: =E6+C7-D7 -> 58480000 | F7: 케이앤이 | G7: 기관실 에너지회수효율 개선공사 | J7: 2 | K7: 컨베이어 롤 브러쉬 설치 | L7: 60
B8: 3 | C8: 50000000 | D8: 36000000 | E8: =E7+C8-D8 -> 72480000 | F8: 우진라페 | G8: 1차 연소실 내화물 보수공사 (50%) | J8: 3 | K8: 혼합연료호퍼 물분무 소화설비 설치 | L8: 17
B9: 4 | C9: 50000000 | D9: 5300000 | E9: =E8+C9-D9 -> 117180000 | F9: 지아이오토메이션 | G9: 유인송풍기 인터록 작업 | J9: 4 | K9: 습식세정탑 폴링 교체 및 덕트 보수 | L9: 40 | M9: =D13 -> 29000000 | O9: 덕트보수 건 추가 진행 필요
D10: 36000000 | E10: =E9+C10-D10 -> 81180000 | F10: 우진라페 | G10: 1차 연소실 내화물 보수공사 잔금 (50%) | J10: 5 | K10: 급수탱크 교체 및 급수 라인 내림관 설치 공사 | L10: 70
D11: 6350000 | E11: =E10+C11-D11 -> 74830000 | F11: 다올씨앤씨 | G11: 제어실 LED DID교체 계약금(50%) | J11: 6 | K11: 전기 분전반 설치 | L11: 37
D12: 6250000 | E12: =E11+C12-D12 -> 68580000 | F12: 거성산업 | G12: 혼합연료 로터리밸브 'B' 구매 계약금 (50%) | J12: 7 | K12: 탄산암모늄 공급 펌프 탱크 및 펌프 용량 개선 | L12: 120
B13: 5 | C13: 50000000 | D13: 29000000 | E13: =E12+C13-D13 -> 89580000 | F13: 와이티엔텍 | G13: 세정탑 폴링 교체 | I13: 유지 보수 | J13: 1 | K13: 소각로 산기관 교체 | L13: 59
D14: 6350000 | E14: =E13+C14-D14 -> 83230000 | F14: 다올씨앤씨 | G14: 제어실 LED DID교체 잔금(50%) | J14: 2 | K14: 압입송풍기 /유인송풍기 인터버 오버홀 | L14: 13 | M14: =D20 -> 12000000 | N14: 완료
D15: 6250000 | E15: =E14+C15-D15 -> 76980000 | F15: 거성산업 | G15: 혼합연료 로터리밸브 'B' 구매 잔금 (50%) | J15: 3 | K15: 보일러 드럼 하부 부식 개선 및 보온 | L15: 30
B16: 6 | C16: 50000000 | D16: 18100000 | E16: =E15+C16-D16 -> 108880000 | F16: 선드라이브 | G16: 압입 / 유인송풍기 인버터 스패어 구매 | J16: 4 | K16: 제어실 LED모니터 교체 | L16: 12 | M16: =(D11+D14) -> 12700000 | N16: 완료
B17: 7 | C17: 50000000 | D17: 5000000 | E17: =E16+C17-D17 -> 153880000 | F17: 정풍산업 | G17: 에어컴프레셔 수냉식 쿨러 설치 (A) | J17: 5 | K17: 소각로 내화물 보수 공사 | L17: 130 | M17: 72000000 | N17: 완료 | O17: 진척률
D18: 8490000 | E18: =E17+C18-D18 -> 145390000 | F18: 승현상사 | G18: 냉난방기 설치 | I18: 추진건수 | J18: =COUNTA(J6:J17) -> 12 | K18: 완료건수 | L18: =SUM(L6:L17) -> 600 | M18: =SUM(M6:M17) -> 135950000 | N18: =COUNTA(N6:N17) -> 4 | O18: =N18/J18 -> 0.33333333
B19: 8 | C19: 50000000 | D19: 5250000 | E19: =E18+C19-D19 -> 190140000 | F19: 정풍산업 | G19: 에어컴프레셔 수냉식 쿨러 설치 (B) | I19: 추가 작업사항 (개선비용처리) | J19: 1 | K19: =G7 -> 기관실 에너지회수효율 개선공사 | M19: =D7 -> 41520000 | N19: 완료
D20: 12000000 | E20: =E19+C20-D20 -> 178140000 | F20: 선드라이브 | G20: 압입 / 유인송풍기 인버터 오버홀 | J20: 2 | K20: 유인송풍기 HMI 인터록 설정 작업 | M20: =D9 -> 5300000 | N20: 완료
B21: 9 | C21: 50000000 | D21: 900000 | E21: =E20+C21-D21 -> 227240000 | F21: 지아이오토메이션 | G21: 유동상 PLC점검 및 HMI수정 출장비 | J21: 3 | K21: 혼합연료 로터리밸브 'B' 구매 | M21: 12500000 | N21: 완료
D22: 25750000 | E22: =E21+C22-D22 -> 201490000 | F22: 와이티엔텍 | G22: 유동상소각로 습식세정탑 노즐 배관 개선 공사 (계약금 50%) | J22: 4 | K22: =G16 -> 압입 / 유인송풍기 인버터 스패어 구매 | M22: =D16 -> 18100000 | N22: 완료
B23: 10 | C23: 50000000 | D23: 0 | E23: =E22+C23-D23 -> 251490000 | J23: 5 | K23: =G18 -> 냉난방기 설치 | M23: =D18 -> 8490000 | N23: 완료
B24: 11 | E24: =E23+C24-D24 -> 251490000 | J24: 6
B25: 12 | E25: =E24+C25-D25 -> 251490000 | J25: 7
B26: 총 액 | C26: =SUM(C6:C25) -> 500000000 | D26: =SUM(D6:D25) -> 248510000 | E26: =C26-D26 -> 251490000 | J26: 8
I27: 추가건수 | J27: =COUNTA(J19:J26) -> 8 | K27: 합계금액 | M27: =SUM(M19:M26) -> 85910000 | N27: =COUNTA(N19:N26) -> 5
L28: 총 계 | M28: =M18+M27 -> 221860000 | N28: =N27+N18&"건" -> 9건

Sheet 6. 25년 사고이력
B2: '25년 유동상소각로 설비 사고 이력
B4: No. | C4: 일 자 | D4: 사 유 | E4: 조치내역 | F4: 운휴시간(Hr) | G4: 손실금액(백만원) | H4: 비 고
B5: 1 | C5: 45666 | D5: 유인송풍기 인버터 트러블 불시 운휴 | E5: PLC A/O Module교체(전기팀) | F5: 3.8 | G5: 0.9 | H5: -
B6: 2 | C6: 45704 | D6: 유인송풍기 인버터 트러블 불시 운휴 및 혼합연료 이송컨베이어벨트 사행 발생 | E6: 인버터 점검(전기팀) 및 컨베이어벨트 이탈 방지용 가이드롤러 설치 | F6: 10 | G6: 5 | H6: -
B7: 3 | C7: 45736 | D7: 유인송풍기 인버터 트러블 불시 운휴 | E7: 토글스위치 접점 불량으로 케이블 우회 결선(전기팀) | F7: 14.3 | G7: 8.2 | H7: -
B8: 4 | C8: 45859 | D8: SRF투입 크레인 브레이크 코일 소손 | E8: 브레이크 코일 교체 (전기팀) | F8: 3.3 | G8: 0 | H8: -
B9: 5 | H9: -
B10: 6 | H10: -
B11: 7 | H11: -
B12: 발생횟수 | C12: =COUNTA(C5:C10) -> 4 | D12: 합 계 (Hr) | F12: =SUM(F5:F11) -> 31.4 | G12: =SUM(G5:G11) -> 14.1
D13: 합 계 (Day) | F13: =F12/24 -> 1.3083333
B17: 2. '25년 유동상소각로 정기 정비 이력
B19: No. | C19: 일 자 | D19: 사 유 | E19: 조치내역 | F19: 운휴시간(Hr) | G19: 비 고
B20: 1 | C20: 1/24~31 | D20: 보일러 정기정비 (제지 조단기간 이용 정비진행) | E20: 보일러 및 공기예열기 소제 및 점검 | F20: 174.5
B21: 2 | C21: 3/27~4/6 | D21: 보일러 정기정비 (제지 조단기간 이용 정비진행) | E21: 1차 연소실 내화물 보수 및 B/F클리닝 등 | F21: 229.67 | H21: 제지 조단기간 제외 시 31hr 추가운휴(4/5~6)
B22: 3 | C22: 6/10~16 | D22: 보일러 정기정비 (제지 조단기간 이용 정비진행) | E22: 보일러 및 공기예열기 소제 및 점검 | F22: 143
B23: 4 | C23: 8/16~21 | D23: 보일러 정기정비 | E23: 보일러 및 공기예열기 소제 및 점검, 인버터 오버홀 | F23: 145.5 | H23: 폐합성2호기 잦은 운휴로 정비기간 고정비 지급 처리로 합의
B30: 정비횟수 | C30: =COUNTA(C20:C29) -> 4 | D30: 합 계 (Hr) | F30: =SUM(F20:F29) -> 692.67
D31: 합 계 (Day) | F31: =F30/24 -> 28.86125
G32: 총 운휴시간 | H32: =F12+F30 -> 724.07
G33: 총 운휴일수 | H33: =H32/24 -> 30.169583
E34: .

Sheet 유동상 약품 원단위
B3: 구 분 | C3: '22. 1월 | D3: 2월 | E3: 3월 | F3: 4월 | G3: 5월 | H3: 6월 | I3: 7월 | J3: 8월 | K3: 9월 | L3: 10월 | M3: 11월 | N3: 12월 | O3: 합 계
B4: 스팀 생산량 | C4: 16136.7 | D4: 11273.9 | E4: 14891.6 | F4: 14558.4 | G4: 11423.3 | H4: 13862.8 | I4: 12888.4 | J4: 12136.8 | K4: 10375 | L4: 12357.8 | M4: 9236.4 | N4: 12297.8 | O4: =SUM(C4:N4) -> 151438.9
B5: 약품 구입비 | C5: 97271500 | D5: 75656545 | E5: 86333700 | F5: 80534545 | G5: 88906579 | H5: 92472536 | I5: 85970209 | J5: 92287291 | K5: 80412891 | L5: 95014995 | M5: 72445198 | N5: 82566887 | O5: =SUM(C5:N5) -> 1.0298729e+09
B6: 원단위 | C6: =ROUNDUP(C5/C4,0) -> 6028 | D6: =ROUNDUP(D5/D4,0) -> 6711 | E6: =ROUNDUP(E5/E4,0) -> 5798 | F6: =ROUNDUP(F5/F4,0) -> 5532 | G6: =ROUNDUP(G5/G4,0) -> 7783 | H6: =ROUNDUP(H5/H4,0) -> 6671 | I6: =ROUNDUP(I5/I4,0) -> 6671 | J6: =ROUNDUP(J5/J4,0) -> 7604 | ... N6: =ROUNDUP(N5/N4,0) -> 6714 | O6: =TRUNC(O5/O4,-1) -> 6800
B9: * 유동상 연간 운영비
B11: 1. 인건비 등 고정비 | D11: =139*12 -> 1668 | E11: 백만원/년
B12: 2. 측정비 / 소수선비 | D12: =33*12 -> 396 | E12: 백만원/년
B13: 3. 유지보수비 | D13: 780 | E13: 백만원/년
B14: 4. 약품비 | D14: =O5/1000000 -> 1029.8729 | E14: 백만원/년
B15: 5. 연간 예상 운영비 | D15: =SUM(D11:D14) -> 3873.8729 | E15: 백만원/년
