Workbook

Sheet 1
A1: 근 무 자 | B1: 오 전 | D1: 오 후 | F1: 야 간 | H1: 유동상소각로 운전일지 | T1: 결 재 | U1: 반장 | W1: 대리 | Y1: 팀장
B2: 권정민 | D2: 김문한 | F2: 임종민
H3: 46204
A5: 1. 소각현황(KG) | P5: 2. BOILER 운전현황(TON, HR)
A6: 구 분 | D6: SRF소각량 | G6: SLUDGE 소각량 | J6: 합 계 | P6: 구 분 | R6: 스팀 생산량 | U6: 스팀 송기량 | X6: 가동시간
A7: 금 일 | D7: 70549 | G7: 170800 | J7: =D7+G7 -> 241349 | P7: 금 일 | R7: 475.7 | U7: 277.8 | X7: 24
A8: 누 계 | D8: =D7 -> 70549 | G8: =G7 -> 170800 | J8: =D8+G8 -> 241349 | P8: 누 계 | R8: =R7 -> 475.7 | U8: =U7 -> 277.8 | X8: =X7 -> 24
A10: 3. 약품 사용현황 (KG) | P10: 4. 소각재 발생량 (TON, 대)
A11: 품 명 | C11: 전일 재고량 | E11: 입고량 | G11: 사용량 | I11: 재고량 | K11: 입고량 누계 | M11: 사용량 누계 | P11: 구 분 | S11: 반출량 | W11: 누계
A12: 탄산암모늄 | C12: 14914 | E12: 0 | G12: 3339 | I12: =C12+E12-G12 -> 11575 | K12: =E12 -> 0 | M12: =G12 -> 3339 | P12: 비산재 | S12: 54.12 | W12: =S12 -> 54.12
A13: 청관제 | C13: 590 | E13: 0 | G13: 90 | I13: =C13+E13-G13 -> 500 | K13: =E13 -> 0 | M13: =G13 -> 90
A14: 활성탄 | C14: 600 | E14: 0 | G14: 120 | I14: =C14+E14-G14 -> 480 | K14: =E14 -> 0 | M14: =G14 -> 120 | P14: 바닥재 | S14: 24.1 | W14: =S14 -> 24.1
A15: 가성소다 | C15: 1299 | E15: 0 | G15: 33 | I15: =C15+E15-G15 -> 1266 | K15: =E15 -> 0 | M15: =G15 -> 33
A16: 소석회 | C16: 2350 | E16: 0 | G16: 20 | I16: =C16+E16-G16 -> 2330 | K16: =E16 -> 0 | M16: =G16 -> 20 | P16: 구분 | S16: 주간 | U16: 야간 | W16: 합계 | Y16: 누계
A17: 소 금 | C17: 1850 | E17: 0 | G17: 200 | I17: =C17+E17-G17 -> 1650 | K17: =E17 -> 0 | M17: =G17 -> 200
A18: 경 유 | C18: 5340 | E18: 0 | G18: 0 | I18: =C18+E18-G18 -> 5340 | K18: =E18 -> 0 | M18: =G18 -> 0 | P18: 불연물 | S18: 2 | U18: 1 | W18: =S18+U18 -> 3 | Y18: =W18 -> 3
A19: SRF | C19: 110000 | E19: 70150 | G19: =D7 -> 70549 | I19: =C19+E19-G19 -> 109601 | K19: =E19 -> 70150 | M19: =G19 -> 70549
A20: 규 사 | I20: - | K20: =E20 -> 0 | M20: =G20 -> 0
A22: 5. 전력 사용량 (KWH) | P22: 6. 유틸리티 사용현황 (㎥)
A23: 구 분 | D23: 전일지침 | G23: 금일지침 | J23: 사용량 | M23: 누 계 | P23: 구 분 | S23: 전일 사용량 | V23: 금일 사용량 | Y23: 누 계
A24: MAIN | D24: 3671568 | G24: 3714008 | J24: =G24-D24 -> 42440 | K24: 12.255 | L24: 12.255 | M24: =J24 -> 42440 | P24: 재이용수 | V24: 432.2 | Y24: =V24 -> 432.2
A25: ASH 저장조 | D25: 32764.1 | G25: 32826.1 | J25: =G25-D25 -> 62 | K25: 12.255 | L25: 12.255 | M25: =J25 -> 62 | P25: 복류수 | V25: 56.4 | Y25: =V25 -> 56.4
A26: BAG FILTER | D26: 24300 | G26: 24340 | J26: =G26-D26 -> 40 | K26: 12.255 | L26: 12.255 | M26: =J26 -> 40 | P26: 응축수 | V26: 477.8 | Y26: =V26 -> 477.8
A27: SCRUBBER | D27: 1339000 | G27: 1346000 | J27: =G27-D27 -> 7000 | K27: 12.255 | L27: 12.255 | M27: =J27 -> 7000 | P27: 보일러 급수 | V27: 500.3 | Y27: =V27 -> 500.3
A28: 활성탄 공급 | D28: 4938 | G28: 5045 | J28: =G28-D28 -> 107 | K28: 12.255 | L28: 12.255 | M28: =J28 -> 107 | P28: 폐 수 | V28: 0 | Y28: =V28 -> 0
A29: 소석회 공급 | D29: 66180 | G29: 66190 | J29: =G29-D29 -> 10 | K29: 12.255 | L29: 12.255 | M29: =J29 -> 10 | P29: 연 수 | V29: 61.6 | Y29: =V29 -> 61.6
A30: 요소수 공급 | D30: 53220 | G30: 53250 | J30: =G30-D30 -> 30 | K30: 12.255 | L30: 12.255 | M30: =J30 -> 30 | P30: 계 | V30: 0 | Y30: =SUM(Y24:Z29) -> 1528.3
A31: F.D | D31: 6202095 | G31: 6216379 | J31: =G31-D31 -> 14284 | K31: 12.255 | L31: 12.255 | M31: =J31 -> 14284
A32: 활성탄 BAG | D32: 1.6 | G32: 1.6 | J32: =G32-D32 -> 0 | K32: 12.255 | L32: 12.255 | M32: =J32 -> 0
A33: 소석회 BAG | D33: 0 | G33: 0 | J33: =G33-D33 -> 0 | K33: 12.255 | L33: 12.255 | M33: =J33 -> 0
A35: 7. 특이사항
A36: 오 전
A49: 오 후
A63: 야 간

Sheet 2
A1: 근 무 자 | B1: 오 전 | D1: 오 후 | F1: 야 간 | H1: 유동상소각로 운전일지 | T1: 결 재 | U1: 반장 | W1: 대리 | Y1: 팀장
B2: 권정민 | D2: 김문한 | F2: 임종민
H3: 46205
A5: 1. 소각현황(KG) | P5: 2. BOILER 운전현황(TON, HR)
A6: 구 분 | D6: SRF소각량 | G6: SLUDGE 소각량 | J6: 합 계 | P6: 구 분 | R6: 스팀 생산량 | U6: 스팀 송기량 | X6: 가동시간
A7: 금 일 | D7: 63525 | G7: 178400 | J7: =D7+G7 -> 241925 | P7: 금 일 | R7: 481.2 | U7: 327.4 | X7: 24
A8: 누 계 | D8: ='1'!D8+D7 -> 134074 | G8: ='1'!G8+'2'!G7 -> 349200 | J8: =D8+G8 -> 483274 | P8: 누 계 | R8: ='1'!R8+R7 -> 956.9 | U8: ='1'!U8+U7 -> 605.2 | X8: ='1'!X8+'2'!X7 -> 48
A10: 3. 약품 사용현황 (KG) | P10: 4. 소각재 발생량 (TON, 대)
A11: 품 명 | C11: 전일 재고량 | E11: 입고량 | G11: 사용량 | I11: 재고량 | K11: 입고량 누계 | M11: 사용량 누계 | P11: 구 분 | S11: 반출량 | W11: 누계
A12: 탄산암모늄 | C12: ='1'!I12 -> 11575 | E12: 0 | G12: 3812 | I12: =C12+E12-G12 -> 7763 | K12: ='1'!K12+E12 -> 0 | M12: ='1'!M12+G12 -> 7151 | P12: 비산재 | S12: 55.53 | W12: ='1'!W12+'2'!S12 -> 109.65
A13: 청관제 | C13: ='1'!I13 -> 500 | E13: 0 | G13: 100 | I13: =C13+E13-G13 -> 400 | K13: ='1'!K13+E13 -> 0 | M13: ='1'!M13+G13 -> 190
A14: 활성탄 | C14: ='1'!I14 -> 480 | E14: 0 | G14: 120 | I14: =C14+E14-G14 -> 360 | K14: ='1'!K14+E14 -> 0 | M14: ='1'!M14+G14 -> 240 | P14: 바닥재 | S14: 0 | W14: ='1'!W14+'2'!S14 -> 24.1
A15: 가성소다 | C15: ='1'!I15 -> 1266 | E15: 0 | G15: 31 | I15: =C15+E15-G15 -> 1235 | K15: ='1'!K15+E15 -> 0 | M15: ='1'!M15+G15 -> 64
A16: 소석회 | C16: ='1'!I16 -> 2330 | E16: 0 | G16: 20 | I16: =C16+E16-G16 -> 2310 | K16: ='1'!K16+E16 -> 0 | M16: ='1'!M16+G16 -> 40 | P16: 구분 | S16: 주간 | U16: 야간 | W16: 합계 | Y16: 누계
A17: 소 금 | C17: ='1'!I17 -> 1650 | E17: 0 | G17: 200 | I17: =C17+E17-G17 -> 1450 | K17: ='1'!K17+E17 -> 0 | M17: ='1'!M17+G17 -> 400
A18: 경 유 | C18: ='1'!I18 -> 5340 | E18: 0 | G18: 0 | I18: =C18+E18-G18 -> 5340 | K18: ='1'!K18+E18 -> 0 | M18: ='1'!M18+G18 -> 0 | P18: 불연물 | S18: 3 | U18: 2 | W18: =S18+U18 -> 5 | Y18: ='1'!Y18+W18 -> 8
A19: SRF | C19: ='1'!I19 -> 109601 | E19: 66230 | G19: =D7 -> 63525 | I19: =C19+E19-G19 -> 112306 | K19: ='1'!K19+E19 -> 136380 | M19: ='1'!M19+G19 -> 134074
A20: 규 사 | C20: ='1'!I20 -> - | I20: - | K20: ='1'!K20+'2'!E20 -> 0 | M20: =G20 -> 0
A22: 5. 전력 사용량 (KWH) | P22: 6. 유틸리티 사용현황 (㎥)
A23: 구 분 | D23: 전일지침 | G23: 금일지침 | J23: 사용량 | M23: 누 계 | P23: 구 분 | S23: 전일 사용량 | V23: 금일 사용량 | Y23: 누 계
A24: MAIN | D24: ='1'!G24 -> 3714008 | G24: 3735314 | J24: =G24-D24 -> 21306 | M24: ='1'!$J24+$J24 -> 63746 | P24: 재이용수 | S24: ='1'!V24 -> 432.2 | V24: 429.1 | Y24: ='1'!Y24+'2'!V24 -> 861.3
A25: ASH 저장조 | D25: ='1'!G25 -> 32826.1 | G25: 32858.2 | J25: =G25-D25 -> 32.1 | M25: ='1'!$J25+$J25 -> 94.1 | P25: 복류수 | S25: ='1'!V25 -> 56.4 | V25: 55.3 | Y25: ='1'!Y25+'2'!V25 -> 111.7
A26: BAG FILTER | D26: ='1'!G26 -> 24340 | G26: 24360 | J26: =G26-D26 -> 20 | M26: ='1'!$J26+$J26 -> 60 | P26: 응축수 | S26: ='1'!V26 -> 477.8 | V26: 499.6 | Y26: ='1'!Y26+'2'!V26 -> 977.4
A27: SCRUBBER | D27: ='1'!G27 -> 1346000 | G27: 1349000 | J27: =G27-D27 -> 3000 | M27: ='1'!$J27+$J27 -> 10000 | P27: 보일러 급수 | S27: ='1'!V27 -> 500.3 | V27: 514.9 | Y27: ='1'!Y27+'2'!V27 -> 1015.2
A28: 활성탄 공급 | D28: ='1'!G28 -> 5045 | G28: 5099 | J28: =G28-D28 -> 54 | M28: ='1'!$J28+$J28 -> 161 | P28: 폐 수 | S28: ='1'!V28 -> 0 | V28: 0 | Y28: ='1'!Y28+'2'!V28 -> 0
A29: 소석회 공급 | D29: ='1'!G29 -> 66190 | G29: 66190 | J29: =G29-D29 -> 0 | M29: ='1'!$J29+$J29 -> 10 | P29: 연 수 | S29: ='1'!V29 -> 61.6 | V29: 59.7 | Y29: ='1'!Y29+'2'!V29 -> 121.3
A30: 요소수 공급 | D30: ='1'!G30 -> 53250 | G30: 53260 | J30: =G30-D30 -> 10 | M30: ='1'!$J30+$J30 -> 40 | P30: 계 | S30: =SUM(S24:U29) -> 1528.3 | V30: 0 | Y30: ='1'!Y30+'2'!V30 -> 1528.3
A31: F.D | D31: ='1'!G31 -> 6216379 | G31: 6223530 | J31: =G31-D31 -> 7151 | K31: 12.255 | L31: 12.255 | M31: ='1'!M31+J31 -> 21435
A32: 활성탄 BAG | D32: ='1'!G32 -> 1.6 | G32: 1.6 | J32: =G32-D32 -> 0 | K32: 12.255 | L32: 12.255 | M32: ='1'!M32+J32 -> 0
A33: 소석회 BAG | D33: ='1'!G33 -> 0 | G33: 0 | J33: =G33-D33 -> 0 | K33: 12.255 | L33: 12.255 | M33: ='1'!M33+J33 -> 0
A35: 7. 특이사항
A36: 오 전
A49: 오 후
A63: 야 간

Sheet 3
A1: 근 무 자 | B1: 오 전 | D1: 오 후 | F1: 야 간 | H1: 유동상소각로 운전일지 | T1: 결 재 | U1: 반장 | W1: 대리 | Y1: 팀장
B2: 권정민 | D2: 김동욱 | F2: 임종민
H3: 46206
A5: 1. 소각현황(KG) | P5: 2. BOILER 운전현황(TON, HR)
A6: 구 분 | D6: SRF소각량 | G6: SLUDGE 소각량 | J6: 합 계 | P6: 구 분 | R6: 스팀 생산량 | U6: 스팀 송기량 | X6: 가동시간
A7: 금 일 | D7: 63380 | G7: 157600 | J7: =D7+G7 -> 220980 | P7: 금 일 | R7: 478 | U7: 390.8 | X7: 24
A8: 누 계 | D8: ='2'!D8+D7 -> 197454 | G8: ='2'!G8+'3'!G7 -> 506800 | J8: =D8+G8 -> 704254 | P8: 누 계 | R8: ='2'!R8+'3'!R7 -> 1434.9 | U8: ='2'!U8+U7 -> 996 | X8: ='2'!X8+'3'!X7 -> 72
A10: 3. 약품 사용현황 (KG) | P10: 4. 소각재 발생량 (TON, 대)
A11: 품 명 | C11: 전일 재고량 | E11: 입고량 | G11: 사용량 | I11: 재고량 | K11: 입고량 누계 | M11: 사용량 누계 | P11: 구 분 | S11: 반출량 | W11: 누계
A12: 탄산암모늄 | C12: ='2'!I12 -> 7763 | E12: 15450 | G12: 3638 | I12: =C12+E12-G12 -> 19575 | K12: ='2'!K12+E12 -> 15450 | M12: ='2'!M12+G12 -> 10789 | P12: 비산재 | S12: 58.74 | W12: ='2'!W12+'3'!S12 -> 168.39
A13: 청관제 | C13: ='2'!I13 -> 400 | E13: 710 | G13: 100 | I13: =C13+E13-G13 -> 1010 | K13: ='2'!K13+E13 -> 710 | M13: ='2'!M13+G13 -> 290
A14: 활성탄 | C14: ='2'!I14 -> 360 | E14: 0 | G14: 120 | I14: =C14+E14-G14 -> 240 | K14: ='2'!K14+E14 -> 0 | M14: ='2'!M14+G14 -> 360 | P14: 바닥재 | S14: 0 | W14: ='2'!W14+'3'!S14 -> 24.1
A15: 가성소다 | C15: ='2'!I15 -> 1235 | E15: 0 | G15: 24 | I15: =C15+E15-G15 -> 1211 | K15: ='2'!K15+E15 -> 0 | M15: ='2'!M15+G15 -> 88
A16: 소석회 | C16: ='2'!I16 -> 2310 | E16: 0 | G16: 20 | I16: =C16+E16-G16 -> 2290 | K16: ='2'!K16+E16 -> 0 | M16: ='2'!M16+G16 -> 60 | P16: 구분 | S16: 주간 | U16: 야간 | W16: 합계 | Y16: 누계
A17: 소 금 | C17: ='2'!I17 -> 1450 | E17: 0 | G17: 200 | I17: =C17+E17-G17 -> 1250 | K17: ='2'!K17+E17 -> 0 | M17: ='2'!M17+G17 -> 600
A18: 경 유 | C18: ='2'!I18 -> 5340 | E18: 0 | G18: 0 | I18: =C18+E18-G18 -> 5340 | K18: ='2'!K18+E18 -> 0 | M18: ='2'!M18+G18 -> 0 | P18: 불연물 | S18: 2 | U18: 2 | W18: =S18+U18 -> 4 | Y18: ='2'!Y18+'3'!W18 -> 12
A19: SRF | C19: ='2'!I19 -> 112306 | E19: 64150 | G19: =D7 -> 63380 | I19: =C19+E19-G19 -> 113076 | K19: ='2'!K19+E19 -> 200530 | M19: ='2'!M19+G19 -> 197454
A20: 규 사 | C20: ='2'!I20 -> - | I20: - | K20: ='2'!K20+'3'!E20 -> 0 | M20: =G20 -> 0
A22: 5. 전력 사용량 (KWH) | P22: 6. 유틸리티 사용현황 (㎥)
A23: 구 분 | D23: 전일지침 | G23: 금일지침 | J23: 사용량 | M23: 누 계 | P23: 구 분 | S23: 전일 사용량 | V23: 금일 사용량 | Y23: 누 계
A24: MAIN | D24: ='2'!G24 -> 3735314 | G24: 3756081 | J24: =G24-D24 -> 20767 | M24: ='2'!M24+J24 -> 84513 | P24: 재이용수 | S24: ='2'!V24 -> 429.1 | V24: 427.2 | Y24: ='2'!Y24+'3'!V24 -> 1288.5
A25: ASH 저장조 | D25: ='2'!G25 -> 32858.2 | G25: 32889.9 | J25: =G25-D25 -> 31.7 | M25: ='2'!M25+J25 -> 125.8 | P25: 복류수 | S25: ='2'!V25 -> 55.3 | V25: 56.1 | Y25: ='2'!Y25+'3'!V25 -> 167.8
A26: BAG FILTER | D26: ='2'!G26 -> 24360 | G26: 24370 | J26: =G26-D26 -> 10 | M26: ='2'!M26+J26 -> 70 | P26: 응축수 | S26: ='2'!V26 -> 499.6 | V26: 429.7 | Y26: ='2'!Y26+'3'!V26 -> 1407.1
A27: SCRUBBER | D27: ='2'!G27 -> 1349000 | G27: 1352000 | J27: =G27-D27 -> 3000 | M27: ='2'!M27+J27 -> 13000 | P27: 보일러 급수 | S27: ='2'!V27 -> 514.9 | V27: 481.3 | Y27: ='2'!Y27+'3'!V27 -> 1496.5
A28: 활성탄 공급 | D28: ='2'!G28 -> 5099 | G28: 5151 | J28: =G28-D28 -> 52 | M28: ='2'!M28+J28 -> 213 | P28: 폐 수 | S28: ='2'!V28 -> 0 | V28: 0 | Y28: ='2'!Y28+'3'!V28 -> 0
A29: 소석회 공급 | D29: ='2'!G29 -> 66190 | G29: 66190 | J29: =G29-D29 -> 0 | M29: ='2'!M29+J29 -> 10 | P29: 연 수 | S29: ='2'!V29 -> 59.7 | V29: 65.1 | Y29: ='2'!Y29+'3'!V29 -> 186.4
A30: 요소수 공급 | D30: ='2'!G30 -> 53260 | G30: 53270 | J30: =G30-D30 -> 10 | M30: ='2'!M30+J30 -> 50 | P30: 계 | S30: =SUM(S24:U29) -> 1558.6 | Y30: ='2'!Y30+'3'!V30 -> 1528.3
A31: F.D | D31: ='2'!G31 -> 6223530 | G31: 6230623 | J31: =G31-D31 -> 7093 | K31: 12.255 | L31: 12.255 | M31: ='2'!M31+J31 -> 28528
A32: 활성탄 BAG | D32: ='2'!G32 -> 1.6 | G32: 1.6 | J32: =G32-D32 -> 0 | K32: 12.255 | L32: 12.255 | M32: ='2'!M32+J32 -> 0
A33: 소석회 BAG | D33: ='2'!G33 -> 0 | G33: 0 | J33: =G33-D33 -> 0 | K33: 12.255 | L33: 12.255 | M33: ='2'!M33+J33 -> 0
A35: 7. 특이사항
A36: 오 전
A49: 오 후
A63: 야 간

Sheet 4
A1: 근 무 자 | B1: 오 전 | D1: 오 후 | F1: 야 간 | H1: 유동상소각로 운전일지 | T1: 결 재 | U1: 반장 | W1: 대리 | Y1: 팀장
B2: 권정민 | D2: 김동욱 | F2: 임종민
H3: 46207
A5: 1. 소각현황(KG) | P5: 2. BOILER 운전현황(TON, HR)
A6: 구 분 | D6: SRF소각량 | G6: SLUDGE 소각량 | J6: 합 계 | P6: 구 분 | R6: 스팀 생산량 | U6: 스팀 송기량 | X6: 가동시간
A7: 금 일 | D7: 59627 | G7: 159400 | J7: =D7+G7 -> 219027 | P7: 금 일 | R7: 477.1 | U7: 388.4 | X7: 24
A8: 누 계 | D8: ='3'!D8+D7 -> 257081 | G8: ='3'!G8+'4'!G7 -> 666200 | J8: =D8+G8 -> 923281 | P8: 누 계 | R8: ='3'!R8+R7 -> 1912 | U8: ='3'!U8+'4'!U7 -> 1384.4 | X8: ='3'!X8+X7 -> 96
A10: 3. 약품 사용현황 (KG) | P10: 4. 소각재 발생량 (TON, 대)
A11: 품 명 | C11: 전일 재고량 | E11: 입고량 | G11: 사용량 | I11: 재고량 | K11: 입고량 누계 | M11: 사용량 누계 | P11: 구 분 | S11: 반출량 | W11: 누계
A12: 탄산암모늄 | C12: ='3'!I12 -> 19575 | E12: 0 | G12: 4682 | I12: =C12+E12-G12 -> 14893 | K12: ='3'!K12+E12 -> 15450 | M12: ='3'!M12+'4'!G12 -> 15471 | P12: 비산재 | S12: 26.29 | W12: ='3'!W12+'4'!S12 -> 194.68
A13: 청관제 | C13: ='3'!I13 -> 1010 | E13: 0 | G13: 80 | I13: =C13+E13-G13 -> 930 | K13: ='3'!K13+E13 -> 710 | M13: ='3'!M13+'4'!G13 -> 370
A14: 활성탄 | C14: ='3'!I14 -> 240 | E14: 0 | G14: 120 | I14: =C14+E14-G14 -> 120 | K14: ='3'!K14+E14 -> 0 | M14: ='3'!M14+'4'!G14 -> 480 | P14: 바닥재 | S14: 22.74 | W14: ='3'!W14+'4'!S14 -> 46.84
A15: 가성소다 | C15: ='3'!I15 -> 1211 | E15: 0 | G15: 35 | I15: =C15+E15-G15 -> 1176 | K15: ='3'!K15+E15 -> 0 | M15: ='3'!M15+'4'!G15 -> 123
A16: 소석회 | C16: ='3'!I16 -> 2290 | E16: 0 | G16: 20 | I16: =C16+E16-G16 -> 2270 | K16: ='3'!K16+E16 -> 0 | M16: ='3'!M16+'4'!G16 -> 80 | P16: 구분 | S16: 주간 | U16: 야간 | W16: 합계 | Y16: 누계
A17: 소 금 | C17: ='3'!I17 -> 1250 | E17: 0 | G17: 200 | I17: =C17+E17-G17 -> 1050 | K17: ='3'!K17+E17 -> 0 | M17: ='3'!M17+'4'!G17 -> 800
A18: 경 유 | C18: ='3'!I18 -> 5340 | E18: 0 | G18: 0 | I18: =C18+E18-G18 -> 5340 | K18: ='3'!K18+E18 -> 0 | M18: ='3'!M18+'4'!G18 -> 0 | P18: 불연물 | S18: 1 | U18: 2 | W18: =S18+U18 -> 3 | Y18: ='3'!Y18+'4'!W18 -> 15
A19: SRF | C19: ='3'!I19 -> 113076 | E19: 62100 | G19: =D7 -> 59627 | I19: =C19+E19-G19 -> 115549 | K19: ='3'!K19+E19 -> 262630 | M19: ='3'!M19+'4'!G19 -> 257081
A20: 규 사 | C20: ='3'!I20 -> - | I20: - | K20: ='3'!K20+E20 -> 0 | M20: =G20 -> 0
A22: 5. 전력 사용량 (KWH) | P22: 6. 유틸리티 사용현황 (㎥)
A23: 구 분 | D23: 전일지침 | G23: 금일지침 | J23: 사용량 | M23: 누 계 | P23: 구 분 | S23: 전일 사용량 | V23: 금일 사용량 | Y23: 누 계
A24: MAIN | D24: ='3'!G24 -> 3756081 | G24: 3777062 | J24: =G24-D24 -> 20981 | M24: ='3'!M24+'4'!J24 -> 105494 | P24: 재이용수 | S24: ='3'!V24 -> 427.2 | V24: 428.1 | Y24: ='3'!Y24+V24 -> 1716.6
A25: ASH 저장조 | D25: ='3'!G25 -> 32889.9 | G25: 32922.4 | J25: =G25-D25 -> 32.5 | M25: ='3'!M25+'4'!J25 -> 158.3 | P25: 복류수 | S25: ='3'!V25 -> 56.1 | V25: 57.3 | Y25: ='3'!Y25+V25 -> 225.1
A26: BAG FILTER | D26: ='3'!G26 -> 24370 | G26: 24390 | J26: =G26-D26 -> 20 | M26: ='3'!M26+'4'!J26 -> 90 | P26: 응축수 | S26: ='3'!V26 -> 429.7 | V26: 430.3 | Y26: ='3'!Y26+V26 -> 1837.4
A27: SCRUBBER | D27: ='3'!G27 -> 1352000 | G27: 1356000 | J27: =G27-D27 -> 4000 | M27: ='3'!M27+'4'!J27 -> 17000 | P27: 보일러 급수 | S27: ='3'!V27 -> 481.3 | V27: 480.1 | Y27: ='3'!Y27+V27 -> 1976.6
A28: 활성탄 공급 | D28: ='3'!G28 -> 5151 | G28: 5204 | J28: =G28-D28 -> 53 | M28: ='3'!M28+'4'!J28 -> 266 | P28: 폐 수 | S28: ='3'!V28 -> 0 | V28: 0 | Y28: ='3'!Y28+V28 -> 0
A29: 소석회 공급 | D29: ='3'!G29 -> 66190 | G29: 66200 | J29: =G29-D29 -> 10 | M29: ='3'!M29+'4'!J29 -> 20 | P29: 연 수 | S29: ='3'!V29 -> 65.1 | V29: 60.8 | Y29: ='3'!Y29+V29 -> 247.2
A30: 요소수 공급 | D30: ='3'!G30 -> 53270 | G30: 53280 | J30: =G30-D30 -> 10 | M30: ='3'!M30+'4'!J30 -> 60 | P30: 계 | S30: =SUM(S24:U29) -> 1459.4 | Y30: ='3'!Y30+V30 -> 1528.3
A31: F.D | D31: ='3'!G31 -> 6230623 | G31: 6237766 | J31: =G31-D31 -> 7143 | K31: 12.255 | L31: 12.255 | M31: ='3'!M31+'4'!J31 -> 35671
A32: 활성탄 BAG | D32: ='3'!G32 -> 1.6 | G32: 1.6 | J32: =G32-D32 -> 0 | K32: 12.255 | L32: 12.255 | M32: ='3'!M32+'4'!J32 -> 0
A33: 소석회 BAG | D33: ='3'!G33 -> 0 | G33: 0 | J33: =G33-D33 -> 0 | K33: 12.255 | L33: 12.255 | M33: ='3'!M33+'4'!J33 -> 0
A35: 7. 특이사항
A36: 오 전
A49: 오 후
A63: 야 간

Sheet 5
A1: 근 무 자 | B1: 오 전 | D1: 오 후 | F1: 야 간 | H1: 유동상소각로 운전일지 | T1: 결 재 | U1: 반장 | W1: 대리 | Y1: 팀장
B2: 김문한 | D2: 김동욱 | F2: 임종민
H3: 46208
A5: 1. 소각현황(KG) | P5: 2. BOILER 운전현황(TON, HR)
A6: 구 분 | D6: SRF소각량 | G6: SLUDGE 소각량 | J6: 합 계 | P6: 구 분 | R6: 스팀 생산량 | U6: 스팀 송기량 | X6: 가동시간
A7: 금 일 | D7: 65675 | G7: 158700 | J7: =D7+G7 -> 224375 | P7: 금 일 | R7: 474 | U7: 344 | X7: 24
A8: 누 계 | D8: ='4'!D8+D7 -> 322756 | G8: ='4'!G8+'5'!G7 -> 824900 | J8: =D8+G8 -> 1147656 | P8: 누 계 | R8: ='4'!R8+'5'!R7 -> 2386 | U8: ='4'!U8+U7 -> 1728.4 | X8: ='4'!X8+'5'!X7 -> 120
A10: 3. 약품 사용현황 (KG) | P10: 4. 소각재 발생량 (TON, 대)
A11: 품 명 | C11: 전일 재고량 | E11: 입고량 | G11: 사용량 | I11: 재고량 | K11: 입고량 누계 | M11: 사용량 누계 | P11: 구 분 | S11: 반출량 | W11: 누계
A12: 탄산암모늄 | C12: ='4'!I12 -> 14893 | E12: 0 | G12: 3767 | I12: =C12+E12-G12 -> 11126 | K12: ='4'!K12+E12 -> 15450 | M12: ='4'!M12+G12 -> 19238 | P12: 비산재 | S12: 0 | W12: ='4'!W12+'5'!S12 -> 194.68
A13: 청관제 | C13: ='4'!I13 -> 930 | E13: 0 | G13: 110 | I13: =C13+E13-G13 -> 820 | K13: ='4'!K13+E13 -> 710 | M13: ='4'!M13+G13 -> 480
A14: 활성탄 | C14: ='4'!I14 -> 120 | E14: 0 | G14: 120 | I14: =C14+E14-G14 -> 0 | K14: ='4'!K14+E14 -> 0 | M14: ='4'!M14+G14 -> 600 | P14: 바닥재 | S14: 0 | W14: ='4'!W14+'5'!S14 -> 46.84
A15: 가성소다 | C15: ='4'!I15 -> 1176 | E15: 0 | G15: 29 | I15: =C15+E15-G15 -> 1147 | K15: ='4'!K15+E15 -> 0 | M15: ='4'!M15+G15 -> 152
A16: 소석회 | C16: ='4'!I16 -> 2270 | E16: 0 | G16: 20 | I16: =C16+E16-G16 -> 2250 | K16: ='4'!K16+E16 -> 0 | M16: ='4'!M16+G16 -> 100 | P16: 구분 | S16: 주간 | U16: 야간 | W16: 합계 | Y16: 누계
A17: 소 금 | C17: ='4'!I17 -> 1050 | E17: 1440 | G17: 200 | I17: =C17+E17-G17 -> 2290 | K17: ='4'!K17+E17 -> 1440 | M17: ='4'!M17+'5'!G17 -> 1000
A18: 경 유 | C18: ='4'!I18 -> 5340 | E18: 0 | G18: 0 | I18: =C18+E18-G18 -> 5340 | K18: ='4'!K18+E18 -> 0 | M18: ='4'!M18+G18 -> 0 | P18: 불연물 | S18: 3 | U18: 2 | W18: =S18+U18 -> 5 | Y18: ='4'!Y18+'5'!W18 -> 20
A19: SRF | C19: ='4'!I19 -> 115549 | E19: 45930 | G19: =D7 -> 65675 | I19: =C19+E19-G19 -> 95804 | K19: ='4'!K19+E19 -> 308560 | M19: ='4'!M19+G19 -> 322756
A20: 규 사 | C20: ='4'!I20 -> - | I20: - | K20: ='4'!K20+'5'!E20 -> 0 | M20: ='4'!M20+G20 -> 0
A22: 5. 전력 사용량 (KWH) | P22: 6. 유틸리티 사용현황 (㎥)
A23: 구 분 | D23: 전일지침 | G23: 금일지침 | J23: 사용량 | M23: 누 계 | P23: 구 분 | S23: 전일 사용량 | V23: 금일 사용량 | Y23: 누 계
A24: MAIN | D24: ='4'!G24 -> 3777062 | G24: 3798128 | J24: =G24-D24 -> 21066 | M24: ='4'!M24+'5'!J24 -> 126560 | P24: 재이용수 | S24: ='4'!V24 -> 428.1 | V24: 424.3 | Y24: ='4'!Y24+'5'!V24 -> 2140.9
A25: ASH 저장조 | D25: ='4'!G25 -> 32922.4 | G25: 32955.5 | J25: =G25-D25 -> 33.1 | M25: ='4'!M25+'5'!J25 -> 191.4 | P25: 복류수 | S25: ='4'!V25 -> 57.3 | V25: 55 | Y25: ='4'!Y25+'5'!V25 -> 280.1
A26: BAG FILTER | D26: ='4'!G26 -> 24390 | G26: 24410 | J26: =G26-D26 -> 20 | M26: ='4'!M26+'5'!J26 -> 110 | P26: 응축수 | S26: ='4'!V26 -> 430.3 | V26: 454.9 | Y26: ='4'!Y26+'5'!V26 -> 2292.3
A27: SCRUBBER | D27: ='4'!G27 -> 1356000 | G27: 1359000 | J27: =G27-D27 -> 3000 | M27: ='4'!M27+'5'!J27 -> 20000 | P27: 보일러 급수 | S27: ='4'!V27 -> 480.1 | V27: 491 | Y27: ='4'!Y27+'5'!V27 -> 2467.6
A28: 활성탄 공급 | D28: ='4'!G28 -> 5204 | G28: 5257 | J28: =G28-D28 -> 53 | M28: ='4'!M28+'5'!J28 -> 319 | P28: 폐 수 | S28: ='4'!V28 -> 0 | V28: 0 | Y28: ='4'!Y28+'5'!V28 -> 0
A29: 소석회 공급 | D29: ='4'!G29 -> 66200 | G29: 66200 | J29: =G29-D29 -> 0 | M29: ='4'!M29+'5'!J29 -> 20 | P29: 연 수 | S29: ='4'!V29 -> 60.8 | V29: 61.2 | Y29: ='4'!Y29+'5'!V29 -> 308.4
A30: 요소수 공급 | D30: ='4'!G30 -> 53280 | G30: 53290 | J30: =G30-D30 -> 10 | M30: ='4'!M30+'5'!J30 -> 70 | P30: 계 | S30: =SUM(S24:U29) -> 1456.6 | Y30: ='4'!Y30+'5'!V30 -> 1528.3
A31: F.D | D31: ='4'!G31 -> 6237766 | G31: 6244869 | J31: =G31-D31 -> 7103 | K31: 12.255 | L31: 12.255 | M31: ='4'!M31+J31 -> 42774
A32: 활성탄 BAG | D32: ='4'!G32 -> 1.6 | G32: 1.6 | J32: =G32-D32 -> 0 | K32: 12.255 | L32: 12.255 | M32: ='4'!M32+J32 -> 0
A33: 소석회 BAG | D33: ='4'!G33 -> 0 | G33: 0 | J33: =G33-D33 -> 0 | K33: 12.255 | L33: 12.255 | M33: ='4'!M33+J33 -> 0
A35: 7. 특이사항
A36: 오 전
A49: 오 후
A63: 야 간

Sheet 6
A1: 근 무 자 | B1: 오 전 | D1: 오 후 | F1: 야 간 | H1: 유동상소각로 운전일지 | T1: 결 재 | U1: 반장 | W1: 대리 | Y1: 팀장
B2: 김문한 | D2: 김동욱 | F2: 권정민
H3: 46209
A5: 1. 소각현황(KG) | P5: 2. BOILER 운전현황(TON, HR)
A6: 구 분 | D6: SRF소각량 | G6: SLUDGE 소각량 | J6: 합 계 | P6: 구 분 | R6: 스팀 생산량 | U6: 스팀 송기량 | X6: 가동시간
A7: 금 일 | D7: 73379 | G7: 163900 | J7: =D7+G7 -> 237279 | P7: 금 일 | R7: 488.7 | U7: 354.5 | X7: 24
A8: 누 계 | D8: ='5'!D8+D7 -> 396135 | G8: ='5'!G8+'6'!G7 -> 988800 | J8: =D8+G8 -> 1384935 | P8: 누 계 | R8: ='5'!R8+'6'!R7 -> 2874.7 | U8: ='5'!U8+'6'!U7 -> 2082.9 | X8: ='5'!X8+X7 -> 144
A10: 3. 약품 사용현황 (KG) | P10: 4. 소각재 발생량 (TON, 대)
A11: 품 명 | C11: 전일 재고량 | E11: 입고량 | G11: 사용량 | I11: 재고량 | K11: 입고량 누계 | M11: 사용량 누계 | P11: 구 분 | S11: 반출량 | W11: 누계
A12: 탄산암모늄 | C12: ='5'!I12 -> 11126 | E12: 0 | G12: 4082 | I12: =C12+E12-G12 -> 7044 | K12: ='5'!K12+'6'!E12 -> 15450 | M12: ='5'!M12+'6'!G12 -> 23320 | P12: 비산재 | S12: 25.95 | W12: ='5'!W12+'6'!S12 -> 220.63
A13: 청관제 | C13: ='5'!I13 -> 820 | E13: 0 | G13: 90 | I13: =C13+E13-G13 -> 730 | K13: ='5'!K13+'6'!E13 -> 710 | M13: ='5'!M13+'6'!G13 -> 570
A14: 활성탄 | C14: ='5'!I14 -> 0 | E14: 2000 | G14: 120 | I14: =C14+E14-G14 -> 1880 | K14: ='5'!K14+'6'!E14 -> 2000 | M14: ='5'!M14+'6'!G14 -> 720 | P14: 바닥재 | S14: 0 | W14: ='5'!W14+'6'!S14 -> 46.84
A15: 가성소다 | C15: ='5'!I15 -> 1147 | E15: 0 | G15: 24 | I15: =C15+E15-G15 -> 1123 | K15: ='5'!K15+'6'!E15 -> 0 | M15: ='5'!M15+'6'!G15 -> 176
A16: 소석회 | C16: ='5'!I16 -> 2250 | E16: 0 | G16: 20 | I16: =C16+E16-G16 -> 2230 | K16: ='5'!K16+'6'!E16 -> 0 | M16: ='5'!M16+'6'!G16 -> 120 | P16: 구분 | S16: 주간 | U16: 야간 | W16: 합계 | Y16: 누계
A17: 소 금 | C17: ='5'!I17 -> 2290 | E17: 0 | G17: 200 | I17: =C17+E17-G17 -> 2090 | K17: ='5'!K17+'6'!E17 -> 1440 | M17: ='5'!M17+'6'!G17 -> 1200
A18: 경 유 | C18: ='5'!I18 -> 5340 | E18: 0 | G18: 0 | I18: =C18+E18-G18 -> 5340 | K18: ='5'!K18+'6'!E18 -> 0 | M18: ='5'!M18+'6'!G18 -> 0 | P18: 불연물 | S18: 2 | U18: 2 | W18: =S18+U18 -> 4 | Y18: ='5'!Y18+'6'!W18 -> 24
A19: SRF | C19: ='5'!I19 -> 95804 | E19: 70810 | G19: =D7 -> 73379 | I19: =C19+E19-G19 -> 93235 | K19: ='5'!K19+'6'!E19 -> 379370 | M19: ='5'!M19+'6'!G19 -> 396135
A20: 규 사 | C20: ='5'!I20 -> - | I20: - | K20: ='5'!K20+'6'!E20 -> 0 | M20: ='5'!M20+'6'!G20 -> 0
A22: 5. 전력 사용량 (KWH) | P22: 6. 유틸리티 사용현황 (㎥)
A23: 구 분 | D23: 전일지침 | G23: 금일지침 | J23: 사용량 | M23: 누 계 | P23: 구 분 | S23: 전일 사용량 | V23: 금일 사용량 | Y23: 누 계
A24: MAIN | D24: ='5'!G24 -> 3798128 | G24: 3819302 | J24: =G24-D24 -> 21174 | M24: ='5'!M24+J24 -> 147734 | P24: 재이용수 | S24: ='5'!V24 -> 424.3 | V24: 426.3 | Y24: ='5'!Y24+'6'!V24 -> 2567.2
A25: ASH 저장조 | D25: ='5'!G25 -> 32955.5 | G25: 32988.4 | J25: =G25-D25 -> 32.9 | M25: ='5'!M25+J25 -> 224.3 | P25: 복류수 | S25: ='5'!V25 -> 55 | V25: 57.3 | Y25: ='5'!Y25+'6'!V25 -> 337.4
A26: BAG FILTER | D26: ='5'!G26 -> 24410 | G26: 24430 | J26: =G26-D26 -> 20 | M26: ='5'!M26+J26 -> 130 | P26: 응축수 | S26: ='5'!V26 -> 454.9 | V26: 541.2 | Y26: ='5'!Y26+'6'!V26 -> 2833.5
A27: SCRUBBER | D27: ='5'!G27 -> 1359000 | G27: 1362000 | J27: =G27-D27 -> 3000 | M27: ='5'!M27+J27 -> 23000 | P27: 보일러 급수 | S27: ='5'!V27 -> 491 | V27: 531.5 | Y27: ='5'!Y27+'6'!V27 -> 2999.1
A28: 활성탄 공급 | D28: ='5'!G28 -> 5257 | G28: 5310 | J28: =G28-D28 -> 53 | M28: ='5'!M28+J28 -> 372 | P28: 폐 수 | S28: ='5'!V28 -> 0 | V28: 0 | Y28: ='5'!Y28+'6'!V28 -> 0
A29: 소석회 공급 | D29: ='5'!G29 -> 66200 | G29: 66200 | J29: =G29-D29 -> 0 | M29: ='5'!M29+J29 -> 20 | P29: 연 수 | S29: ='5'!V29 -> 61.2 | V29: 61.6 | Y29: ='5'!Y29+'6'!V29 -> 370
A30: 요소수 공급 | D30: ='5'!G30 -> 53290 | G30: 53310 | J30: =G30-D30 -> 20 | M30: ='5'!M30+J30 -> 90 | P30: 계 | S30: =SUM(S24:U29) -> 1486.4 | Y30: ='5'!Y30+'6'!V30 -> 1528.3
A31: F.D | D31: ='5'!G31 -> 6244869 | G31: 6252030 | J31: =G31-D31 -> 7161 | K31: 12.255 | L31: 12.255 | M31: ='5'!M31+J31 -> 49935
A32: 활성탄 BAG | D32: ='5'!G32 -> 1.6 | G32: 1.7 | J32: =G32-D32 -> 0.1 | K32: 12.255 | L32: 12.255 | M32: ='5'!M32+J32 -> 0.1
A33: 소석회 BAG | D33: ='5'!G33 -> 0 | G33: 0 | J33: =G33-D33 -> 0 | K33: 12.255 | L33: 12.255 | M33: ='5'!M33+J33 -> 0
A35: 7. 특이사항
A36: 오 전
A49: 오 후
A63: 야 간

Sheet 7
A1: 근 무 자 | B1: 오 전 | D1: 오 후 | F1: 야 간 | H1: 유동상소각로 운전일지 | T1: 결 재 | U1: 반장 | W1: 대리 | Y1: 팀장
B2: 김문한 | D2: 김동욱 | F2: 권정민
H3: 46210
A5: 1. 소각현황(KG) | P5: 2. BOILER 운전현황(TON, HR)
A6: 구 분 | D6: SRF소각량 | G6: SLUDGE 소각량 | J6: 합 계 | P6: 구 분 | R6: 스팀 생산량 | U6: 스팀 송기량 | X6: 가동시간
A7: 금 일 | D7: 78842 | G7: 117000 | J7: =D7+G7 -> 195842 | P7: 금 일 | R7: 455 | U7: 259.2 | X7: 24
A8: 누 계 | D8: ='6'!D8+D7 -> 474977 | G8: ='6'!G8+G7 -> 1105800 | J8: =D8+G8 -> 1580777 | P8: 누 계 | R8: ='6'!R8+'7'!R7 -> 3329.7 | U8: ='6'!U8+U7 -> 2342.1 | X8: ='6'!X8+X7 -> 168
A10: 3. 약품 사용현황 (KG) | P10: 4. 소각재 발생량 (TON, 대)
A11: 품 명 | C11: 전일 재고량 | E11: 입고량 | G11: 사용량 | I11: 재고량 | K11: 입고량 누계 | M11: 사용량 누계 | P11: 구 분 | S11: 반출량 | W11: 누계
A12: 탄산암모늄 | C12: ='6'!I12 -> 7044 | E12: 16020 | G12: 3356 | I12: =C12+E12-G12 -> 19708 | K12: ='6'!K12+E12 -> 31470 | M12: ='6'!M12+'7'!G12 -> 26676 | P12: 비산재 | S12: 55.97 | W12: ='6'!W12+'7'!S12 -> 276.6
A13: 청관제 | C13: ='6'!I13 -> 730 | E13: 0 | G13: 90 | I13: =C13+E13-G13 -> 640 | K13: ='6'!K13+E13 -> 710 | M13: ='6'!M13+'7'!G13 -> 660
A14: 활성탄 | C14: ='6'!I14 -> 1880 | E14: 0 | G14: 120 | I14: =C14+E14-G14 -> 1760 | K14: ='6'!K14+E14 -> 2000 | M14: ='6'!M14+'7'!G14 -> 840 | P14: 바닥재 | S14: 24.8 | W14: ='6'!W14+'7'!S14 -> 71.64
A15: 가성소다 | C15: ='6'!I15 -> 1123 | E15: 0 | G15: 33 | I15: =C15+E15-G15 -> 1090 | K15: ='6'!K15+E15 -> 0 | M15: ='6'!M15+'7'!G15 -> 209
A16: 소석회 | C16: ='6'!I16 -> 2230 | E16: 0 | G16: 20 | I16: =C16+E16-G16 -> 2210 | K16: ='6'!K16+E16 -> 0 | M16: ='6'!M16+'7'!G16 -> 140 | P16: 구분 | S16: 주간 | U16: 야간 | W16: 합계 | Y16: 누계
A17: 소 금 | C17: ='6'!I17 -> 2090 | E17: 0 | G17: 200 | I17: =C17+E17-G17 -> 1890 | K17: ='6'!K17+E17 -> 1440 | M17: ='6'!M17+'7'!G17 -> 1400
A18: 경 유 | C18: ='6'!I18 -> 5340 | E18: 0 | G18: 0 | I18: =C18+E18-G18 -> 5340 | K18: ='6'!K18+E18 -> 0 | M18: ='6'!M18+'7'!G18 -> 0 | P18: 불연물 | S18: 2 | U18: 1 | W18: =S18+U18 -> 3 | Y18: ='6'!Y18+'7'!W18 -> 27
A19: SRF | C19: ='6'!I19 -> 93235 | E19: 66070 | G19: 78842 | I19: =C19+E19-G19 -> 80463 | K19: ='6'!K19+E19 -> 445440 | M19: ='6'!M19+'7'!G19 -> 474977
A20: 규 사 | C20: ='6'!I20 -> - | E20: 0 | G20: 0 | I20: - | K20: ='6'!K20+'7'!E20 -> 0 | M20: ='6'!M20+'7'!G20 -> 0
A22: 5. 전력 사용량 (KWH) | P22: 6. 유틸리티 사용현황 (㎥)
A23: 구 분 | D23: 전일지침 | G23: 금일지침 | J23: 사용량 | M23: 누 계 | P23: 구 분 | S23: 전일 사용량 | V23: 금일 사용량 | Y23: 누 계
A24: MAIN | D24: ='6'!G24 -> 3819302 | G24: 3840163 | J24: =G24-D24 -> 20861 | M24: ='6'!M24+J24 -> 168595 | P24: 재이용수 | S24: ='6'!V24 -> 426.3 | V24: 421.4 | Y24: ='6'!Y24+'7'!V24 -> 2988.6
A25: ASH 저장조 | D25: ='6'!G25 -> 32988.4 | G25: 33021.8 | J25: =G25-D25 -> 33.4 | M25: ='6'!M25+J25 -> 257.7 | P25: 복류수 | S25: ='6'!V25 -> 57.3 | V25: 61.2 | Y25: ='6'!Y25+'7'!V25 -> 398.6
A26: BAG FILTER | D26: ='6'!G26 -> 24430 | G26: 24450 | J26: =G26-D26 -> 20 | M26: ='6'!M26+J26 -> 150 | P26: 응축수 | S26: ='6'!V26 -> 541.2 | V26: 574.8 | Y26: ='6'!Y26+'7'!V26 -> 3408.3
A27: SCRUBBER | D27: ='6'!G27 -> 1362000 | G27: 1365000 | J27: =G27-D27 -> 3000 | M27: ='6'!M27+J27 -> 26000 | P27: 보일러 급수 | S27: ='6'!V27 -> 531.5 | V27: 527.8 | Y27: ='6'!Y27+'7'!V27 -> 3526.9
A28: 활성탄 공급 | D28: ='6'!G28 -> 5310 | G28: 5362 | J28: =G28-D28 -> 52 | M28: ='6'!M28+J28 -> 424 | P28: 폐 수 | S28: ='6'!V28 -> 0 | V28: 0 | Y28: ='6'!Y28+'7'!V28 -> 0
A29: 소석회 공급 | D29: ='6'!G29 -> 66200 | G29: 66210 | J29: =G29-D29 -> 10 | M29: ='6'!M29+J29 -> 30 | P29: 연 수 | S29: ='6'!V29 -> 61.6 | V29: 69.9 | Y29: ='6'!Y29+'7'!V29 -> 439.9
A30: 요소수 공급 | D30: ='6'!G30 -> 53310 | G30: 53320 | J30: =G30-D30 -> 10 | M30: ='6'!M30+J30 -> 100 | P30: 계 | S30: =SUM(S24:U29) -> 1617.9 | Y30: ='6'!Y30+'7'!V30 -> 1528.3
A31: F.D | D31: ='6'!G31 -> 6252030 | G31: 6259077 | J31: =G31-D31 -> 7047 | K31: 12.255 | L31: 12.255 | M31: ='6'!M31+J31 -> 56982
A32: 활성탄 BAG | D32: ='6'!G32 -> 1.7 | G32: 1.7 | J32: =G32-D32 -> 0 | K32: 12.255 | L32: 12.255 | M32: ='6'!M32+J32 -> 0.1
A33: 소석회 BAG | D33: ='6'!G33 -> 0 | G33: 0 | J33: =G33-D33 -> 0 | K33: 12.255 | L33: 12.255 | M33: ='6'!M33+J33 -> 0
A35: 7. 특이사항
A36: 오 전
A49: 오 후
A63: 야 간

Sheet 8
A1: 근 무 자 | B1: 오 전 | D1: 오 후 | F1: 야 간 | H1: 유동상소각로 운전일지 | T1: 결 재 | U1: 반장 | W1: 대리 | Y1: 팀장
B2: 임종민 | D2: 임종민 권정민 | F2: 권정민
H3: 46211
A5: 1. 소각현황(KG) | P5: 2. BOILER 운전현황(TON, HR)
A6: 구 분 | D6: SRF소각량 | G6: SLUDGE 소각량 | J6: 합 계 | P6: 구 분 | R6: 스팀 생산량 | U6: 스팀 송기량 | X6: 가동시간
A7: 금 일 | D7: 81006 | G7: 106400 | J7: =D7+G7 -> 187406 | P7: 금 일 | R7: 468.2 | U7: 253.9 | X7: 24
A8: 누 계 | D8: ='7'!D8+D7 -> 555983 | G8: ='7'!G8+'8'!G7 -> 1212200 | J8: =D8+G8 -> 1768183 | P8: 누 계 | R8: ='7'!R8+'8'!R7 -> 3797.9 | U8: ='7'!U8+U7 -> 2596 | X8: ='7'!X8+'8'!X7 -> 192
A10: 3. 약품 사용현황 (KG) | P10: 4. 소각재 발생량 (TON, 대)
A11: 품 명 | C11: 전일 재고량 | E11: 입고량 | G11: 사용량 | I11: 재고량 | K11: 입고량 누계 | M11: 사용량 누계 | P11: 구 분 | S11: 반출량 | W11: 누계
A12: 탄산암모늄 | C12: ='7'!I12 -> 19708 | E12: 0 | G12: 4727 | I12: =C12+E12-G12 -> 14981 | K12: ='7'!K12+'8'!E12 -> 31470 | M12: ='7'!M12+'8'!G12 -> 31403 | P12: 비산재 | S12: 55.74 | W12: ='7'!W12+'8'!S12 -> 332.34
A13: 청관제 | C13: ='7'!I13 -> 640 | E13: 0 | G13: 80 | I13: =C13+E13-G13 -> 560 | K13: ='7'!K13+'8'!E13 -> 710 | M13: ='7'!M13+'8'!G13 -> 740
A14: 활성탄 | C14: ='7'!I14 -> 1760 | E14: 0 | G14: 120 | I14: =C14+E14-G14 -> 1640 | K14: ='7'!K14+'8'!E14 -> 2000 | M14: ='7'!M14+'8'!G14 -> 960 | P14: 바닥재 | S14: 0 | W14: ='7'!W14+'8'!S14 -> 71.64
A15: 가성소다 | C15: ='7'!I15 -> 1090 | E15: 0 | G15: 29 | I15: =C15+E15-G15 -> 1061 | K15: ='7'!K15+'8'!E15 -> 0 | M15: ='7'!M15+'8'!G15 -> 238
A16: 소석회 | C16: ='7'!I16 -> 2210 | E16: 0 | G16: 20 | I16: =C16+E16-G16 -> 2190 | K16: ='7'!K16+'8'!E16 -> 0 | M16: ='7'!M16+'8'!G16 -> 160 | P16: 구분 | S16: 주간 | U16: 야간 | W16: 합계 | Y16: 누계
A17: 소 금 | C17: ='7'!I17 -> 1890 | E17: 0 | G17: 200 | I17: =C17+E17-G17 -> 1690 | K17: ='7'!K17+'8'!E17 -> 1440 | M17: ='7'!M17+'8'!G17 -> 1600
A18: 경 유 | C18: ='7'!I18 -> 5340 | E18: 0 | G18: 0 | I18: =C18+E18-G18 -> 5340 | K18: ='7'!K18+'8'!E18 -> 0 | M18: ='7'!M18+'8'!G18 -> 0 | P18: 불연물 | S18: 2 | U18: 2 | W18: =S18+U18 -> 4 | Y18: ='7'!Y18+'8'!W18 -> 31
A19: SRF | C19: ='7'!I19 -> 80463 | E19: 71350 | G19: =D7 -> 81006 | I19: =C19+E19-G19 -> 70807 | K19: ='7'!K19+'8'!E19 -> 516790 | M19: ='7'!M19+'8'!G19 -> 555983
A20: 규 사 | C20: ='7'!I20 -> - | I20: - | K20: ='7'!K20+'8'!E20 -> 0 | M20: ='7'!M20+'8'!G20 -> 0
A22: 5. 전력 사용량 (KWH) | P22: 6. 유틸리티 사용현황 (㎥)
A23: 구 분 | D23: 전일지침 | G23: 금일지침 | J23: 사용량 | M23: 누 계 | P23: 구 분 | S23: 전일 사용량 | V23: 금일 사용량 | Y23: 누 계
A24: MAIN | D24: ='7'!G24 -> 3840163 | G24: 3861765 | J24: =G24-D24 -> 21602 | M24: ='7'!M24+J24 -> 190197 | P24: 재이용수 | S24: ='7'!V24 -> 421.4 | V24: 414.6 | Y24: ='7'!Y24+'8'!V24 -> 3403.2
A25: ASH 저장조 | D25: ='7'!G25 -> 33021.8 | G25: 33055.3 | J25: =G25-D25 -> 33.5 | M25: ='7'!M25+J25 -> 291.2 | P25: 복류수 | S25: ='7'!V25 -> 61.2 | V25: 55.2 | Y25: ='7'!Y25+'8'!V25 -> 453.8
A26: BAG FILTER | D26: ='7'!G26 -> 24450 | G26: 24470 | J26: =G26-D26 -> 20 | M26: ='7'!M26+J26 -> 170 | P26: 응축수 | S26: ='7'!V26 -> 574.8 | V26: 532.6 | Y26: ='7'!Y26+'8'!V26 -> 3940.9
A27: SCRUBBER | D27: ='7'!G27 -> 1365000 | G27: 1369000 | J27: =G27-D27 -> 4000 | M27: ='7'!M27+J27 -> 30000 | P27: 보일러 급수 | S27: ='7'!V27 -> 527.8 | V27: 506.4 | Y27: ='7'!Y27+'8'!V27 -> 4033.3
A28: 활성탄 공급 | D28: ='7'!G28 -> 5362 | G28: 5418 | J28: =G28-D28 -> 56 | M28: ='7'!M28+J28 -> 480 | P28: 폐 수 | S28: ='7'!V28 -> 0 | V28: 0 | Y28: ='7'!Y28+'8'!V28 -> 0
A29: 소석회 공급 | D29: ='7'!G29 -> 66210 | G29: 66210 | J29: =G29-D29 -> 0 | M29: ='7'!M29+J29 -> 30 | P29: 연 수 | S29: ='7'!V29 -> 69.9 | V29: 59.7 | Y29: ='7'!Y29+'8'!V29 -> 499.6
A30: 요소수 공급 | D30: ='7'!G30 -> 53320 | G30: 53330 | J30: =G30-D30 -> 10 | M30: ='7'!M30+J30 -> 110 | P30: 계 | S30: =SUM(S24:U29) -> 1655.1 | Y30: ='7'!Y30+'8'!V30 -> 1528.3
A31: F.D | D31: ='7'!G31 -> 6259077 | G31: 6266307 | J31: =G31-D31 -> 7230 | K31: 12.255 | L31: 12.255 | M31: ='7'!M31+J31 -> 64212
A32: 활성탄 BAG | D32: ='7'!G32 -> 1.7 | G32: 1.7 | J32: =G32-D32 -> 0 | K32: 12.255 | L32: 12.255 | M32: ='7'!M32+J32 -> 0.1
A33: 소석회 BAG | D33: ='7'!G33 -> 0 | G33: 0 | J33: =G33-D33 -> 0 | K33: 12.255 | L33: 12.255 | M33: ='7'!M33+J33 -> 0
A35: 7. 특이사항
A36: 오 전
A49: 오 후
A63: 야 간

Sheet 9
A1: 근 무 자 | B1: 오 전 | D1: 오 후 | F1: 야 간 | H1: 유동상소각로 운전일지 | T1: 결 재 | U1: 반장 | W1: 대리 | Y1: 팀장
B2: 임종민 | D2: 임종민,권정민 | F2: 권정민
H3: 46212
A5: 1. 소각현황(KG) | P5: 2. BOILER 운전현황(TON, HR)
A6: 구 분 | D6: SRF소각량 | G6: SLUDGE 소각량 | J6: 합 계 | P6: 구 분 | R6: 스팀 생산량 | U6: 스팀 송기량 | X6: 가동시간
A7: 금 일 | D7: 78799 | G7: 152000 | J7: =D7+G7 -> 230799 | P7: 금 일 | R7: 497 | U7: 388.7 | X7: 24
A8: 누 계 | D8: ='8'!D8+'9'!D7 -> 634782 | G8: ='8'!G8+'9'!G7 -> 1364200 | J8: =D8+G8 -> 1998982 | P8: 누 계 | R8: ='8'!R8+'9'!R7 -> 4294.9 | U8: ='8'!U8+U7 -> 2984.7 | X8: ='8'!X8+'9'!X7 -> 216
A10: 3. 약품 사용현황 (KG) | P10: 4. 소각재 발생량 (TON, 대)
A11: 품 명 | C11: 전일 재고량 | E11: 입고량 | G11: 사용량 | I11: 재고량 | K11: 입고량 누계 | M11: 사용량 누계 | P11: 구 분 | S11: 반출량 | W11: 누계
A12: 탄산암모늄 | C12: ='8'!I12 -> 14981 | E12: 0 | G12: 3518 | I12: =C12+E12-G12 -> 11463 | K12: ='8'!K12+'9'!E12 -> 31470 | M12: ='8'!M12+G12 -> 34921 | P12: 비산재 | S12: 30.99 | W12: ='8'!W12+'9'!S12 -> 363.33
A13: 청관제 | C13: ='8'!I13 -> 560 | E13: 0 | G13: 90 | I13: =C13+E13-G13 -> 470 | K13: ='8'!K13+'9'!E13 -> 710 | M13: ='8'!M13+G13 -> 830
A14: 활성탄 | C14: ='8'!I14 -> 1640 | E14: 0 | G14: 120 | I14: =C14+E14-G14 -> 1520 | K14: ='8'!K14+'9'!E14 -> 2000 | M14: ='8'!M14+G14 -> 1080 | P14: 바닥재 | S14: 0 | W14: ='8'!W14+'9'!S14 -> 71.64
A15: 가성소다 | C15: ='8'!I15 -> 1061 | E15: 0 | G15: 26 | I15: =C15+E15-G15 -> 1035 | K15: ='8'!K15+'9'!E15 -> 0 | M15: ='8'!M15+G15 -> 264
A16: 소석회 | C16: ='8'!I16 -> 2190 | E16: 0 | G16: 20 | I16: =C16+E16-G16 -> 2170 | K16: ='8'!K16+'9'!E16 -> 0 | M16: ='8'!M16+G16 -> 180 | P16: 구분 | S16: 주간 | U16: 야간 | W16: 합계 | Y16: 누계
A17: 소 금 | C17: ='8'!I17 -> 1690 | E17: 0 | G17: 200 | I17: =C17+E17-G17 -> 1490 | K17: ='8'!K17+'9'!E17 -> 1440 | M17: ='8'!M17+G17 -> 1800
A18: 경 유 | C18: ='8'!I18 -> 5340 | E18: 0 | G18: 0 | I18: =C18+E18-G18 -> 5340 | K18: ='8'!K18+'9'!E18 -> 0 | M18: ='8'!M18+G18 -> 0 | P18: 불연물 | S18: 2 | U18: 1 | W18: =S18+U18 -> 3 | Y18: ='8'!Y18+'9'!W18 -> 34
A19: SRF | C19: ='8'!I19 -> 70807 | E19: 70800 | G19: =D7 -> 78799 | I19: =C19+E19-G19 -> 62808 | K19: ='8'!K19+'9'!E19 -> 587590 | M19: ='8'!M19+G19 -> 634782
A20: 규 사 | C20: ='8'!I20 -> - | E20: 0 | G20: 0 | I20: - | K20: ='8'!K20+'9'!E20 -> 0 | M20: ='8'!M20+G20 -> 0
A22: 5. 전력 사용량 (KWH) | P22: 6. 유틸리티 사용현황 (㎥)
A23: 구 분 | D23: 전일지침 | G23: 금일지침 | J23: 사용량 | M23: 누 계 | P23: 구 분 | S23: 전일 사용량 | V23: 금일 사용량 | Y23: 누 계
A24: MAIN | D24: ='8'!G24 -> 3861765 | G24: 3883602 | J24: =G24-D24 -> 21837 | M24: ='8'!M24+J24 -> 212034 | P24: 재이용수 | S24: ='8'!V24 -> 414.6 | V24: 473.9 | Y24: ='8'!Y24+'9'!V24 -> 3877.1
A25: ASH 저장조 | D25: ='8'!G25 -> 33055.3 | G25: 33087.1 | J25: =G25-D25 -> 31.8 | M25: ='8'!M25+J25 -> 323 | P25: 복류수 | S25: ='8'!V25 -> 55.2 | V25: 55.4 | Y25: ='8'!Y25+'9'!V25 -> 509.2
A26: BAG FILTER | D26: ='8'!G26 -> 24470 | G26: 24490 | J26: =G26-D26 -> 20 | M26: ='8'!M26+J26 -> 190 | P26: 응축수 | S26: ='8'!V26 -> 532.6 | V26: 514.9 | Y26: ='8'!Y26+'9'!V26 -> 4455.8
A27: SCRUBBER | D27: ='8'!G27 -> 1369000 | G27: 1372000 | J27: =G27-D27 -> 3000 | M27: ='8'!M27+J27 -> 33000 | P27: 보일러 급수 | S27: ='8'!V27 -> 506.4 | V27: 508.5 | Y27: ='8'!Y27+'9'!V27 -> 4541.8
A28: 활성탄 공급 | D28: ='8'!G28 -> 5418 | G28: 5471 | J28: =G28-D28 -> 53 | M28: ='8'!M28+J28 -> 533 | P28: 폐 수 | S28: ='8'!V28 -> 0 | V28: 0 | Y28: ='8'!Y28+'9'!V28 -> 0
A29: 소석회 공급 | D29: ='8'!G29 -> 66210 | G29: 66210 | J29: =G29-D29 -> 0 | M29: ='8'!M29+J29 -> 30 | P29: 연 수 | S29: ='8'!V29 -> 59.7 | V29: 62 | Y29: ='8'!Y29+'9'!V29 -> 561.6
A30: 요소수 공급 | D30: ='8'!G30 -> 53330 | G30: 53340 | J30: =G30-D30 -> 10 | M30: ='8'!M30+J30 -> 120 | P30: 계 | S30: =SUM(S24:U29) -> 1568.5 | Y30: ='8'!Y30+'9'!V30 -> 1528.3
A31: F.D | D31: ='8'!G31 -> 6266307 | G31: 6273899 | J31: =G31-D31 -> 7592 | K31: 12.255 | L31: 12.255 | M31: ='8'!M31+J31 -> 71804
A32: 활성탄 BAG | D32: ='8'!G32 -> 1.7 | G32: 1.7 | J32: =G32-D32 -> 0 | K32: 12.255 | L32: 12.255 | M32: ='8'!M32+J32 -> 0.1
A33: 소석회 BAG | D33: ='8'!G33 -> 0 | G33: 0 | J33: =G33-D33 -> 0 | K33: 12.255 | L33: 12.255 | M33: ='8'!M33+J33 -> 0
A35: 7. 특이사항
A36: 오 전
A49: 오 후
A63: 야 간

Sheet 10
A1: 근 무 자 | B1: 오 전 | D1: 오 후 | F1: 야 간 | H1: 유동상소각로 운전일지 | T1: 결 재 | U1: 반장 | W1: 대리 | Y1: 팀장
B2: 김동욱 | D2: 임종민 | F2: 권정민
H3: 46213
A5: 1. 소각현황(KG) | P5: 2. BOILER 운전현황(TON, HR)
A6: 구 분 | D6: SRF소각량 | G6: SLUDGE 소각량 | J6: 합 계 | P6: 구 분 | R6: 스팀 생산량 | U6: 스팀 송기량 | X6: 가동시간
A7: 금 일 | D7: 80936 | G7: 138500 | J7: =D7+G7 -> 219436 | P7: 금 일 | R7: 507.6 | U7: 319.8 | X7: 24
A8: 누 계 | D8: ='9'!D8+'10'!D7 -> 715718 | G8: ='9'!G8+'10'!G7 -> 1502700 | J8: =D8+G8 -> 2218418 | P8: 누 계 | R8: ='9'!R8+'10'!R7 -> 4802.5 | U8: ='9'!U8+U7 -> 3304.5 | X8: ='9'!X8+'10'!X7 -> 240
A10: 3. 약품 사용현황 (KG) | P10: 4. 소각재 발생량 (TON, 대)
A11: 품 명 | C11: 전일 재고량 | E11: 입고량 | G11: 사용량 | I11: 재고량 | K11: 입고량 누계 | M11: 사용량 누계 | P11: 구 분 | S11: 반출량 | W11: 누계
A12: 탄산암모늄 | C12: ='9'!I12 -> 11463 | E12: 11400 | G12: 3494 | I12: =C12+E12-G12 -> 19369 | K12: ='9'!K12+'10'!E12 -> 42870 | M12: ='9'!M12+'10'!G12 -> 38415 | P12: 비산재 | S12: 26.21 | W12: ='9'!W12+'10'!S12 -> 389.54
A13: 청관제 | C13: ='9'!I13 -> 470 | E13: 0 | G13: 100 | I13: =C13+E13-G13 -> 370 | K13: ='9'!K13+'10'!E13 -> 710 | M13: ='9'!M13+'10'!G13 -> 930
A14: 활성탄 | C14: ='9'!I14 -> 1520 | E14: 0 | G14: 120 | I14: =C14+E14-G14 -> 1400 | K14: ='9'!K14+'10'!E14 -> 2000 | M14: ='9'!M14+'10'!G14 -> 1200 | P14: 바닥재 | S14: 0 | W14: ='9'!W14+'10'!S14 -> 71.64
A15: 가성소다 | C15: ='9'!I15 -> 1035 | E15: 0 | G15: 31 | I15: =C15+E15-G15 -> 1004 | K15: ='9'!K15+'10'!E15 -> 0 | M15: ='9'!M15+'10'!G15 -> 295
A16: 소석회 | C16: ='9'!I16 -> 2170 | E16: 0 | G16: 20 | I16: =C16+E16-G16 -> 2150 | K16: ='9'!K16+'10'!E16 -> 0 | M16: ='9'!M16+'10'!G16 -> 200 | P16: 구분 | S16: 주간 | U16: 야간 | W16: 합계 | Y16: 누계
A17: 소 금 | C17: ='9'!I17 -> 1490 | E17: 0 | G17: 200 | I17: =C17+E17-G17 -> 1290 | K17: ='9'!K17+'10'!E17 -> 1440 | M17: ='9'!M17+'10'!G17 -> 2000
A18: 경 유 | C18: ='9'!I18 -> 5340 | E18: 0 | G18: 0 | I18: =C18+E18-G18 -> 5340 | K18: ='9'!K18+'10'!E18 -> 0 | M18: ='9'!M18+'10'!G18 -> 0 | P18: 불연물 | S18: 1 | U18: 1 | W18: =S18+U18 -> 2 | Y18: ='9'!Y18+W18 -> 36
A19: SRF | C19: ='9'!I19 -> 62808 | E19: 65350 | G19: =D7 -> 80936 | I19: =C19+E19-G19 -> 47222 | K19: ='9'!K19+'10'!E19 -> 652940 | M19: ='9'!M19+'10'!G19 -> 715718
A20: 규 사 | C20: ='9'!I20 -> - | E20: 0 | G20: 0 | I20: - | K20: ='9'!K20+'10'!E20 -> 0 | M20: ='9'!M20+'10'!G20 -> 0
A22: 5. 전력 사용량 (KWH) | P22: 6. 유틸리티 사용현황 (㎥)
A23: 구 분 | D23: 전일지침 | G23: 금일지침 | J23: 사용량 | M23: 누 계 | P23: 구 분 | S23: 전일 사용량 | V23: 금일 사용량 | Y23: 누 계
A24: MAIN | D24: ='9'!G24 -> 3883602 | G24: 3905553 | J24: =G24-D24 -> 21951 | M24: ='9'!M24+'10'!J24 -> 233985 | P24: 재이용수 | S24: ='9'!V24 -> 473.9 | V24: 562 | Y24: ='9'!Y24+V24 -> 4439.1
A25: ASH 저장조 | D25: ='9'!G25 -> 33087.1 | G25: 33117.7 | J25: =G25-D25 -> 30.6 | M25: ='9'!M25+'10'!J25 -> 353.6 | P25: 복류수 | S25: ='9'!V25 -> 55.4 | V25: 62.9 | Y25: ='9'!Y25+V25 -> 572.1
A26: BAG FILTER | D26: ='9'!G26 -> 24490 | G26: 24510 | J26: =G26-D26 -> 20 | M26: ='9'!M26+'10'!J26 -> 210 | P26: 응축수 | S26: ='9'!V26 -> 514.9 | V26: 488.1 | Y26: ='9'!Y26+V26 -> 4943.9
A27: SCRUBBER | D27: ='9'!G27 -> 1372000 | G27: 1375000 | J27: =G27-D27 -> 3000 | M27: ='9'!M27+'10'!J27 -> 36000 | P27: 보일러 급수 | S27: ='9'!V27 -> 508.5 | V27: 513.3 | Y27: ='9'!Y27+V27 -> 5055.1
A28: 활성탄 공급 | D28: ='9'!G28 -> 5471 | G28: 5522 | J28: =G28-D28 -> 51 | M28: ='9'!M28+'10'!J28 -> 584 | P28: 폐 수 | S28: ='9'!V28 -> 0 | V28: 0 | Y28: ='9'!Y28+V28 -> 0
A29: 소석회 공급 | D29: ='9'!G29 -> 66210 | G29: 66220 | J29: =G29-D29 -> 10 | M29: ='9'!M29+'10'!J29 -> 40 | P29: 연 수 | S29: ='9'!V29 -> 62 | V29: 70.3 | Y29: ='9'!Y29+V29 -> 631.9
A30: 요소수 공급 | D30: ='9'!G30 -> 53340 | G30: 53350 | J30: =G30-D30 -> 10 | M30: ='9'!M30+'10'!J30 -> 130 | P30: 계 | S30: ='9'!S30 -> 1568.5 | Y30: ='9'!Y30+V30 -> 1528.3
A31: F.D | D31: ='9'!G31 -> 6273899 | G31: 6281769 | J31: =G31-D31 -> 7870 | K31: 12.255 | L31: 12.255 | M31: ='9'!M31+'10'!J31 -> 79674
A32: 활성탄 BAG | D32: ='9'!G32 -> 1.7 | G32: 1.7 | J32: =G32-D32 -> 0 | K32: 12.255 | L32: 12.255 | M32: ='9'!M32+'10'!J32 -> 0.1
A33: 소석회 BAG | D33: ='9'!G33 -> 0 | G33: 0 | J33: =G33-D33 -> 0 | K33: 12.255 | L33: 12.255 | M33: ='9'!M33+'10'!J33 -> 0
A35: 7. 특이사항
A36: 오 전
A49: 오 후
A63: 야 간

Sheet 11
A1: 근 무 자 | B1: 오 전 | D1: 오 후 | F1: 야 간 | H1: 유동상소각로 운전일지 | T1: 결 재 | U1: 반장 | W1: 대리 | Y1: 팀장
B2: 김동욱 | D2: 임종민 | F2: 김문한
H3: 46214
A5: 1. 소각현황(KG) | P5: 2. BOILER 운전현황(TON, HR)
A6: 구 분 | D6: SRF소각량 | G6: SLUDGE 소각량 | J6: 합 계 | P6: 구 분 | R6: 스팀 생산량 | U6: 스팀 송기량 | X6: 가동시간
A7: 금 일 | D7: 73131 | G7: 127700 | J7: =D7+G7 -> 200831 | P7: 금 일 | R7: 495.7 | U7: 384.2 | X7: 24
A8: 누 계 | D8: ='10'!D8+'11'!D7 -> 788849 | G8: ='10'!G8+G7 -> 1630400 | J8: =D8+G8 -> 2419249 | P8: 누 계 | R8: ='10'!R8+R7 -> 5298.2 | U8: ='10'!U8+U7 -> 3688.7 | X8: ='10'!X8+'11'!X7 -> 264
A10: 3. 약품 사용현황 (KG) | P10: 4. 소각재 발생량 (TON, 대)
A11: 품 명 | C11: 전일 재고량 | E11: 입고량 | G11: 사용량 | I11: 재고량 | K11: 입고량 누계 | M11: 사용량 누계 | P11: 구 분 | S11: 반출량 | W11: 누계
A12: 탄산암모늄 | C12: ='10'!I12 -> 19369 | E12: 0 | G12: 4136 | I12: =C12+E12-G12 -> 15233 | K12: ='10'!K12+'11'!E12 -> 42870 | M12: ='10'!M12+G12 -> 42551 | P12: 비산재 | S12: 56.34 | W12: ='10'!W12+'11'!S12 -> 445.88
A13: 청관제 | C13: ='10'!I13 -> 370 | E13: 0 | G13: 90 | I13: =C13+E13-G13 -> 280 | K13: ='10'!K13+'11'!E13 -> 710 | M13: ='10'!M13+G13 -> 1020
A14: 활성탄 | C14: ='10'!I14 -> 1400 | E14: 0 | G14: 120 | I14: =C14+E14-G14 -> 1280 | K14: ='10'!K14+'11'!E14 -> 2000 | M14: ='10'!M14+G14 -> 1320 | P14: 바닥재 | S14: 22.1 | W14: ='10'!W14+'11'!S14 -> 93.74
A15: 가성소다 | C15: ='10'!I15 -> 1004 | E15: 0 | G15: 24 | I15: =C15+E15-G15 -> 980 | K15: ='10'!K15+'11'!E15 -> 0 | M15: ='10'!M15+G15 -> 319
A16: 소석회 | C16: ='10'!I16 -> 2150 | E16: 0 | G16: 20 | I16: =C16+E16-G16 -> 2130 | K16: ='10'!K16+'11'!E16 -> 0 | M16: ='10'!M16+G16 -> 220 | P16: 구분 | S16: 주간 | U16: 야간 | W16: 합계 | Y16: 누계
A17: 소 금 | C17: ='10'!I17 -> 1290 | E17: 0 | G17: 200 | I17: =C17+E17-G17 -> 1090 | K17: ='10'!K17+'11'!E17 -> 1440 | M17: ='10'!M17+G17 -> 2200
A18: 경 유 | C18: ='10'!I18 -> 5340 | E18: 0 | G18: 0 | I18: =C18+E18-G18 -> 5340 | K18: ='10'!K18+'11'!E18 -> 0 | M18: ='10'!M18+G18 -> 0 | P18: 불연물 | S18: 3 | U18: 2 | W18: =S18+U18 -> 5 | Y18: ='10'!Y18+'11'!W18 -> 41
A19: SRF | C19: ='10'!I19 -> 47222 | E19: 98650 | G19: =D7 -> 73131 | I19: =C19+E19-G19 -> 72741 | K19: ='10'!K19+'11'!E19 -> 751590 | M19: ='10'!M19+G19 -> 788849
A20: 규 사 | C20: ='10'!I20 -> - | E20: 0 | G20: 0 | I20: - | K20: ='10'!K20+'11'!E20 -> 0 | M20: ='10'!M20+G20 -> 0
A22: 5. 전력 사용량 (KWH) | P22: 6. 유틸리티 사용현황 (㎥)
A23: 구 분 | D23: 전일지침 | G23: 금일지침 | J23: 사용량 | M23: 누 계 | P23: 구 분 | S23: 전일 사용량 | V23: 금일 사용량 | Y23: 누 계
A24: MAIN | D24: ='10'!G24 -> 3905553 | G24: 3926872 | J24: =G24-D24 -> 21319 | M24: ='10'!M24+'11'!J24 -> 255304 | P24: 재이용수 | S24: ='10'!V24 -> 562 | V24: 558.8 | Y24: ='10'!Y24+'11'!V24 -> 4997.9
A25: ASH 저장조 | D25: ='10'!G25 -> 33117.7 | G25: 33147.1 | J25: =G25-D25 -> 29.4 | M25: ='10'!M25+'11'!J25 -> 383 | P25: 복류수 | S25: ='10'!V25 -> 62.9 | V25: 56.5 | Y25: ='10'!Y25+'11'!V25 -> 628.6
A26: BAG FILTER | D26: ='10'!G26 -> 24510 | G26: 24530 | J26: =G26-D26 -> 20 | M26: ='10'!M26+'11'!J26 -> 230 | P26: 응축수 | S26: ='10'!V26 -> 488.1 | V26: 468.7 | Y26: ='10'!Y26+'11'!V26 -> 5412.6
A27: SCRUBBER | D27: ='10'!G27 -> 1375000 | G27: 1378000 | J27: =G27-D27 -> 3000 | M27: ='10'!M27+'11'!J27 -> 39000 | P27: 보일러 급수 | S27: ='10'!V27 -> 513.3 | V27: 500 | Y27: ='10'!Y27+'11'!V27 -> 5555.1
A28: 활성탄 공급 | D28: ='10'!G28 -> 5522 | G28: 5571 | J28: =G28-D28 -> 49 | M28: ='10'!M28+'11'!J28 -> 633 | P28: 폐 수 | S28: ='10'!V28 -> 0 | V28: 0 | Y28: ='10'!Y28+'11'!V28 -> 0
A29: 소석회 공급 | D29: ='10'!G29 -> 66220 | G29: 66220 | J29: =G29-D29 -> 0 | M29: ='10'!M29+'11'!J29 -> 40 | P29: 연 수 | S29: ='10'!V29 -> 70.3 | V29: 64.8 | Y29: ='10'!Y29+'11'!V29 -> 696.7
A30: 요소수 공급 | D30: ='10'!G30 -> 53350 | G30: 53370 | J30: =G30-D30 -> 20 | M30: ='10'!M30+'11'!J30 -> 150 | P30: 계 | S30: =SUM(S24:U29) -> 1696.6 | Y30: ='10'!Y30+'11'!V30 -> 1528.3
A31: F.D | D31: ='10'!G31 -> 6281769 | G31: 6289325 | J31: =G31-D31 -> 7556 | K31: 12.255 | L31: 12.255 | M31: ='10'!M31+J31 -> 87230
A32: 활성탄 BAG | D32: ='10'!G32 -> 1.7 | G32: 1.7 | J32: 0 | K32: 12.255 | L32: 12.255 | M32: ='10'!M32+J32 -> 0.1
A33: 소석회 BAG | D33: ='10'!G33 -> 0 | G33: 0 | J33: =G33-D33 -> 0 | K33: 12.255 | L33: 12.255 | M33: ='10'!M33+J33 -> 0
A35: 7. 특이사항
A36: 오 전
A49: 오 후
A63: 야 간

Sheet 12
A1: 근 무 자 | B1: 오 전 | D1: 오 후 | F1: 야 간 | H1: 유동상소각로 운전일지 | T1: 결 재 | U1: 반장 | W1: 대리 | Y1: 팀장
B2: 김동욱 | D2: 임종민 | F2: 김문한
H3: 46215
A5: 1. 소각현황(KG) | P5: 2. BOILER 운전현황(TON, HR)
A6: 구 분 | D6: SRF소각량 | G6: SLUDGE 소각량 | J6: 합 계 | P6: 구 분 | R6: 스팀 생산량 | U6: 스팀 송기량 | X6: 가동시간
A7: 금 일 | D7: 72830 | G7: 142900 | J7: =D7+G7 -> 215730 | P7: 금 일 | R7: 491.5 | U7: 365.7 | X7: 24
A8: 누 계 | D8: ='11'!D8+'12'!D7 -> 861679 | G8: ='11'!G8+G7 -> 1773300 | J8: =D8+G8 -> 2634979 | P8: 누 계 | R8: ='11'!R8+'12'!R7 -> 5789.7 | U8: ='11'!U8+U7 -> 4054.4 | X8: ='11'!X8+'12'!X7 -> 288
A10: 3. 약품 사용현황 (KG) | P10: 4. 소각재 발생량 (TON, 대)
A11: 품 명 | C11: 전일 재고량 | E11: 입고량 | G11: 사용량 | I11: 재고량 | K11: 입고량 누계 | M11: 사용량 누계 | P11: 구 분 | S11: 반출량 | W11: 누계
A12: 탄산암모늄 | C12: ='11'!I12 -> 15233 | E12: 0 | G12: 3591 | I12: =C12+E12-G12 -> 11642 | K12: ='11'!K12+'12'!E12 -> 42870 | M12: ='11'!M12+'12'!G12 -> 46142 | P12: 비산재 | S12: 0 | W12: ='11'!W12+'12'!S12 -> 445.88
A13: 청관제 | C13: ='11'!I13 -> 280 | E13: 0 | G13: 100 | I13: =C13+E13-G13 -> 180 | K13: ='11'!K13+'12'!E13 -> 710 | M13: ='11'!M13+'12'!G13 -> 1120
A14: 활성탄 | C14: ='11'!I14 -> 1280 | E14: 0 | G14: 120 | I14: =C14+E14-G14 -> 1160 | K14: ='11'!K14+'12'!E14 -> 2000 | M14: ='11'!M14+'12'!G14 -> 1440 | P14: 바닥재 | S14: 0 | W14: ='11'!W14+'12'!S14 -> 93.74
A15: 가성소다 | C15: ='11'!I15 -> 980 | E15: 0 | G15: 22 | I15: =C15+E15-G15 -> 958 | K15: ='11'!K15+'12'!E15 -> 0 | M15: ='11'!M15+'12'!G15 -> 341
A16: 소석회 | C16: ='11'!I16 -> 2130 | E16: 0 | G16: 20 | I16: =C16+E16-G16 -> 2110 | K16: ='11'!K16+'12'!E16 -> 0 | M16: ='11'!M16+'12'!G16 -> 240 | P16: 구분 | S16: 주간 | U16: 야간 | W16: 합계 | Y16: 누계
A17: 소 금 | C17: ='11'!I17 -> 1090 | E17: 1440 | G17: 200 | I17: =C17+E17-G17 -> 2330 | K17: ='11'!K17+'12'!E17 -> 2880 | M17: ='11'!M17+'12'!G17 -> 2400
A18: 경 유 | C18: ='11'!I18 -> 5340 | E18: 0 | G18: 0 | I18: =C18+E18-G18 -> 5340 | K18: ='11'!K18+'12'!E18 -> 0 | M18: ='11'!M18+'12'!G18 -> 0 | P18: 불연물 | S18: 2 | U18: 2 | W18: =S18+U18 -> 4 | Y18: ='11'!Y18+'12'!W18 -> 45
A19: SRF | C19: ='11'!I19 -> 72741 | E19: 68680 | G19: =D7 -> 72830 | I19: =C19+E19-G19 -> 68591 | K19: ='11'!K19+'12'!E19 -> 820270 | M19: ='11'!M19+'12'!G19 -> 861679
A20: 규 사 | C20: ='11'!I20 -> - | E20: 0 | G20: 0 | I20: - | K20: ='11'!K20+'12'!E20 -> 0 | M20: ='11'!M20+'12'!G20 -> 0
A22: 5. 전력 사용량 (KWH) | P22: 6. 유틸리티 사용현황 (㎥)
A23: 구 분 | D23: 전일지침 | G23: 금일지침 | J23: 사용량 | M23: 누 계 | P23: 구 분 | S23: 전일 사용량 | V23: 금일 사용량 | Y23: 누 계
A24: MAIN | D24: ='11'!G24 -> 3926872 | G24: 3949272 | J24: =G24-D24 -> 22400 | M24: ='11'!M24+J24 -> 277704 | P24: 재이용수 | S24: ='11'!V24 -> 558.8 | V24: 561.3 | Y24: ='11'!Y24+'12'!V24 -> 5559.2
A25: ASH 저장조 | D25: ='11'!G25 -> 33147.1 | G25: 33176.5 | J25: =G25-D25 -> 29.4 | M25: ='11'!M25+J25 -> 412.4 | P25: 복류수 | S25: ='11'!V25 -> 56.5 | V25: 60.8 | Y25: ='11'!Y25+'12'!V25 -> 689.4
A26: BAG FILTER | D26: ='11'!G26 -> 24530 | G26: 24550 | J26: =G26-D26 -> 20 | M26: ='11'!M26+J26 -> 250 | P26: 응축수 | S26: ='11'!V26 -> 468.7 | V26: 521.6 | Y26: ='11'!Y26+'12'!V26 -> 5934.2
A27: SCRUBBER | D27: ='11'!G27 -> 1378000 | G27: 1381000 | J27: =G27-D27 -> 3000 | M27: ='11'!M27+J27 -> 42000 | P27: 보일러 급수 | S27: ='11'!V27 -> 500 | V27: 516.5 | Y27: ='11'!Y27+'12'!V27 -> 6071.6
A28: 활성탄 공급 | D28: ='11'!G28 -> 5571 | G28: 5620 | J28: =G28-D28 -> 49 | M28: ='11'!M28+J28 -> 682 | P28: 폐 수 | S28: ='11'!V28 -> 0 | V28: 0 | Y28: ='11'!Y28+'12'!V28 -> 0
A29: 소석회 공급 | D29: ='11'!G29 -> 66220 | G29: 66220 | J29: =G29-D29 -> 0 | M29: ='11'!M29+J29 -> 40 | P29: 연 수 | S29: ='11'!V29 -> 64.8 | V29: 68.9 | Y29: ='11'!Y29+'12'!V29 -> 765.6
A30: 요소수 공급 | D30: ='11'!G30 -> 53370 | G30: 53380 | J30: =G30-D30 -> 10 | M30: ='11'!M30+J30 -> 160 | P30: 계 | S30: =SUM(S24:U29) -> 1648.8 | Y30: ='11'!Y30+'12'!V30 -> 1528.3
A31: F.D | D31: ='11'!G31 -> 6289325 | G31: 6297139 | J31: =G31-D31 -> 7814 | K31: 12.255 | L31: 12.255 | M31: ='11'!M31+J31 -> 95044
A32: 활성탄 BAG | D32: ='11'!G32 -> 1.7 | G32: 1.7 | J32: =G32-D32 -> 0 | K32: 12.255 | L32: 12.255 | M32: ='11'!M32+J32 -> 0.1
A33: 소석회 BAG | D33: ='11'!G33 -> 0 | G33: 0 | J33: =G33-D33 -> 0 | K33: 12.255 | L33: 12.255 | M33: ='11'!M33+J33 -> 0
A35: 7. 특이사항
A36: 오 전
A49: 오 후
A63: 야 간

Sheet 13
A1: 근 무 자 | B1: 오 전 | D1: 오 후 | F1: 야 간 | H1: 유동상소각로 운전일지 | T1: 결 재 | U1: 반장 | W1: 대리 | Y1: 팀장
B2: 김동욱 | D2: 김동욱,김문한 | F2: 김문한
H3: 46216
A5: 1. 소각현황(KG) | P5: 2. BOILER 운전현황(TON, HR)
A6: 구 분 | D6: SRF소각량 | G6: SLUDGE 소각량 | J6: 합 계 | P6: 구 분 | R6: 스팀 생산량 | U6: 스팀 송기량 | X6: 가동시간
A7: 금 일 | D7: 76475 | G7: 137100 | J7: =D7+G7 -> 213575 | P7: 금 일 | R7: 487.2 | U7: 338.4 | X7: 24
A8: 누 계 | D8: ='12'!D8+D7 -> 938154 | G8: ='12'!G8+G7 -> 1910400 | J8: =D8+G8 -> 2848554 | P8: 누 계 | R8: ='12'!R8+'13'!R7 -> 6276.9 | U8: ='12'!U8+'13'!U7 -> 4392.8 | X8: ='12'!X8+X7 -> 312
A10: 3. 약품 사용현황 (KG) | P10: 4. 소각재 발생량 (TON, 대)
A11: 품 명 | C11: 전일 재고량 | E11: 입고량 | G11: 사용량 | I11: 재고량 | K11: 입고량 누계 | M11: 사용량 누계 | P11: 구 분 | S11: 반출량 | W11: 누계
A12: 탄산암모늄 | C12: ='12'!I12 -> 11642 | E12: 11350 | G12: 3941 | I12: =C12+E12-G12 -> 19051 | K12: ='12'!K12+E12 -> 54220 | M12: ='12'!M12+'13'!G12 -> 50083 | P12: 비산재 | S12: 26.67 | W12: ='12'!W12+'13'!S12 -> 472.55
A13: 청관제 | C13: ='12'!I13 -> 180 | E13: 910 | G13: 100 | I13: =C13+E13-G13 -> 990 | K13: ='12'!K13+E13 -> 1620 | M13: ='12'!M13+'13'!G13 -> 1220
A14: 활성탄 | C14: ='12'!I14 -> 1160 | E14: 0 | G14: 120 | I14: =C14+E14-G14 -> 1040 | K14: ='12'!K14+E14 -> 2000 | M14: ='12'!M14+'13'!G14 -> 1560 | P14: 바닥재 | S14: 0 | W14: ='12'!W14+'13'!S14 -> 93.74
A15: 가성소다 | C15: ='12'!I15 -> 958 | E15: 0 | G15: 31 | I15: =C15+E15-G15 -> 927 | K15: ='12'!K15+E15 -> 0 | M15: ='12'!M15+'13'!G15 -> 372
A16: 소석회 | C16: ='12'!I16 -> 2110 | E16: 0 | G16: 20 | I16: =C16+E16-G16 -> 2090 | K16: ='12'!K16+E16 -> 0 | M16: ='12'!M16+'13'!G16 -> 260 | P16: 구분 | S16: 주간 | U16: 야간 | W16: 합계 | Y16: 누계
A17: 소 금 | C17: ='12'!I17 -> 2330 | E17: 0 | G17: 200 | I17: =C17+E17-G17 -> 2130 | K17: ='12'!K17+E17 -> 2880 | M17: ='12'!M17+'13'!G17 -> 2600
A18: 경 유 | C18: ='12'!I18 -> 5340 | E18: 0 | G18: 0 | I18: =C18+E18-G18 -> 5340 | K18: ='12'!K18+E18 -> 0 | M18: ='12'!M18+'13'!G18 -> 0 | P18: 불연물 | S18: 1 | U18: 2 | W18: =S18+U18 -> 3 | Y18: ='12'!Y18+'13'!W18 -> 48
A19: SRF | C19: ='12'!I19 -> 68591 | E19: 74790 | G19: =D7 -> 76475 | I19: =C19+E19-G19 -> 66906 | K19: ='12'!K19+E19 -> 895060 | M19: ='12'!M19+'13'!G19 -> 938154
A20: 규 사 | C20: ='12'!I20 -> - | E20: 0 | G20: 0 | I20: - | K20: ='12'!K20+'13'!E20 -> 0 | M20: ='12'!M20+'13'!G20 -> 0
A22: 5. 전력 사용량 (KWH) | P22: 6. 유틸리티 사용현황 (㎥)
A23: 구 분 | D23: 전일지침 | G23: 금일지침 | J23: 사용량 | M23: 누 계 | P23: 구 분 | S23: 전일 사용량 | V23: 금일 사용량 | Y23: 누 계
A24: MAIN | D24: ='12'!G24 -> 3949272 | G24: 3971350 | J24: =G24-D24 -> 22078 | M24: ='12'!M24+J24 -> 299782 | P24: 재이용수 | S24: ='12'!V24 -> 561.3 | V24: 561.3 | Y24: ='12'!Y24+V24 -> 6120.5
A25: ASH 저장조 | D25: ='12'!G25 -> 33176.5 | G25: 33206.6 | J25: =G25-D25 -> 30.1 | M25: ='12'!M25+J25 -> 442.5 | P25: 복류수 | S25: ='12'!V25 -> 60.8 | V25: 60.6 | Y25: ='12'!Y25+V25 -> 750
A26: BAG FILTER | D26: ='12'!G26 -> 24550 | G26: 24570 | J26: =G26-D26 -> 20 | M26: ='12'!M26+J26 -> 270 | P26: 응축수 | S26: ='12'!V26 -> 521.6 | V26: 525.1 | Y26: ='12'!Y26+V26 -> 6459.3
A27: SCRUBBER | D27: ='12'!G27 -> 1381000 | G27: 1384000 | J27: =G27-D27 -> 3000 | M27: ='12'!M27+J27 -> 45000 | P27: 보일러 급수 | S27: ='12'!V27 -> 516.5 | V27: 577.6 | Y27: ='12'!Y27+V27 -> 6649.2
A28: 활성탄 공급 | D28: ='12'!G28 -> 5620 | G28: 5669 | J28: =G28-D28 -> 49 | M28: ='12'!M28+J28 -> 731 | P28: 폐 수 | S28: ='12'!V28 -> 0 | V28: 0 | Y28: ='12'!Y28+V28 -> 0
A29: 소석회 공급 | D29: ='12'!G29 -> 66220 | G29: 66220 | J29: =G29-D29 -> 0 | M29: ='12'!M29+J29 -> 40 | P29: 연 수 | S29: ='12'!V29 -> 68.9 | V29: 75.6 | Y29: ='12'!Y29+V29 -> 841.2
A30: 요소수 공급 | D30: ='12'!G30 -> 53380 | G30: 53390 | J30: =G30-D30 -> 10 | M30: ='12'!M30+J30 -> 170 | P30: 계 | S30: =SUM(S24:U29) -> 1729.1 | Y30: ='12'!Y30+V30 -> 1528.3
A31: F.D | D31: ='12'!G31 -> 6297139 | G31: 6304835 | J31: =G31-D31 -> 7696 | K31: 12.255 | L31: 12.255 | M31: ='12'!M31+J31 -> 102740
A32: 활성탄 BAG | D32: ='12'!G32 -> 1.7 | G32: 1.7 | J32: =G32-D32 -> 0 | K32: 12.255 | L32: 12.255 | M32: ='12'!M32+J32 -> 0.1
A33: 소석회 BAG | D33: ='12'!G33 -> 0 | G33: 0 | J33: =G33-D33 -> 0 | K33: 12.255 | L33: 12.255 | M33: ='12'!M33+J33 -> 0
A35: 7. 특이사항
A36: 오 전
A49: 오 후
A63: 야 간

Sheet 14
A1: 근 무 자 | B1: 오 전 | D1: 오 후 | F1: 야 간 | H1: 유동상소각로 운전일지 | T1: 결 재 | U1: 반장 | W1: 대리 | Y1: 팀장
B2: 권정민 | D2: 권정민,김문한 | F2: 김문한
H3: 46217
A5: 1. 소각현황(KG) | P5: 2. BOILER 운전현황(TON, HR)
A6: 구 분 | D6: SRF소각량 | G6: SLUDGE 소각량 | J6: 합 계 | P6: 구 분 | R6: 스팀 생산량 | U6: 스팀 송기량 | X6: 가동시간
A7: 금 일 | D7: 69312 | G7: 148900 | J7: =D7+G7 -> 218212 | P7: 금 일 | R7: 487.8 | U7: 86.6 | X7: 24
A8: 누 계 | D8: ='13'!D8+D7 -> 1007466 | G8: ='13'!G8+G7 -> 2059300 | J8: =D8+G8 -> 3066766 | P8: 누 계 | R8: ='13'!R8+'14'!R7 -> 6764.7 | U8: ='13'!U8+U7 -> 4479.4 | X8: ='13'!X8+'14'!X7 -> 336
A10: 3. 약품 사용현황 (KG) | P10: 4. 소각재 발생량 (TON, 대)
A11: 품 명 | C11: 전일 재고량 | E11: 입고량 | G11: 사용량 | I11: 재고량 | K11: 입고량 누계 | M11: 사용량 누계 | P11: 구 분 | S11: 반출량 | W11: 누계
A12: 탄산암모늄 | C12: ='13'!I12 -> 19051 | E12: 0 | G12: 4270 | I12: =C12+E12-G12 -> 14781 | K12: ='13'!K12+'14'!E12 -> 54220 | M12: ='13'!M12+G12 -> 54353 | P12: 비산재 | S12: 59.94 | W12: ='13'!W12+'14'!S12 -> 532.49
A13: 청관제 | C13: ='13'!I13 -> 990 | E13: 0 | G13: 90 | I13: =C13+E13-G13 -> 900 | K13: ='13'!K13+'14'!E13 -> 1620 | M13: ='13'!M13+G13 -> 1310
A14: 활성탄 | C14: ='13'!I14 -> 1040 | E14: 0 | G14: 120 | I14: =C14+E14-G14 -> 920 | K14: ='13'!K14+'14'!E14 -> 2000 | M14: ='13'!M14+G14 -> 1680 | P14: 바닥재 | S14: 24.69 | W14: ='13'!W14+'14'!S14 -> 118.43
A15: 가성소다 | C15: ='13'!I15 -> 927 | E15: 0 | G15: 24 | I15: =C15+E15-G15 -> 903 | K15: ='13'!K15+'14'!E15 -> 0 | M15: ='13'!M15+G15 -> 396
A16: 소석회 | C16: ='13'!I16 -> 2090 | E16: 0 | G16: 20 | I16: =C16+E16-G16 -> 2070 | K16: ='13'!K16+'14'!E16 -> 0 | M16: ='13'!M16+G16 -> 280 | P16: 구분 | S16: 주간 | U16: 야간 | W16: 합계 | Y16: 누계
A17: 소 금 | C17: ='13'!I17 -> 2130 | E17: 0 | G17: 200 | I17: =C17+E17-G17 -> 1930 | K17: ='13'!K17+'14'!E17 -> 2880 | M17: ='13'!M17+G17 -> 2800
A18: 경 유 | C18: ='13'!I18 -> 5340 | E18: 0 | G18: 0 | I18: =C18+E18-G18 -> 5340 | K18: ='13'!K18+'14'!E18 -> 0 | M18: ='13'!M18+G18 -> 0 | P18: 불연물 | S18: 1 | U18: 2 | W18: =S18+U18 -> 3 | Y18: ='13'!Y18+'14'!W18 -> 51
A19: SRF | C19: ='13'!I19 -> 66906 | E19: 67100 | G19: =D7 -> 69312 | I19: =C19+E19-G19 -> 64694 | K19: ='13'!K19+'14'!E19 -> 962160 | M19: ='13'!M19+G19 -> 1007466
A20: 규 사 | C20: ='13'!I20 -> - | E20: 0 | G20: 0 | I20: - | K20: ='13'!K20+'14'!E20 -> 0 | M20: ='13'!M20+G20 -> 0
A22: 5. 전력 사용량 (KWH) | P22: 6. 유틸리티 사용현황 (㎥)
A23: 구 분 | D23: 전일지침 | G23: 금일지침 | J23: 사용량 | M23: 누 계 | P23: 구 분 | S23: 전일 사용량 | V23: 금일 사용량 | Y23: 누 계
A24: MAIN | D24: ='13'!G24 -> 3971350 | G24: 3993645 | J24: =G24-D24 -> 22295 | M24: ='13'!M24+'14'!J24 -> 322077 | P24: 재이용수 | S24: ='13'!V24 -> 561.3 | V24: 559.9 | Y24: ='13'!Y24+V24 -> 6680.4
A25: ASH 저장조 | D25: ='13'!G25 -> 33206.6 | G25: 33239.9 | J25: =G25-D25 -> 33.3 | M25: ='13'!M25+'14'!J25 -> 475.8 | P25: 복류수 | S25: ='13'!V25 -> 60.6 | V25: 61.1 | Y25: ='13'!Y25+V25 -> 811.1
A26: BAG FILTER | D26: ='13'!G26 -> 24570 | G26: 24590 | J26: =G26-D26 -> 20 | M26: ='13'!M26+'14'!J26 -> 290 | P26: 응축수 | S26: ='13'!V26 -> 525.1 | V26: 472.2 | Y26: ='13'!Y26+V26 -> 6931.5
A27: SCRUBBER | D27: ='13'!G27 -> 1384000 | G27: 1387000 | J27: =G27-D27 -> 3000 | M27: ='13'!M27+'14'!J27 -> 48000 | P27: 보일러 급수 | S27: ='13'!V27 -> 577.6 | V27: 482.6 | Y27: ='13'!Y27+V27 -> 7131.8
A28: 활성탄 공급 | D28: ='13'!G28 -> 5669 | G28: 5719 | J28: =G28-D28 -> 50 | M28: ='13'!M28+'14'!J28 -> 781 | P28: 폐 수 | S28: ='13'!V28 -> 0 | V28: 0 | Y28: ='13'!Y28+V28 -> 0
A29: 소석회 공급 | D29: ='13'!G29 -> 66220 | G29: 66230 | J29: =G29-D29 -> 10 | M29: ='13'!M29+'14'!J29 -> 50 | P29: 연 수 | S29: ='13'!V29 -> 75.6 | V29: 69 | Y29: ='13'!Y29+V29 -> 910.2
A30: 요소수 공급 | D30: ='13'!G30 -> 53390 | G30: 53400 | J30: =G30-D30 -> 10 | M30: ='13'!M30+'14'!J30 -> 180 | P30: 계 | S30: =SUM(S24:U29) -> 1800.2 | Y30: ='13'!Y30+V30 -> 1528.3
A31: F.D | D31: ='13'!G31 -> 6304835 | G31: 6312416 | J31: =G31-D31 -> 7581 | M31: ='13'!M31+J31 -> 110321
A32: 활성탄 BAG | D32: ='13'!G32 -> 1.7 | G32: 1.7 | J32: =G32-D32 -> 0 | K32: 12.255 | L32: 12.255 | M32: ='13'!M32+J32 -> 0.1
A33: 소석회 BAG | D33: ='13'!G33 -> 0 | G33: 0 | J33: =G33-D33 -> 0 | K33: 12.255 | L33: 12.255 | M33: ='13'!M33+J33 -> 0
A35: 7. 특이사항
A36: 오 전
A49: 오 후
A63: 야 간

Sheet 15
A1: 근 무 자 | B1: 오 전 | D1: 오 후 | F1: 야 간 | H1: 유동상소각로 운전일지 | T1: 결 재 | U1: 반장 | W1: 대리 | Y1: 팀장
B2: 임종민 | D2: 임종민,김문한 | F2: 김문한
H3: 46218
A5: 1. 소각현황(KG) | P5: 2. BOILER 운전현황(TON, HR)
A6: 구 분 | D6: SRF소각량 | G6: SLUDGE 소각량 | J6: 합 계 | P6: 구 분 | R6: 스팀 생산량 | U6: 스팀 송기량 | X6: 가동시간
A7: 금 일 | D7: 61510 | G7: 171100 | J7: =D7+G7 -> 232610 | P7: 금 일 | R7: 495.2 | U7: 124.8 | X7: 24
A8: 누 계 | D8: ='14'!D8+D7 -> 1068976 | G8: ='14'!G8+G7 -> 2230400 | J8: =D8+G8 -> 3299376 | P8: 누 계 | R8: ='14'!R8+'15'!R7 -> 7259.9 | U8: ='14'!U8+U7 -> 4604.2 | X8: ='14'!X8+X7 -> 360
A10: 3. 약품 사용현황 (KG) | P10: 4. 소각재 발생량 (TON, 대)
A11: 품 명 | C11: 전일 재고량 | E11: 입고량 | G11: 사용량 | I11: 재고량 | K11: 입고량 누계 | M11: 사용량 누계 | P11: 구 분 | S11: 반출량 | W11: 누계
A12: 탄산암모늄 | C12: ='14'!I12 -> 14781 | E12: 0 | G12: 4082 | I12: =C12+E12-G12 -> 10699 | K12: ='14'!K12+'15'!E12 -> 54220 | M12: ='14'!M12+G12 -> 58435 | P12: 비산재 | S12: 54.94 | W12: ='14'!W12+'15'!S12 -> 587.43
A13: 청관제 | C13: ='14'!I13 -> 900 | E13: 0 | G13: 90 | I13: =C13+E13-G13 -> 810 | K13: ='14'!K13+'15'!E13 -> 1620 | M13: ='14'!M13+G13 -> 1400
A14: 활성탄 | C14: ='14'!I14 -> 920 | E14: 0 | G14: 120 | I14: =C14+E14-G14 -> 800 | K14: ='14'!K14+'15'!E14 -> 2000 | M14: ='14'!M14+G14 -> 1800 | P14: 바닥재 | S14: 0 | W14: ='14'!W14+'15'!S14 -> 118.43
A15: 가성소다 | C15: ='14'!I15 -> 903 | E15: 0 | G15: 40 | I15: =C15+E15-G15 -> 863 | K15: ='14'!K15+'15'!E15 -> 0 | M15: ='14'!M15+G15 -> 436
A16: 소석회 | C16: ='14'!I16 -> 2070 | E16: 0 | G16: 20 | I16: =C16+E16-G16 -> 2050 | K16: ='14'!K16+'15'!E16 -> 0 | M16: ='14'!M16+G16 -> 300 | P16: 구분 | S16: 주간 | U16: 야간 | W16: 합계 | Y16: 누계
A17: 소 금 | C17: ='14'!I17 -> 1930 | E17: 0 | G17: 200 | I17: =C17+E17-G17 -> 1730 | K17: ='14'!K17+'15'!E17 -> 2880 | M17: ='14'!M17+G17 -> 3000
A18: 경 유 | C18: ='14'!I18 -> 5340 | E18: 0 | G18: 0 | I18: =C18+E18-G18 -> 5340 | K18: ='14'!K18+'15'!E18 -> 0 | M18: ='14'!M18+G18 -> 0 | P18: 불연물 | S18: 1 | U18: 2 | W18: =S18+U18 -> 3 | Y18: ='14'!Y18+'15'!W18 -> 54
A19: SRF | C19: ='14'!I19 -> 64694 | E19: 94630 | G19: =D7 -> 61510 | I19: =C19+E19-G19 -> 97814 | K19: ='14'!K19+'15'!E19 -> 1056790 | M19: ='14'!M19+G19 -> 1068976
A20: 규 사 | C20: ='14'!I20 -> - | I20: - | K20: ='14'!K20+'15'!E20 -> 0 | M20: ='14'!M20+G20 -> 0
A22: 5. 전력 사용량 (KWH) | P22: 6. 유틸리티 사용현황 (㎥)
A23: 구 분 | D23: 전일지침 | G23: 금일지침 | J23: 사용량 | M23: 누 계 | P23: 구 분 | S23: 전일 사용량 | V23: 금일 사용량 | Y23: 누 계
A24: MAIN | D24: ='14'!G24 -> 3993645 | G24: 4016997 | J24: =G24-D24 -> 23352 | M24: ='14'!M24+'15'!J24 -> 345429 | P24: 재이용수 | S24: ='14'!V24 -> 559.9 | V24: 559.3 | Y24: ='14'!Y24+'15'!V24 -> 7239.7
A25: ASH 저장조 | D25: ='14'!G25 -> 33239.9 | G25: 33273.7 | J25: =G25-D25 -> 33.8 | M25: ='14'!M25+'15'!J25 -> 509.6 | P25: 복류수 | S25: ='14'!V25 -> 61.1 | V25: 55.6 | Y25: ='14'!Y25+'15'!V25 -> 866.7
A26: BAG FILTER | D26: ='14'!G26 -> 24590 | G26: 24610 | J26: =G26-D26 -> 20 | M26: ='14'!M26+'15'!J26 -> 310 | P26: 응축수 | S26: ='14'!V26 -> 472.2 | V26: 480.7 | Y26: ='14'!Y26+'15'!V26 -> 7412.2
A27: SCRUBBER | D27: ='14'!G27 -> 1387000 | G27: 1390000 | J27: =G27-D27 -> 3000 | M27: ='14'!M27+'15'!J27 -> 51000 | P27: 보일러 급수 | S27: ='14'!V27 -> 482.6 | V27: 490.9 | Y27: ='14'!Y27+'15'!V27 -> 7622.7
A28: 활성탄 공급 | D28: ='14'!G28 -> 5719 | G28: 5772 | J28: =G28-D28 -> 53 | M28: ='14'!M28+'15'!J28 -> 834 | P28: 폐 수 | S28: ='14'!V28 -> 0 | V28: 0 | Y28: ='14'!Y28+'15'!V28 -> 0
A29: 소석회 공급 | D29: ='14'!G29 -> 66230 | G29: 66230 | J29: =G29-D29 -> 0 | M29: ='14'!M29+'15'!J29 -> 50 | P29: 연 수 | S29: ='14'!V29 -> 69 | V29: 66.6 | Y29: ='14'!Y29+'15'!V29 -> 976.8
